Workbook

Sheet Competitive Analysis
C2: AURA BEACON ISLAND — 5-Mile Competitive Supply
B3: 2022–2026 New Construction | 5-mile radius | As of 2026 Q2 QTD | Stabilization Target: | G3: 95% target
B4: # | C4: Property | D4: Units | E4: Est. Delivery | F4: Occupancy | G4: Avg Mkt Rent | H4: Owner | I4: Proximity | J4: Type | K4: Notes
C5: STABILIZED / STABILIZING (5 properties, 1,671 units)
B6: 1 | C6: Livano Kemah | D6: 325 | E6: Q3 2022 | F6: 0.929 | G6: 1439 | H6: LIV Development | I6: 3 | J6: Mid-Rise | K6: Year built: 2022/2023; Delivery quarter estimated; Rent: CoStar ask $1,861 vs RealPage eff $1,439
B7: 2 | C7: The Reserve at Baybrook | D7: 291 | E7: Q3 2022 | F7: 0.952 | G7: 1927 | H7: DRA Advisors | I7: 5.4 | J7: Mid-Rise
B8: 3 | C8: Lenox Bayside | D8: 315 | E8: Q2 2023 | F8: 0.911 | G8: 1821 | H8: OHT Partners | I8: 4.5 | J8: Mid-Rise | K8: Occ: CoStar 88% vs RealPage 91%
B9: 4 | C9: The Kippford at Kemah Crossing | D9: 360 | E9: Q3 2023 | F9: 0.95 | G9: 1793 | H9: Allen Harrison Company | I9: 2.8 | J9: Garden | K9: Year built: 2023/2024; Occ: CoStar 90% vs RealPage 95%
B10: 5 | C10: Broadstone Baybrook | D10: 380 | E10: Q3 2024 | F10: 0.953 | G10: 1709 | H10: Alliance Residential Company | I10: 4.4 | J10: Mid-Rise | K10: Year built: 2024/2025; Occ: CoStar 93% vs RealPage 95%
C12: UNDER CONSTRUCTION (3 properties, 885 units)
B13: 6 | C13: Dakota at Kemah | D13: 229 | E13: Q1 2027 | G13: — | H13: Dakota Enterprises | I13: 3.1 | J13: Garden | K13: Diligence: under construction
B14: 7 | C14: Lenox Clear Creek | D14: 336 | E14: Q3 2027 | G14: — | H14: OHT Partners | I14: 4 | J14: Mid-Rise | K14: Diligence: under construction
B15: 8 | C15: The Edge at Seabrook Town Centre | D15: 320 | E15: Q2 2028 | G15: — | H15: HS Development Group | I15: 3.5 | J15: Townhome | K15: Diligence: under construction
C17: PROPOSED (7 properties, 1,963 units)
B18: 9 | C18: The League I | D18: 304 | E18: Q3 2026 | G18: — | H18: MOS R.E LLC | I18: 2.1 | J18: Mid-Rise | K18: Diligence: proposed
B19: 10 | C19: Riverview at Clear Creek | D19: 298 | E19: Q2 2028 | G19: — | H19: Atticus Real Estate | I19: 3.7 | J19: Mid-Rise | K19: Diligence: proposed
B20: 11 | C20: Seabrook Plaza | D20: 260 | E20: Q3 2028 | G20: — | H20: HM Equity Management | I20: 2.1 | J20: Mid-Rise | K20: Units: CoStar 260 vs RealPage 76; Diligence: proposed
B21: 12 | C21: The League Future Phases | D21: 400 | E21: TBD | G21: — | H21: Privately Owned | I21: 2.4 | J21: Mid-Rise | K21: RealPage pipeline (not yet in CoStar); Diligence: proposed
B22: 13 | C22: Residences at Highland Center | D22: 275 | E22: TBD | G22: — | H22: Highland Resources Inc | I22: 3.5 | J22: High-Rise | K22: RealPage pipeline (not yet in CoStar); Diligence: proposed
B23: 14 | C23: Avalon at Kemah II | D23: 228 | E23: TBD | G23: — | H23: — | I23: 3 | J23: Garden | K23: RealPage pipeline (not yet in CoStar); Diligence: proposed
B24: 15 | C24: Avalon at Kemah I | D24: 198 | E24: TBD | G24: — | H24: — | I24: 3 | J24: Garden | K24: RealPage pipeline (not yet in CoStar); Diligence: proposed
B27: * 5-Mile radius. Rent ($) = market asking. Proximity (mi) = straight-line distance from the subject (geocoded); lease-up rent/occupancy to be verified w/ HelloData. See the 'Supply & Absorption' tab for the forward supply / absorption / overall-occupancy forecast.

Sheet Supply & Absorption
Z1: 8105
B2: SUPPLY & ABSORPTION — 5-MILE MARKET (relative-year / TTM) | Z2: =IFERROR(VALUE(RIGHT($C$5,4))*4+MATCH(LEFT($C$5,2),{"Q1","Q2","Q3","Q4"},0)-1,0)
R3: UNDER CONSTRUCTION (linked from Competitive Analysis) | Z3: =IF($C$7="Bear",3,IF($C$7="Base",2,1))
B4: As-of Quarter | C4: Q2 2026 | R4: Property | S4: Units | T4: Est. Delivery
B5: Close Quarter (Y1 start) | C5: Q4 2026 | R5: ='Competitive Analysis'!C14 | S5: ='Competitive Analysis'!D14 | T5: ='Competitive Analysis'!E14 | V5: =IFERROR(VALUE(RIGHT(T5,4))*4+MATCH(LEFT(T5,2),{"Q1","Q2","Q3","Q4"},0)-1,"") | W5: =IF(V5="","",IF(V5<=$Z$1,0,MAX(1,INT((V5-$Z$2)/4)+1)))
B6: Stabilization Target | C6: 0.95 | R6: ='Competitive Analysis'!C15 | S6: ='Competitive Analysis'!D15 | T6: ='Competitive Analysis'!E15 | V6: =IFERROR(VALUE(RIGHT(T6,4))*4+MATCH(LEFT(T6,2),{"Q1","Q2","Q3","Q4"},0)-1,"") | W6: =IF(V6="","",IF(V6<=$Z$1,0,MAX(1,INT((V6-$Z$2)/4)+1)))
B7: Demand Scenario | C7: Base | R7: ='Competitive Analysis'!C13 | S7: ='Competitive Analysis'!D13 | T7: ='Competitive Analysis'!E13 | V7: =IFERROR(VALUE(RIGHT(T7,4))*4+MATCH(LEFT(T7,2),{"Q1","Q2","Q3","Q4"},0)-1,"") | W7: =IF(V7="","",IF(V7<=$Z$1,0,MAX(1,INT((V7-$Z$2)/4)+1)))
B8: Bear Annual Absorption | C8: 150
B9: Base Annual Absorption | C9: 325 | R9: PROPOSED PIPELINE (scenario toggle)
B10: Bull Annual Absorption | C10: 500 | R10: Property | S10: Units | T10: Est. Delivery | U10: Built In
B11: Selected Annual Demand | C11: =IF($C$7="Bear",$C$8,IF($C$7="Bull",$C$10,$C$9)) | R11: The League Future Phases | S11: 400 | U11: Bear only | V11: =IFERROR(VALUE(RIGHT(T11,4))*4+MATCH(LEFT(T11,2),{"Q1","Q2","Q3","Q4"},0)-1,"") | W11: =IF(V11="","",IF(V11<=$Z$1,0,MAX(1,INT((V11-$Z$2)/4)+1))) | X11: =IF(U11="All",1,IF(U11="Bear+Base",IF($Z$3>=2,1,0),IF(U11="Bear only",IF($Z$3>=3,1,0),0)))
R12: The League I | S12: 304 | T12: Q3 2026 | U12: Bear only | V12: =IFERROR(VALUE(RIGHT(T12,4))*4+MATCH(LEFT(T12,2),{"Q1","Q2","Q3","Q4"},0)-1,"") | W12: =IF(V12="","",IF(V12<=$Z$1,0,MAX(1,INT((V12-$Z$2)/4)+1))) | X12: =IF(U12="All",1,IF(U12="Bear+Base",IF($Z$3>=2,1,0),IF(U12="Bear only",IF($Z$3>=3,1,0),0)))
R13: Riverview at Clear Creek | S13: 298 | T13: Q2 2028 | U13: Bear only | V13: =IFERROR(VALUE(RIGHT(T13,4))*4+MATCH(LEFT(T13,2),{"Q1","Q2","Q3","Q4"},0)-1,"") | W13: =IF(V13="","",IF(V13<=$Z$1,0,MAX(1,INT((V13-$Z$2)/4)+1))) | X13: =IF(U13="All",1,IF(U13="Bear+Base",IF($Z$3>=2,1,0),IF(U13="Bear only",IF($Z$3>=3,1,0),0)))
R14: Residences at Highland Center | S14: 275 | U14: Bear only | V14: =IFERROR(VALUE(RIGHT(T14,4))*4+MATCH(LEFT(T14,2),{"Q1","Q2","Q3","Q4"},0)-1,"") | W14: =IF(V14="","",IF(V14<=$Z$1,0,MAX(1,INT((V14-$Z$2)/4)+1))) | X14: =IF(U14="All",1,IF(U14="Bear+Base",IF($Z$3>=2,1,0),IF(U14="Bear only",IF($Z$3>=3,1,0),0)))
R15: Seabrook Plaza | S15: 260 | T15: Q3 2028 | U15: Bear only | V15: =IFERROR(VALUE(RIGHT(T15,4))*4+MATCH(LEFT(T15,2),{"Q1","Q2","Q3","Q4"},0)-1,"") | W15: =IF(V15="","",IF(V15<=$Z$1,0,MAX(1,INT((V15-$Z$2)/4)+1))) | X15: =IF(U15="All",1,IF(U15="Bear+Base",IF($Z$3>=2,1,0),IF(U15="Bear only",IF($Z$3>=3,1,0),0)))
R16: Avalon at Kemah II | S16: 228 | U16: Bear only | V16: =IFERROR(VALUE(RIGHT(T16,4))*4+MATCH(LEFT(T16,2),{"Q1","Q2","Q3","Q4"},0)-1,"") | W16: =IF(V16="","",IF(V16<=$Z$1,0,MAX(1,INT((V16-$Z$2)/4)+1))) | X16: =IF(U16="All",1,IF(U16="Bear+Base",IF($Z$3>=2,1,0),IF(U16="Bear only",IF($Z$3>=3,1,0),0)))
B17: 5-MILE MARKET | C17: -Y6 | D17: -Y5 | E17: -Y4 | F17: -Y3 | G17: -Y2 | H17: -Y1 | I17: Y0 | J17: Y1 | K17: Y2 | L17: Y3 | M17: Y4 | N17: Y5 | O17: Y6 | R17: Avalon at Kemah I | S17: 198 | U17: Bear only | V17: =IFERROR(VALUE(RIGHT(T17,4))*4+MATCH(LEFT(T17,2),{"Q1","Q2","Q3","Q4"},0)-1,"") | W17: =IF(V17="","",IF(V17<=$Z$1,0,MAX(1,INT((V17-$Z$2)/4)+1))) | X17: =IF(U17="All",1,IF(U17="Bear+Base",IF($Z$3>=2,1,0),IF(U17="Bear only",IF($Z$3>=3,1,0),0)))
C18: Q3'19-Q2'20 | D18: Q3'20-Q2'21 | E18: Q3'21-Q2'22 | F18: Q3'22-Q2'23 | G18: Q3'23-Q2'24 | H18: Q3'24-Q2'25 | I18: Q3'25-Q2'26 | J18: Hold Yr 1 | K18: Hold Yr 2 | L18: Hold Yr 3 | M18: Hold Yr 4 | N18: Hold Yr 5 | O18: Hold Yr 6
B19: NEW SUPPLY (5-mi) | C19: 351 | D19: 656 | E19: 0 | F19: 1221 | G19: 360 | H19: 380 | I19: 0 | J19: =SUMIFS($S$5:$S$7,$W$5:$W$7,1)+SUMIFS($S$11:$S$17,$W$11:$W$17,1,$X$11:$X$17,1) | K19: =SUMIFS($S$5:$S$7,$W$5:$W$7,2)+SUMIFS($S$11:$S$17,$W$11:$W$17,2,$X$11:$X$17,1) | L19: =SUMIFS($S$5:$S$7,$W$5:$W$7,3)+SUMIFS($S$11:$S$17,$W$11:$W$17,3,$X$11:$X$17,1) | M19: =SUMIFS($S$5:$S$7,$W$5:$W$7,4)+SUMIFS($S$11:$S$17,$W$11:$W$17,4,$X$11:$X$17,1) | N19: =SUMIFS($S$5:$S$7,$W$5:$W$7,5)+SUMIFS($S$11:$S$17,$W$11:$W$17,5,$X$11:$X$17,1) | O19: =SUMIFS($S$5:$S$7,$W$5:$W$7,6)+SUMIFS($S$11:$S$17,$W$11:$W$17,6,$X$11:$X$17,1)
B20: ABSORPTION (5-mi) | C20: 262 | D20: 800 | E20: -336 | F20: 458 | G20: 575 | H20: 501 | I20: -74 | J20: =J31-I31 | K20: =K31-J31 | L20: =L31-K31 | M20: =M31-L31 | N20: =N31-M31 | O20: =O31-N31
B21: OCCUPANCY (5-mi) | C21: 0.925 | D21: 0.933 | E21: 0.919 | F21: 0.892 | G21: 0.902 | H21: 0.908 | I21: 0.905 | J21: =IFERROR(J31/J30,0) | K21: =IFERROR(K31/K30,0) | L21: =IFERROR(L31/L30,0) | M21: =IFERROR(M31/M30,0) | N21: =IFERROR(N31/N30,0) | O21: =IFERROR(O31/O30,0)
B22: SUBJECT (Aura Beacon Island)
B23: Market Rent (RealPage→HD) | F23: 1795 | G23: 1854 | H23: 1793 | I23: 1782
B24: Market Rent YoY % | D24: =IFERROR(D23/C23-1,"") | E24: =IFERROR(E23/D23-1,"") | F24: =IFERROR(F23/E23-1,"") | G24: =IFERROR(G23/F23-1,"") | H24: =IFERROR(H23/G23-1,"") | I24: =IFERROR(I23/H23-1,"")
B25: Effective Rent | F25: 1657 | G25: 1728 | H25: 1697 | I25: 1543
B26: Effective Rent YoY % | D26: =IFERROR(D25/C25-1,"") | E26: =IFERROR(E25/D25-1,"") | F26: =IFERROR(F25/E25-1,"") | G26: =IFERROR(G25/F25-1,"") | H26: =IFERROR(H25/G25-1,"") | I26: =IFERROR(I25/H25-1,"")
B27: Occupancy (financials / CoStar) | F27: 0.34137931 | G27: 0.87758621 | H27: 0.9324034 | I27: 0.91948675
B28: Concession % | F28: =IFERROR((F23-F25)/F23,"") | G28: =IFERROR((G23-G25)/G23,"") | H28: =IFERROR((H23-H25)/H23,"") | I28: =IFERROR((I23-I25)/I23,"")
B30: inventory | C30: 23134 | D30: 23790 | E30: 23790 | F30: 25011 | G30: 25371 | H30: 25751 | I30: 25751 | J30: =I30+J19 | K30: =J30+K19 | L30: =K30+L19 | M30: =L30+M19 | N30: =M30+N19 | O30: =N30+O19
B31: occupied | C31: 21391 | D31: 22191 | E31: 21855 | F31: 22313 | G31: 22888 | H31: 23388 | I31: 23314 | J31: =MIN($C$6*J30,I31+$C$11) | K31: =MIN($C$6*K30,J31+$C$11) | L31: =MIN($C$6*L30,K31+$C$11) | M31: =MIN($C$6*M30,L31+$C$11) | N31: =MIN($C$6*N30,M31+$C$11) | O31: =MIN($C$6*O30,N31+$C$11)
B33: IMPLIED 5-MI OCCUPANCY BY DEMAND SCENARIO | J33: Y1 | K33: Y2 | L33: Y3 | M33: Y4 | N33: Y5 | O33: Y6
B34: Bear | J34: =MIN($C$6,($I$31+$C$8*1)/J30) | K34: =MIN($C$6,($I$31+$C$8*2)/K30) | L34: =MIN($C$6,($I$31+$C$8*3)/L30) | M34: =MIN($C$6,($I$31+$C$8*4)/M30) | N34: =MIN($C$6,($I$31+$C$8*5)/N30) | O34: =MIN($C$6,($I$31+$C$8*6)/O30)
B35: Base | J35: =MIN($C$6,($I$31+$C$9*1)/J30) | K35: =MIN($C$6,($I$31+$C$9*2)/K30) | L35: =MIN($C$6,($I$31+$C$9*3)/L30) | M35: =MIN($C$6,($I$31+$C$9*4)/M30) | N35: =MIN($C$6,($I$31+$C$9*5)/N30) | O35: =MIN($C$6,($I$31+$C$9*6)/O30)
B36: Bull | J36: =MIN($C$6,($I$31+$C$10*1)/J30) | K36: =MIN($C$6,($I$31+$C$10*2)/K30) | L36: =MIN($C$6,($I$31+$C$10*3)/L30) | M36: =MIN($C$6,($I$31+$C$10*4)/M30) | N36: =MIN($C$6,($I$31+$C$10*5)/N30) | O36: =MIN($C$6,($I$31+$C$10*6)/O30)
B38: MARKET RENT GROWTH (editable assumptions) | J38: Y1 | K38: Y2 | L38: Y3 | M38: Y4 | N38: Y5 | O38: Y6
B39: Bear | J39: -0.0025 | K39: 0.0175 | L39: 0.0275 | M39: 0.0375 | N39: 0.0275 | O39: 0.0175
B40: Base | J40: 0.01 | K40: 0.03 | L40: 0.04 | M40: 0.05 | N40: 0.04 | O40: 0.03
B41: Bull | J41: 0.02 | K41: 0.04 | L41: 0.05 | M41: 0.06 | N41: 0.05 | O41: 0.04
B42: CONCESSIONS % — forward assumption (editable)
B43: Bear | J43: 0.06 | K43: 0.045 | L43: 0.035 | M43: 0.035 | N43: 0.035 | O43: 0.035
...

Sheet Reconciliation Log
A1: Property | B1: Address | C1: Units | D1: Year Built | E1: Est. Delivery | F1: Bucket | G1: CoStar Occ | H1: RealPage Occ | I1: CoStar Ask Rent | J1: RealPage Eff Rent | K1: Sources | L1: Notes
A2: Broadstone Baybrook | B2: 19101 Town Ridge Ln | C2: 380 | D2: 2024 | E2: Q3 2024 | F2: STABILIZED / STABILIZING | G2: 0.926316 | H2: 0.953 | I2: 1795 | J2: 1709 | K2: CoStar+RealPage | L2: Year built: 2024/2025; Occ: CoStar 93% vs RealPage 95%
A3: The Kippford at Kemah Crossing | B3: 2201 Evergreen Memorial Pky | C3: 360 | D3: 2023 | E3: Q3 2023 | F3: STABILIZED / STABILIZING | G3: 0.902778 | H3: 0.95 | I3: 1765 | J3: 1793 | K3: CoStar+RealPage | L3: Year built: 2023/2024; Occ: CoStar 90% vs RealPage 95%
A4: Lenox Bayside | B4: 250 N Village Dr | C4: 315 | D4: 2023 | E4: Q2 2023 | F4: STABILIZED / STABILIZING | G4: 0.879365 | H4: 0.911 | I4: 1836 | J4: 1821 | K4: CoStar+RealPage | L4: Occ: CoStar 88% vs RealPage 91%
A5: Livano Kemah | B5: 800 FM 518 Rd E | C5: 325 | D5: 2022 | E5: Q3 2022 | F5: STABILIZED / STABILIZING | G5: 0.92 | H5: 0.929 | I5: 1861 | J5: 1439 | K5: CoStar+RealPage | L5: Year built: 2022/2023; Delivery quarter estimated; Rent: CoStar ask $1,861 vs RealPage eff $1,439
A6: The Reserve at Baybrook | B6: 19302 Glenwest Dr | C6: 291 | D6: 2022 | E6: Q3 2022 | F6: STABILIZED / STABILIZING | G6: 0.948454 | H6: 0.952 | I6: 1897 | J6: 1927 | K6: CoStar+RealPage
A7: The Edge at Seabrook Town Centre | B7: 2101 Humble Dr | C7: 320 | D7: 2028 | E7: Q2 2028 | F7: UNDER CONSTRUCTION | K7: RealPage | L7: Diligence: under construction
A8: Lenox Clear Creek | B8: 16200 State Highway 3 | C8: 336 | D8: 2027 | E8: Q3 2027 | F8: UNDER CONSTRUCTION | K8: CoStar+RealPage | L8: Diligence: under construction
A9: Dakota at Kemah | B9: 2801 Lawrence Rd | C9: 229 | D9: 2027 | E9: Q1 2027 | F9: UNDER CONSTRUCTION | K9: RealPage | L9: Diligence: under construction
A10: Seabrook Plaza | B10: 3101 Nasa Pky | C10: 260 | D10: 2027 | E10: Q3 2028 | F10: PROPOSED | K10: CoStar+RealPage | L10: Units: CoStar 260 vs RealPage 76; Diligence: proposed
A11: Riverview at Clear Creek | B11: 301 N Wesley Dr | C11: 298 | D11: 2027 | E11: Q2 2028 | F11: PROPOSED | K11: CoStar+RealPage | L11: Diligence: proposed
A12: The League I | B12: E FM 518 & Main St | C12: 304 | D12: 2028 | E12: Q3 2026 | F12: PROPOSED | K12: RealPage | L12: Diligence: proposed
A13: Avalon at Kemah I | B13: Bel Rd & N Hwy 146 | C13: 198 | F13: PROPOSED | K13: RealPage | L13: RealPage pipeline (not yet in CoStar); Diligence: proposed
A14: The League Future Phases | B14: E FM 518 & Main St | C14: 400 | F14: PROPOSED | K14: RealPage | L14: RealPage pipeline (not yet in CoStar); Diligence: proposed
A15: Residences at Highland Center | B15: 3805 & 3813 NASA Rd 1 | C15: 275 | F15: PROPOSED | K15: RealPage | L15: RealPage pipeline (not yet in CoStar); Diligence: proposed
A16: Avalon at Kemah II | B16: Bel Rd & N Hwy 146 | C16: 228 | F16: PROPOSED | K16: RealPage | L16: RealPage pipeline (not yet in CoStar); Diligence: proposed

Sheet Diligence
B2: PIPELINE DILIGENCE
B3: Property / Site | C3: Units | D3: Est. Delivery | E3: Status | F3: Leasing Pace | G3: Notes | H3: Source
B4: Riverview at Clear Creek | C4: 298 | E4: proposed | G4: WB Property Group; waterfront mixed-use (marina/hotel/townhomes) incl senior-housing component; CoStar 'under construction' NOT corroborated, public record stalls ~2022-23; market-rate; full plan ~2029 | H4: https://communityimpact.com/houston/bay-area/development/2022/04/22/making-a-destination-league-city-developer-sign-agreement-to-build-riverview/
B5: Lenox Clear Creek | C5: 336 | D5: Q3 2027 | E5: under construction | G5: Likely CoStar placeholder = OHT Partners + Crow Holdings JV, 16200 SH-3; broke ground late 2025; market-rate; LOCATION is Clear Lake 77058 (~Webster), NOT League City - weaker overlap | H5: https://rebusinessonline.com/oht-partners-crow-holdings-break-ground-on-336-unit-multifamily-project-in-metro-houston/
B6: Dakota at Kemah | C6: 229 | D6: Q1 2027 | E6: under construction | G6: Dakota Enterprises; mgmt The Mathis Group; 2801 Lawrence Rd Kemah; 10 three-story bldgs; groundbreaking Dec 9 2025; TDLR completion Jan 15 2027; market-rate luxury | H6: https://communityimpact.com/houston/bay-area/government/2025/12/03/the-dakota-at-kemah-to-have-groundbreaking-ceremony/
B7: The League I | C7: 304 | D7: Q3 2026 | E7: proposed | G7: CJ Development (Johnny Vassallo); $125M 44-ac mixed-use FM-518; 304 Phase-1 count UNCONFIRMED (public sourcing ~600 total); no verified groundbreaking, prior multi-yr stall - field-verify vertical status | H7: https://communityimpact.com/houston/bay-area/development/2026/03/31/new-modern-retail-dining-space-coming-to-league-city/
B8: The Edge at Seabrook Town Centre | C8: 320 | D8: Q2 2028 | E8: under construction | G8: HS Development Group; $85M 19.5-ac mixed-use; broke ground Jan 2026 after ~3-yr financing stall; 4-story garden + 28.5k sf retail; market-rate (rents $1.5k-$3.1k); buildout Q2 2028 | H8: https://therealdeal.com/texas/2026/01/16/hs-development-groups-seabrook-town-centre-breaks-ground/
B9: The League Future Phases | C9: 400 | E9: proposed | G9: CJ Development; future tranche of The League (FM-518); total project described up to ~600 units across phases so 400 future phase plausible but specific count NOT independently verified; market-rate | H9: https://communityimpact.com/houston/bay-area/development/2022/01/27/45-acre-mixed-use-development-the-league-to-bring-retail-restaurants-homes-to-league-city/
B10: Residences at Highland Center | C10: 275 | E10: proposed | G10: UNVERIFIED - no public news, city agenda, or developer source found tying a ~275-unit MF project to Highland Center; possible CoStar/RealPage early-stage or speculative entry | H10: not found
B11: Seabrook Plaza | C11: 260 | E11: proposed | G11: UNVERIFIED - could not confirm a 260-unit 'Seabrook Plaza' MF project; may be alias/duplicate of The Edge at Seabrook Town Centre or speculative CoStar entry | H11: not found
B12: Avalon at Kemah I | C12: 198 | E12: proposed | G12: UNVERIFIED - no public record of an 'Avalon at Kemah' apartment project; Kemah's only verified active MF is The Dakota; possible CoStar placeholder/rename | H12: not found
B13: Avalon at Kemah II | C13: 228 | E13: proposed | G13: UNVERIFIED - Phase II of an unverified Phase I; no public confirmation found; treat as speculative pending Kemah planning dept / CoStar source check | H13: not found
B15: SHADOW SUPPLY (latent / untracked — watch list)
B16: Property / Site | C16: Units | D16: Est. Delivery | E16: Status | F16: Leasing Pace | G16: Notes | H16: Source
B17: Westland Ranch MPC potential MF tract | E17: planned/speculative | G17: Meritage Homes MPC, W League City near SH-99/FM-517 (~5-6 mi, radius edge); ~1,200+ SF lots; no confirmed apartment phase but large MPCs often carry MF tracts; MF entitlement UNVERIFIED | H17: https://www.meritagehomes.com/state/tx/houston/westland-ranch
B18: FM-518 / Main St corridor mixed-use capacity | E18: zoning/entitlement capacity | G18: League City comp plan & recent rezonings along FM-518 favor mixed-use w/ residential (The League sits here); latent MF capacity exists but no specific unnamed funded project confirmed | H18: https://www.leaguecitytx.gov/151/Planning
B19: Webster / SH-3 & Bay Area Blvd MF node | E19: redevelopment node | G19: Webster (Baybrook/I-45 hub, ~4-5 mi N) actively courts MF; OHT/Crow 336u JV sits here; likely additional latent MF capacity but no specific unnamed verified project found | H19: https://www.cityofwebster.com
B20: Friendswood multifamily | E20: none confirmed | G20: Friendswood largely SF-oriented, historically resistant to high-density MF; some mixed-use discussion at FM-518/FM-528 but nothing concrete; no specific latent apartment project found | H20: not found
