Workbook

Sheet Competitive Analysis
C2: BELLA MIRAGE — 5-Mile Competitive Supply
B3: 2022–2026 New Construction | 5-mile radius | As of 2026 Q2 QTD | Stabilization Target: | G3: 95% target
B4: # | C4: Property | D4: Units | E4: Est. Delivery | F4: Occupancy | G4: Avg Mkt Rent | H4: Owner | I4: Proximity | J4: Type | K4: Notes
C5: STABILIZED / STABILIZING (22 properties, 5,296 units)
B6: 1 | C6: Luna Bear 94 | D6: 94 | E6: Q1 2022 | F6: 0.989362 | G6: 1913 | H6: Luna Bear Properties LLC | I6: 4.1 | J6: Single Family
B7: 2 | C7: Cyrene at Estrella | D7: 64 | E7: Q1 2022 | F7: 0.984375 | G7: 2442 | H7: BGO | I7: 4.4 | J7: Single Family | K7: Year built: 2022/2023; Delivery quarter estimated; Rent: CoStar ask $2,442 vs RealPage eff $2,261
B8: 3 | C8: Sunset View Apartments | D8: 286 | E8: Q2 2022 | F8: 0.902098 | G8: 1338 | H8: Sunrise Multifamily LLC | I8: 3.7 | J8: Garden | K8: Occ: CoStar 90% vs RealPage 96%; Rent: CoStar ask $1,338 vs RealPage eff $1,167
B9: 4 | C9: Avari Apartments | D9: 354 | E9: Q3 2022 | F9: 0.951977 | G9: 1574 | H9: Brett C. & Lorraine M. Heers | I9: 2.6 | J9: Mid-Rise | K9: Year built: 2022/2023; Delivery quarter estimated; Occ: CoStar 95% vs RealPage 100%
B10: 5 | C10: Prose Desert River | D10: 384 | E10: Q1 2023 | F10: 0.895833 | G10: 1429 | H10: Alliance Residential Company | I10: 4.8 | J10: Garden | K10: Year built: 2023/2024; Delivery quarter estimated; Occ: CoStar 90% vs RealPage 97%; Rent: CoStar ask $1,429 vs RealPage eff $1,313
B11: 6 | C11: District at Civic Square | D11: 352 | E11: Q1 2023 | F11: 0.920455 | G11: 1526 | H11: Billah Khan | I11: 4 | J11: Mid-Rise | K11: Year built: 2023/2024; Delivery quarter estimated; Occ: CoStar 92% vs RealPage 100%; Rent: CoStar ask $1,526 vs RealPage eff $1,263
B12: 7 | C12: Acero Roosevelt | D12: 352 | E12: Q1 2023 | F12: 0.892045 | G12: 1632 | H12: IDM Companies | I12: 5.8 | J12: Garden | K12: Year built: 2023/2024; Delivery quarter estimated; Occ: CoStar 89% vs RealPage 94%; Rent: CoStar ask $1,632 vs RealPage eff $1,236
B13: 8 | C13: Cabana Bullard | D13: 336 | E13: Q1 2023 | F13: 0.949405 | G13: 1335 | H13: Greenlight Communities | I13: 4.1 | J13: Garden | K13: Delivery quarter estimated
B14: 9 | C14: Bungalows at Camelback | D14: 334 | E14: Q1 2023 | F14: 0.763473 | G14: 2026 | H14: Cavan Companies | I14: 3.3 | J14: Garden | K14: Year built: 2023/2024; Delivery quarter estimated; Occ: CoStar 76% vs RealPage 92%; Rent: CoStar ask $2,026 vs RealPage eff $1,385
B15: 10 | C15: Cuvee Apartments | D15: 310 | E15: Q1 2023 | F15: 0.926 | G15: — | H15: Pillar Communities | I15: 5.3 | J15: Mid-Rise | K15: Delivery quarter estimated
B16: 11 | C16: Springs At Westgate | D16: 292 | E16: Q1 2023 | F16: 0.784247 | G16: 1516 | H16: Continental Properties Company, Inc. | I16: 4.3 | J16: Garden | K16: Year built: 2023/2024; Delivery quarter estimated; Occ: CoStar 78% vs RealPage 87%
B17: 12 | C17: BB Living at Civic Square | D17: 290 | E17: Q1 2023 | F17: 0.934483 | G17: 2812 | H17: BB Living | I17: 3.7 | J17: Townhome | K17: Year built: 2023/2024; Delivery quarter estimated; Occ: CoStar 93% vs RealPage 96%; Rent: CoStar ask $2,812 vs RealPage eff $2,575
B18: 13 | C18: Village at Paseo de Luces | D18: 272 | E18: Q1 2023 | F18: 0.926471 | G18: 1820 | H18: Empire Group of Companies | I18: 4.1 | J18: Garden | K18: Year built: 2023/2024; Delivery quarter estimated; Occ: CoStar 93% vs RealPage 97%; Rent: CoStar ask $1,820 vs RealPage eff $1,597
B19: 14 | C19: Parc Lofts | D19: 258 | E19: Q1 2023 | F19: 0.899225 | G19: 1567 | H19: Millburn & Company | I19: 4.6 | J19: Garden | K19: Delivery quarter estimated; Occ: CoStar 90% vs RealPage 94%
B20: 15 | C20: Christopher Todd Communities at McDowell | D20: 217 | E20: Q1 2023 | F20: 0.949309 | G20: 1576 | H20: Christopher Todd Communities | I20: 1.9 | J20: Garden | K20: Year built: 2023/2024; Delivery quarter estimated
B21: 16 | C21: Village Camelback Park | D21: 194 | E21: Q1 2023 | F21: 0.773196 | G21: 1874 | H21: The Empire Group | I21: 1.9 | J21: Single Family | K21: Delivery quarter estimated; Occ: CoStar 77% vs RealPage 92%
B22: 17 | C22: Village at the BLVD | D22: 187 | E22: Q1 2023 | F22: 0.935829 | G22: 1964 | H22: Empire Group of Companies | I22: 4 | J22: Single Family | K22: Year built: 2023/2024; Delivery quarter estimated; Occ: CoStar 94% vs RealPage 96%
B23: 18 | C23: The Crofton at Sheely Farms | D23: 167 | E23: Q1 2023 | F23: 0.952096 | G23: 1607 | H23: Atlantic Creek Real Estate Partners | I23: 5.3 | J23: Garden | K23: Delivery quarter estimated; Rent: CoStar ask $1,607 vs RealPage eff $1,388
B24: 19 | C24: TerraLane at Park McDowell | D24: 162 | E24: Q1 2023 | F24: 0.851852 | G24: 1576 | H24: TerraLane Communities | I24: 3.5 | J24: Garden | K24: Delivery quarter estimated; Occ: CoStar 85% vs RealPage 88%; Rent: CoStar ask $1,576 vs RealPage eff $1,211
B25: 20 | C25: Ironwood Homes at River Run | D25: 103 | E25: Q1 2023 | F25: 0.893204 | G25: 2523 | H25: Sunstone Properties Trust | I25: 1.1 | J25: Garden | K25: Delivery quarter estimated
B26: 21 | C26: Avery | D26: 185 | E26: Q2 2024 | F26: 0.924324 | G26: 1750 | H26: Larson Capital Management | I26: 1.1 | J26: Garden | K26: Rent: CoStar ask $1,750 vs RealPage eff $1,875
B27: 22 | C27: Ironwood at River Run | D27: 103 | E27: Q2 2024 | F27: 0.961 | G27: — | H27: Rockpoint Group | I27: 1.3 | J27: Single Family | K27: Delivery quarter estimated
C29: LEASING UP (28 properties, 7,249 units)
B30: 23 | C30: Radia Avondale Station | D30: 407 | E30: Q1 2024 | F30: 0.616708 | G30: 1743 | H30: Goodman Real Estate Inc. | I30: 3.1 | J30: Garden | K30: Units: CoStar 407 vs RealPage 212; Year built: 2024/2025; Delivery quarter estimated; Occ: CoStar 62% vs RealPage 51%; Verify rent/occ w/ HelloData
B31: 24 | C31: Alta 99th | D31: 402 | E31: Q1 2024 | F31: 0.855721 | G31: 1542 | H31: Wood Partners | I31: 3.1 | J31: Garden | K31: Delivery quarter estimated; Occ: CoStar 86% vs RealPage 90%; Rent: CoStar ask $1,542 vs RealPage eff $1,154; Verify rent/occ w/ HelloData
B32: 25 | C32: Alta Avondale | D32: 360 | E32: Q2 2024 | F32: 0.783333 | G32: 1610 | H32: Wood Partners | I32: 2.9 | J32: Mid-Rise | K32: Year built: 2024/2025; Delivery quarter estimated; Occ: CoStar 78% vs RealPage 84%; Rent: CoStar ask $1,610 vs RealPage eff $1,339; Verify rent/occ w/ HelloData
B33: 26 | C33: Livano Avondale | D33: 316 | E33: Q2 2024 | F33: 0.829114 | G33: 1663 | H33: LIV Development | I33: 2.5 | J33: Mid-Rise | K33: Year built: 2024/2025; Delivery quarter estimated; Rent: CoStar ask $1,663 vs RealPage eff $1,263; Verify rent/occ w/ HelloData
B34: 27 | C34: Cardinal 95 | D34: 198 | E34: Q2 2024 | F34: 0.878788 | G34: 1691 | H34: Quarry Capital | I34: 4.4 | J34: Garden | K34: Delivery quarter estimated; Verify rent/occ w/ HelloData
B35: 28 | C35: Moderne at Roosevelt | D35: 185 | E35: Q2 2024 | F35: 0.891892 | G35: 1900 | H35: MODERNE Communities | I35: 3.9 | J35: Low-Rise | K35: Year built: 2024/2025; Occ: CoStar 89% vs RealPage 94%; Rent: CoStar ask $1,900 vs RealPage eff $1,769; Verify rent/occ w/ HelloData
B36: 29 | C36: Canopy at the Trails | D36: 124 | E36: Q2 2024 | F36: 0.879032 | G36: 2183 | H36: Mark-Taylor Companies | I36: 2.3 | J36: Townhome | K36: Delivery quarter estimated; Occ: CoStar 88% vs RealPage 92%; Verify rent/occ w/ HelloData
B37: 30 | C37: Meritum Sheely Farms | D37: 680 | E37: Q4 2024 | F37: 0.797059 | G37: 1680 | H37: IDM Companies | I37: 3.2 | J37: Mid-Rise | K37: Year built: 2024/2025; Delivery quarter estimated; Rent: CoStar ask $1,680 vs RealPage eff $1,356; Verify rent/occ w/ HelloData
B38: 31 | C38: Alta Goodyear | D38: 342 | E38: Q2 2025 | F38: 0.789474 | G38: 1638 | H38: Wood Partners | I38: 3.5 | J38: Mid-Rise | K38: Delivery quarter estimated; Rent: CoStar ask $1,638 vs RealPage eff $1,433; Verify rent/occ w/ HelloData
B39: 32 | C39: Agave Ranch | D39: 324 | E39: Q2 2025 | F39: 0.802469 | G39: 1747 | H39: The Garrett Companies | I39: 3.5 | J39: Mid-Rise | K39: Delivery quarter estimated; Occ: CoStar 80% vs RealPage 0%; Rent: CoStar ask $1,747 vs RealPage eff $1,582; Verify rent/occ w/ HelloData
B40: 33 | C40: Avondale Commons | D40: 324 | E40: Q2 2025 | F40: 0.37037 | G40: 1632 | H40: Overland Group | I40: 1.9 | J40: Mid-Rise | K40: Year built: 2025/2026; Delivery quarter estimated; Occ: CoStar 37% vs RealPage 85%; Rent: CoStar ask $1,632 vs RealPage eff $1,321; Verify rent/occ w/ HelloData
B41: 34 | C41: Broadstone Westgate | D41: 308 | E41: Q2 2025 | F41: 0.89 | G41: — | H41: Alliance Residential Company/American Realty Advisors | I41: 4.9 | J41: Mid-Rise | K41: Delivery quarter estimated; Verify rent/occ w/ HelloData
B42: 35 | C42: The Douglas | D42: 307 | E42: Q2 2025 | F42: 0.583062 | G42: 2076 | H42: UrbanStreet Group | I42: 4.1 | J42: Townhome | K42: Delivery quarter estimated; Rent: CoStar ask $2,076 vs RealPage eff $1,561; Verify rent/occ w/ HelloData
...

Sheet Supply & Absorption
Z1: 8105
B2: SUPPLY & ABSORPTION — 5-MILE MARKET (relative-year / TTM) | Z2: =IFERROR(VALUE(RIGHT($C$5,4))*4+MATCH(LEFT($C$5,2),{"Q1","Q2","Q3","Q4"},0)-1,0)
R3: UNDER CONSTRUCTION (linked from Competitive Analysis) | Z3: =IF($C$7="Bear",3,IF($C$7="Base",2,1))
B4: As-of Quarter | C4: Q2 2026 | R4: Property | S4: Units | T4: Est. Delivery
B5: Close Quarter (Y1 start) | C5: Q4 2026 | R5: ='Competitive Analysis'!C60 | S5: ='Competitive Analysis'!D60 | T5: ='Competitive Analysis'!E60 | V5: =IFERROR(VALUE(RIGHT(T5,4))*4+MATCH(LEFT(T5,2),{"Q1","Q2","Q3","Q4"},0)-1,"") | W5: =IF(V5="","",IF(V5<=$Z$1,0,MAX(1,INT((V5-$Z$2)/4)+1)))
B6: Stabilization Target | C6: 0.95 | R6: ='Competitive Analysis'!C61 | S6: ='Competitive Analysis'!D61 | T6: ='Competitive Analysis'!E61 | V6: =IFERROR(VALUE(RIGHT(T6,4))*4+MATCH(LEFT(T6,2),{"Q1","Q2","Q3","Q4"},0)-1,"") | W6: =IF(V6="","",IF(V6<=$Z$1,0,MAX(1,INT((V6-$Z$2)/4)+1)))
B7: Demand Scenario | C7: Base | R7: ='Competitive Analysis'!C69 | S7: ='Competitive Analysis'!D69 | T7: ='Competitive Analysis'!E69 | V7: =IFERROR(VALUE(RIGHT(T7,4))*4+MATCH(LEFT(T7,2),{"Q1","Q2","Q3","Q4"},0)-1,"") | W7: =IF(V7="","",IF(V7<=$Z$1,0,MAX(1,INT((V7-$Z$2)/4)+1)))
B8: Bear Annual Absorption | C8: 1250 | R8: ='Competitive Analysis'!C63 | S8: ='Competitive Analysis'!D63 | T8: ='Competitive Analysis'!E63 | V8: =IFERROR(VALUE(RIGHT(T8,4))*4+MATCH(LEFT(T8,2),{"Q1","Q2","Q3","Q4"},0)-1,"") | W8: =IF(V8="","",IF(V8<=$Z$1,0,MAX(1,INT((V8-$Z$2)/4)+1)))
B9: Base Annual Absorption | C9: 2525 | R9: ='Competitive Analysis'!C67 | S9: ='Competitive Analysis'!D67 | T9: ='Competitive Analysis'!E67 | V9: =IFERROR(VALUE(RIGHT(T9,4))*4+MATCH(LEFT(T9,2),{"Q1","Q2","Q3","Q4"},0)-1,"") | W9: =IF(V9="","",IF(V9<=$Z$1,0,MAX(1,INT((V9-$Z$2)/4)+1)))
B10: Bull Annual Absorption | C10: 3800 | R10: ='Competitive Analysis'!C68 | S10: ='Competitive Analysis'!D68 | T10: ='Competitive Analysis'!E68 | V10: =IFERROR(VALUE(RIGHT(T10,4))*4+MATCH(LEFT(T10,2),{"Q1","Q2","Q3","Q4"},0)-1,"") | W10: =IF(V10="","",IF(V10<=$Z$1,0,MAX(1,INT((V10-$Z$2)/4)+1)))
B11: Selected Annual Demand | C11: =IF($C$7="Bear",$C$8,IF($C$7="Bull",$C$10,$C$9)) | R11: ='Competitive Analysis'!C64 | S11: ='Competitive Analysis'!D64 | T11: ='Competitive Analysis'!E64 | V11: =IFERROR(VALUE(RIGHT(T11,4))*4+MATCH(LEFT(T11,2),{"Q1","Q2","Q3","Q4"},0)-1,"") | W11: =IF(V11="","",IF(V11<=$Z$1,0,MAX(1,INT((V11-$Z$2)/4)+1)))
R12: ='Competitive Analysis'!C70 | S12: ='Competitive Analysis'!D70 | T12: ='Competitive Analysis'!E70 | V12: =IFERROR(VALUE(RIGHT(T12,4))*4+MATCH(LEFT(T12,2),{"Q1","Q2","Q3","Q4"},0)-1,"") | W12: =IF(V12="","",IF(V12<=$Z$1,0,MAX(1,INT((V12-$Z$2)/4)+1)))
R13: ='Competitive Analysis'!C62 | S13: ='Competitive Analysis'!D62 | T13: ='Competitive Analysis'!E62 | V13: =IFERROR(VALUE(RIGHT(T13,4))*4+MATCH(LEFT(T13,2),{"Q1","Q2","Q3","Q4"},0)-1,"") | W13: =IF(V13="","",IF(V13<=$Z$1,0,MAX(1,INT((V13-$Z$2)/4)+1)))
R14: ='Competitive Analysis'!C65 | S14: ='Competitive Analysis'!D65 | T14: ='Competitive Analysis'!E65 | V14: =IFERROR(VALUE(RIGHT(T14,4))*4+MATCH(LEFT(T14,2),{"Q1","Q2","Q3","Q4"},0)-1,"") | W14: =IF(V14="","",IF(V14<=$Z$1,0,MAX(1,INT((V14-$Z$2)/4)+1)))
R15: ='Competitive Analysis'!C66 | S15: ='Competitive Analysis'!D66 | T15: ='Competitive Analysis'!E66 | V15: =IFERROR(VALUE(RIGHT(T15,4))*4+MATCH(LEFT(T15,2),{"Q1","Q2","Q3","Q4"},0)-1,"") | W15: =IF(V15="","",IF(V15<=$Z$1,0,MAX(1,INT((V15-$Z$2)/4)+1)))
B17: 5-MILE MARKET | C17: -Y6 | D17: -Y5 | E17: -Y4 | F17: -Y3 | G17: -Y2 | H17: -Y1 | I17: Y0 | J17: Y1 | K17: Y2 | L17: Y3 | M17: Y4 | N17: Y5 | O17: Y6 | R17: PROPOSED PIPELINE (scenario toggle)
C18: Q3'19-Q2'20 | D18: Q3'20-Q2'21 | E18: Q3'21-Q2'22 | F18: Q3'22-Q2'23 | G18: Q3'23-Q2'24 | H18: Q3'24-Q2'25 | I18: Q3'25-Q2'26 | J18: Hold Yr 1 | K18: Hold Yr 2 | L18: Hold Yr 3 | M18: Hold Yr 4 | N18: Hold Yr 5 | O18: Hold Yr 6 | R18: Property | S18: Units | T18: Est. Delivery | U18: Built In
B19: NEW SUPPLY (5-mi) | C19: 1133 | D19: 1860 | E19: 1336 | F19: 2280 | G19: 2823 | H19: 4043 | I19: 1860 | J19: =SUMIFS($S$5:$S$15,$W$5:$W$15,1)+SUMIFS($S$19:$S$63,$W$19:$W$63,1,$X$19:$X$63,1) | K19: =SUMIFS($S$5:$S$15,$W$5:$W$15,2)+SUMIFS($S$19:$S$63,$W$19:$W$63,2,$X$19:$X$63,1) | L19: =SUMIFS($S$5:$S$15,$W$5:$W$15,3)+SUMIFS($S$19:$S$63,$W$19:$W$63,3,$X$19:$X$63,1) | M19: =SUMIFS($S$5:$S$15,$W$5:$W$15,4)+SUMIFS($S$19:$S$63,$W$19:$W$63,4,$X$19:$X$63,1) | N19: =SUMIFS($S$5:$S$15,$W$5:$W$15,5)+SUMIFS($S$19:$S$63,$W$19:$W$63,5,$X$19:$X$63,1) | O19: =SUMIFS($S$5:$S$15,$W$5:$W$15,6)+SUMIFS($S$19:$S$63,$W$19:$W$63,6,$X$19:$X$63,1) | R19: Sheely Center Future Phase | S19: 697 | U19: Bear only | V19: =IFERROR(VALUE(RIGHT(T19,4))*4+MATCH(LEFT(T19,2),{"Q1","Q2","Q3","Q4"},0)-1,"") | W19: =IF(V19="","",IF(V19<=$Z$1,0,MAX(1,INT((V19-$Z$2)/4)+1))) | X19: =IF(U19="All",1,IF(U19="Bear+Base",IF($Z$3>=2,1,0),IF(U19="Bear only",IF($Z$3>=3,1,0),0)))
B20: ABSORPTION (5-mi) | C20: 719 | D20: 1876 | E20: 1210 | F20: 685 | G20: 2514 | H20: 2655 | I20: 2369 | J20: =J31-I31 | K20: =K31-J31 | L20: =L31-K31 | M20: =M31-L31 | N20: =N31-M31 | O20: =O31-N31 | R20: Urban 95 Parcel C | S20: 500 | U20: Bear only | V20: =IFERROR(VALUE(RIGHT(T20,4))*4+MATCH(LEFT(T20,2),{"Q1","Q2","Q3","Q4"},0)-1,"") | W20: =IF(V20="","",IF(V20<=$Z$1,0,MAX(1,INT((V20-$Z$2)/4)+1))) | X20: =IF(U20="All",1,IF(U20="Bear+Base",IF($Z$3>=2,1,0),IF(U20="Bear only",IF($Z$3>=3,1,0),0)))
B21: OCCUPANCY (5-mi) | C21: 0.909 | D21: 0.922 | E21: 0.921 | F21: 0.842 | G21: 0.848 | H21: 0.817 | I21: 0.849 | J21: =IFERROR(J31/J30,0) | K21: =IFERROR(K31/K30,0) | L21: =IFERROR(L31/L30,0) | M21: =IFERROR(M31/M30,0) | N21: =IFERROR(N31/N30,0) | O21: =IFERROR(O31/O30,0) | R21: Urban 95 Parcel B | S21: 478 | U21: Bear only | V21: =IFERROR(VALUE(RIGHT(T21,4))*4+MATCH(LEFT(T21,2),{"Q1","Q2","Q3","Q4"},0)-1,"") | W21: =IF(V21="","",IF(V21<=$Z$1,0,MAX(1,INT((V21-$Z$2)/4)+1))) | X21: =IF(U21="All",1,IF(U21="Bear+Base",IF($Z$3>=2,1,0),IF(U21="Bear only",IF($Z$3>=3,1,0),0)))
B22: SUBJECT (Bella Mirage) | R22: Celebration Plaza Parcel B | S22: 410 | U22: Bear only | V22: =IFERROR(VALUE(RIGHT(T22,4))*4+MATCH(LEFT(T22,2),{"Q1","Q2","Q3","Q4"},0)-1,"") | W22: =IF(V22="","",IF(V22<=$Z$1,0,MAX(1,INT((V22-$Z$2)/4)+1))) | X22: =IF(U22="All",1,IF(U22="Bear+Base",IF($Z$3>=2,1,0),IF(U22="Bear only",IF($Z$3>=3,1,0),0)))
B23: Market Rent (CoStar→HD) | C23: 1088 | D23: 1437 | E23: 1730 | F23: 1572 | G23: 1497 | H23: 1444 | I23: =IFERROR('Cash Flow (Annual)'!$F$4,1332) | J23: =IFERROR('Cash Flow (Annual)'!$K$4,"") | K23: =IFERROR('Cash Flow (Annual)'!$L$4,"") | L23: =IFERROR('Cash Flow (Annual)'!$M$4,"") | M23: =IFERROR('Cash Flow (Annual)'!$N$4,"") | N23: =IFERROR('Cash Flow (Annual)'!$O$4,"") | O23: =IFERROR('Cash Flow (Annual)'!$P$4,"") | R23: The District at Westgate | S23: 384 | U23: Bear only | V23: =IFERROR(VALUE(RIGHT(T23,4))*4+MATCH(LEFT(T23,2),{"Q1","Q2","Q3","Q4"},0)-1,"") | W23: =IF(V23="","",IF(V23<=$Z$1,0,MAX(1,INT((V23-$Z$2)/4)+1))) | X23: =IF(U23="All",1,IF(U23="Bear+Base",IF($Z$3>=2,1,0),IF(U23="Bear only",IF($Z$3>=3,1,0),0)))
B24: Market Rent YoY % | D24: =IFERROR(D23/C23-1,"") | E24: =IFERROR(E23/D23-1,"") | F24: =IFERROR(F23/E23-1,"") | G24: =IFERROR(G23/F23-1,"") | H24: =IFERROR(H23/G23-1,"") | I24: =IFERROR(I23/H23-1,"") | J24: =IFERROR(J23/I23-1,"") | K24: =IFERROR(K23/J23-1,"") | ... O24: =IFERROR(O23/N23-1,"") | R24: Picerne at Palm Valley | S24: 383 | U24: Bear only | V24: =IFERROR(VALUE(RIGHT(T24,4))*4+MATCH(LEFT(T24,2),{"Q1","Q2","Q3","Q4"},0)-1,"") | W24: =IF(V24="","",IF(V24<=$Z$1,0,MAX(1,INT((V24-$Z$2)/4)+1))) | X24: =IF(U24="All",1,IF(U24="Bear+Base",IF($Z$3>=2,1,0),IF(U24="Bear only",IF($Z$3>=3,1,0),0)))
B25: Effective Rent | C25: 1086 | D25: 1434 | E25: 1730 | F25: 1555 | G25: 1402 | H25: 1369 | I25: =IFERROR('Cash Flow (Annual)'!$F$5,1301) | J25: =IFERROR('Cash Flow (Annual)'!$K$5,"") | K25: =IFERROR('Cash Flow (Annual)'!$L$5,"") | L25: =IFERROR('Cash Flow (Annual)'!$M$5,"") | M25: =IFERROR('Cash Flow (Annual)'!$N$5,"") | N25: =IFERROR('Cash Flow (Annual)'!$O$5,"") | O25: =IFERROR('Cash Flow (Annual)'!$P$5,"") | R25: Liv Avondale | S25: 333 | U25: Bear only | V25: =IFERROR(VALUE(RIGHT(T25,4))*4+MATCH(LEFT(T25,2),{"Q1","Q2","Q3","Q4"},0)-1,"") | W25: =IF(V25="","",IF(V25<=$Z$1,0,MAX(1,INT((V25-$Z$2)/4)+1))) | X25: =IF(U25="All",1,IF(U25="Bear+Base",IF($Z$3>=2,1,0),IF(U25="Bear only",IF($Z$3>=3,1,0),0)))
B26: Effective Rent YoY % | D26: =IFERROR(D25/C25-1,"") | E26: =IFERROR(E25/D25-1,"") | F26: =IFERROR(F25/E25-1,"") | G26: =IFERROR(G25/F25-1,"") | H26: =IFERROR(H25/G25-1,"") | I26: =IFERROR(I25/H25-1,"") | J26: =IFERROR(J25/I25-1,"") | K26: =IFERROR(K25/J25-1,"") | ... O26: =IFERROR(O25/N25-1,"") | R26: Urban 95 Parcel A | S26: 324 | U26: Bear only | V26: =IFERROR(VALUE(RIGHT(T26,4))*4+MATCH(LEFT(T26,2),{"Q1","Q2","Q3","Q4"},0)-1,"") | W26: =IF(V26="","",IF(V26<=$Z$1,0,MAX(1,INT((V26-$Z$2)/4)+1))) | X26: =IF(U26="All",1,IF(U26="Bear+Base",IF($Z$3>=2,1,0),IF(U26="Bear only",IF($Z$3>=3,1,0),0)))
B27: Occupancy (financials / CoStar) | C27: 0.95034965 | D27: 0.95769231 | E27: 0.9458042 | F27: 0.87889712 | G27: 0.91737132 | H27: 0.93348546 | I27: =IFERROR('Cash Flow (Annual)'!$F$14,0.9206643232607364) | J27: =IFERROR('Cash Flow (Annual)'!$K$14,"") | K27: =IFERROR('Cash Flow (Annual)'!$L$14,"") | L27: =IFERROR('Cash Flow (Annual)'!$M$14,"") | M27: =IFERROR('Cash Flow (Annual)'!$N$14,"") | N27: =IFERROR('Cash Flow (Annual)'!$O$14,"") | O27: =IFERROR('Cash Flow (Annual)'!$P$14,"") | R27: The Waverly | S27: 323 | T27: Q3 2028 | U27: Bear only | V27: =IFERROR(VALUE(RIGHT(T27,4))*4+MATCH(LEFT(T27,2),{"Q1","Q2","Q3","Q4"},0)-1,"") | W27: =IF(V27="","",IF(V27<=$Z$1,0,MAX(1,INT((V27-$Z$2)/4)+1))) | X27: =IF(U27="All",1,IF(U27="Bear+Base",IF($Z$3>=2,1,0),IF(U27="Bear only",IF($Z$3>=3,1,0),0)))
B28: Concession % | C28: =IFERROR((C23-C25)/C23,"") | D28: =IFERROR((D23-D25)/D23,"") | E28: =IFERROR((E23-E25)/E23,"") | F28: =IFERROR((F23-F25)/F23,"") | G28: =IFERROR((G23-G25)/G23,"") | H28: =IFERROR((H23-H25)/H23,"") | I28: =IFERROR((I23-I25)/I23,"") | J28: =IFERROR((J23-J25)/J23,"") | ... O28: =IFERROR((O23-O25)/O23,"") | R28: Fuze 623 | S28: 321 | U28: Bear only | V28: =IFERROR(VALUE(RIGHT(T28,4))*4+MATCH(LEFT(T28,2),{"Q1","Q2","Q3","Q4"},0)-1,"") | W28: =IF(V28="","",IF(V28<=$Z$1,0,MAX(1,INT((V28-$Z$2)/4)+1))) | X28: =IF(U28="All",1,IF(U28="Bear+Base",IF($Z$3>=2,1,0),IF(U28="Bear only",IF($Z$3>=3,1,0),0)))
R29: Anton Glendale | S29: 320 | U29: Bear only | V29: =IFERROR(VALUE(RIGHT(T29,4))*4+MATCH(LEFT(T29,2),{"Q1","Q2","Q3","Q4"},0)-1,"") | W29: =IF(V29="","",IF(V29<=$Z$1,0,MAX(1,INT((V29-$Z$2)/4)+1))) | X29: =IF(U29="All",1,IF(U29="Bear+Base",IF($Z$3>=2,1,0),IF(U29="Bear only",IF($Z$3>=3,1,0),0)))
B30: inventory | C30: 12401 | D30: 14261 | E30: 15597 | F30: 17877 | G30: 20700 | H30: 24743 | I30: 26603 | J30: =I30+J19 | K30: =J30+K19 | L30: =K30+L19 | M30: =L30+M19 | N30: =M30+N19 | O30: =N30+O19 | R30: Western Garden II | S30: 314 | U30: Bear only | V30: =IFERROR(VALUE(RIGHT(T30,4))*4+MATCH(LEFT(T30,2),{"Q1","Q2","Q3","Q4"},0)-1,"") | W30: =IF(V30="","",IF(V30<=$Z$1,0,MAX(1,INT((V30-$Z$2)/4)+1))) | X30: =IF(U30="All",1,IF(U30="Bear+Base",IF($Z$3>=2,1,0),IF(U30="Bear only",IF($Z$3>=3,1,0),0)))
B31: occupied | C31: 11277 | D31: 13152 | E31: 14362 | F31: 15047 | G31: 17560 | H31: 20215 | I31: 22585 | J31: =MIN($C$6*J30,I31+$C$11) | K31: =MIN($C$6*K30,J31+$C$11) | L31: =MIN($C$6*L30,K31+$C$11) | M31: =MIN($C$6*M30,L31+$C$11) | N31: =MIN($C$6*N30,M31+$C$11) | O31: =MIN($C$6*O30,N31+$C$11) | R31: Sanctuair at Centerscape | S31: 303 | U31: Bear only | V31: =IFERROR(VALUE(RIGHT(T31,4))*4+MATCH(LEFT(T31,2),{"Q1","Q2","Q3","Q4"},0)-1,"") | W31: =IF(V31="","",IF(V31<=$Z$1,0,MAX(1,INT((V31-$Z$2)/4)+1))) | X31: =IF(U31="All",1,IF(U31="Bear+Base",IF($Z$3>=2,1,0),IF(U31="Bear only",IF($Z$3>=3,1,0),0)))
R32: Encore Avondale | S32: 300 | T32: Q3 2028 | U32: Bear only | V32: =IFERROR(VALUE(RIGHT(T32,4))*4+MATCH(LEFT(T32,2),{"Q1","Q2","Q3","Q4"},0)-1,"") | W32: =IF(V32="","",IF(V32<=$Z$1,0,MAX(1,INT((V32-$Z$2)/4)+1))) | X32: =IF(U32="All",1,IF(U32="Bear+Base",IF($Z$3>=2,1,0),IF(U32="Bear only",IF($Z$3>=3,1,0),0)))
B33: MARKET-RENT GROWTH — TMG vs 3RD-PARTY FORECAST | J33: Y1 | K33: Y2 | L33: Y3 | M33: Y4 | N33: Y5 | O33: Y6 | P33: AVG | R33: Banyan Avondale | S33: 296 | U33: Bear only | V33: =IFERROR(VALUE(RIGHT(T33,4))*4+MATCH(LEFT(T33,2),{"Q1","Q2","Q3","Q4"},0)-1,"") | W33: =IF(V33="","",IF(V33<=$Z$1,0,MAX(1,INT((V33-$Z$2)/4)+1))) | X33: =IF(U33="All",1,IF(U33="Bear+Base",IF($Z$3>=2,1,0),IF(U33="Bear only",IF($Z$3>=3,1,0),0)))
B34: CoStar | J34: =IFERROR('Rent & Occ Data'!$C$31,"") | K34: =IFERROR('Rent & Occ Data'!$D$31,"") | L34: =IFERROR('Rent & Occ Data'!$E$31,"") | M34: =IFERROR('Rent & Occ Data'!$F$31,"") | N34: =IFERROR('Rent & Occ Data'!$G$31,"") | O34: =IFERROR('Rent & Occ Data'!$H$31,"") | P34: =IFERROR(AVERAGE(J34:O34),"") | R34: Rosilian Villas | S34: 291 | U34: Bear only | V34: =IFERROR(VALUE(RIGHT(T34,4))*4+MATCH(LEFT(T34,2),{"Q1","Q2","Q3","Q4"},0)-1,"") | W34: =IF(V34="","",IF(V34<=$Z$1,0,MAX(1,INT((V34-$Z$2)/4)+1))) | X34: =IF(U34="All",1,IF(U34="Bear+Base",IF($Z$3>=2,1,0),IF(U34="Bear only",IF($Z$3>=3,1,0),0)))
B35: RealPage | J35: =IFERROR('Rent & Occ Data'!$C$32,"") | K35: =IFERROR('Rent & Occ Data'!$D$32,"") | L35: =IFERROR('Rent & Occ Data'!$E$32,"") | M35: =IFERROR('Rent & Occ Data'!$F$32,"") | N35: =IFERROR('Rent & Occ Data'!$G$32,"") | O35: =IFERROR('Rent & Occ Data'!$H$32,"") | P35: =IFERROR(AVERAGE(J35:O35),"") | R35: The Statler at Estrella Parkway | S35: 284 | T35: Q3 2028 | U35: Bear only | V35: =IFERROR(VALUE(RIGHT(T35,4))*4+MATCH(LEFT(T35,2),{"Q1","Q2","Q3","Q4"},0)-1,"") | W35: =IF(V35="","",IF(V35<=$Z$1,0,MAX(1,INT((V35-$Z$2)/4)+1))) | X35: =IF(U35="All",1,IF(U35="Bear+Base",IF($Z$3>=2,1,0),IF(U35="Bear only",IF($Z$3>=3,1,0),0)))
B36: Yardi | J36: =IFERROR('Rent & Occ Data'!$C$33,"") | K36: =IFERROR('Rent & Occ Data'!$D$33,"") | L36: =IFERROR('Rent & Occ Data'!$E$33,"") | M36: =IFERROR('Rent & Occ Data'!$F$33,"") | N36: =IFERROR('Rent & Occ Data'!$G$33,"") | O36: =IFERROR('Rent & Occ Data'!$H$33,"") | P36: =IFERROR(AVERAGE(J36:O36),"") | R36: Orion Avondale | S36: 268 | U36: Bear only | V36: =IFERROR(VALUE(RIGHT(T36,4))*4+MATCH(LEFT(T36,2),{"Q1","Q2","Q3","Q4"},0)-1,"") | W36: =IF(V36="","",IF(V36<=$Z$1,0,MAX(1,INT((V36-$Z$2)/4)+1))) | X36: =IF(U36="All",1,IF(U36="Bear+Base",IF($Z$3>=2,1,0),IF(U36="Bear only",IF($Z$3>=3,1,0),0)))
B37: GreenStreet | J37: =IFERROR('Rent & Occ Data'!$C$34,"") | K37: =IFERROR('Rent & Occ Data'!$D$34,"") | L37: =IFERROR('Rent & Occ Data'!$E$34,"") | M37: =IFERROR('Rent & Occ Data'!$F$34,"") | N37: =IFERROR('Rent & Occ Data'!$G$34,"") | O37: =IFERROR('Rent & Occ Data'!$H$34,"") | P37: =IFERROR(AVERAGE(J37:O37),"") | R37: Tavalo at Avondale | S37: 266 | U37: Bear only | V37: =IFERROR(VALUE(RIGHT(T37,4))*4+MATCH(LEFT(T37,2),{"Q1","Q2","Q3","Q4"},0)-1,"") | W37: =IF(V37="","",IF(V37<=$Z$1,0,MAX(1,INT((V37-$Z$2)/4)+1))) | X37: =IF(U37="All",1,IF(U37="Bear+Base",IF($Z$3>=2,1,0),IF(U37="Bear only",IF($Z$3>=3,1,0),0)))
B38: Consensus (4-source avg) | J38: =IFERROR(AVERAGE(J34:J37),"") | K38: =IFERROR(AVERAGE(K34:K37),"") | L38: =IFERROR(AVERAGE(L34:L37),"") | M38: =IFERROR(AVERAGE(M34:M37),"") | N38: =IFERROR(AVERAGE(N34:N37),"") | O38: =IFERROR(AVERAGE(O34:O37),"") | P38: =IFERROR(AVERAGE(P34:P37),"") | R38: Marbella Ranch East Future Phase | S38: 266 | U38: Bear only | V38: =IFERROR(VALUE(RIGHT(T38,4))*4+MATCH(LEFT(T38,2),{"Q1","Q2","Q3","Q4"},0)-1,"") | W38: =IF(V38="","",IF(V38<=$Z$1,0,MAX(1,INT((V38-$Z$2)/4)+1))) | X38: =IF(U38="All",1,IF(U38="Bear+Base",IF($Z$3>=2,1,0),IF(U38="Bear only",IF($Z$3>=3,1,0),0)))
B39: TMG — our market-rent growth ◄ | J39: =IFERROR(J24,"") | K39: =IFERROR(K24,"") | L39: =IFERROR(L24,"") | M39: =IFERROR(M24,"") | N39: =IFERROR(N24,"") | O39: =IFERROR(O24,"") | P39: =IFERROR(AVERAGE(J39:O39),"") | R39: Crystal Cove | S39: 260 | U39: Bear only | V39: =IFERROR(VALUE(RIGHT(T39,4))*4+MATCH(LEFT(T39,2),{"Q1","Q2","Q3","Q4"},0)-1,"") | W39: =IF(V39="","",IF(V39<=$Z$1,0,MAX(1,INT((V39-$Z$2)/4)+1))) | X39: =IF(U39="All",1,IF(U39="Bear+Base",IF($Z$3>=2,1,0),IF(U39="Bear only",IF($Z$3>=3,1,0),0)))
R40: SimonMed Development I | S40: 239 | U40: Bear only | V40: =IFERROR(VALUE(RIGHT(T40,4))*4+MATCH(LEFT(T40,2),{"Q1","Q2","Q3","Q4"},0)-1,"") | W40: =IF(V40="","",IF(V40<=$Z$1,0,MAX(1,INT((V40-$Z$2)/4)+1))) | X40: =IF(U40="All",1,IF(U40="Bear+Base",IF($Z$3>=2,1,0),IF(U40="Bear only",IF($Z$3>=3,1,0),0)))
B41: ▸ SCENARIO INPUTS — Bear / Base / Bull (implied occupancy, rent-growth & concession assumptions — click + to expand) | R41: Cornerstone at the Wigwam | S41: 212 | U41: Bear only | V41: =IFERROR(VALUE(RIGHT(T41,4))*4+MATCH(LEFT(T41,2),{"Q1","Q2","Q3","Q4"},0)-1,"") | W41: =IF(V41="","",IF(V41<=$Z$1,0,MAX(1,INT((V41-$Z$2)/4)+1))) | X41: =IF(U41="All",1,IF(U41="Bear+Base",IF($Z$3>=2,1,0),IF(U41="Bear only",IF($Z$3>=3,1,0),0)))
...

Sheet Reconciliation Log
A1: Property | B1: Address | C1: Units | D1: Year Built | E1: Est. Delivery | F1: Bucket | G1: CoStar Occ | H1: RealPage Occ | I1: CoStar Ask Rent | J1: RealPage Eff Rent | K1: Sources | L1: Notes
A2: Avery | B2: 1700 N Harbor Shore Blvd | C2: 185 | D2: 2024 | E2: Q2 2024 | F2: STABILIZED / STABILIZING | G2: 0.924324 | H2: 0.924 | I2: 1750 | J2: 1875 | K2: CoStar+RealPage | L2: Rent: CoStar ask $1,750 vs RealPage eff $1,875
A3: Ironwood at River Run | B3: 11951 W Windsor Ave | C3: 103 | D3: 2024 | E3: Q2 2024 | F3: STABILIZED / STABILIZING | H3: 0.961 | J3: 2090 | K3: RealPage | L3: Delivery quarter estimated
A4: TerraLane at Park McDowell | B4: 2250 N 95th Ave | C4: 162 | D4: 2023 | E4: Q1 2023 | F4: STABILIZED / STABILIZING | G4: 0.851852 | H4: 0.877 | I4: 1576 | J4: 1211 | K4: CoStar+RealPage | L4: Delivery quarter estimated; Occ: CoStar 85% vs RealPage 88%; Rent: CoStar ask $1,576 vs RealPage eff $1,211
A5: Bungalows at Camelback | B5: 4747 N 99th Ave | C5: 334 | D5: 2023 | E5: Q1 2023 | F5: STABILIZED / STABILIZING | G5: 0.763473 | H5: 0.916 | I5: 2026 | J5: 1385 | K5: CoStar+RealPage | L5: Year built: 2023/2024; Delivery quarter estimated; Occ: CoStar 76% vs RealPage 92%; Rent: CoStar ask $2,026 vs RealPage eff $1,385
A6: Prose Desert River | B6: 7430 N 100th Ave | C6: 384 | D6: 2023 | E6: Q1 2023 | F6: STABILIZED / STABILIZING | G6: 0.895833 | H6: 0.966 | I6: 1429 | J6: 1313 | K6: CoStar+RealPage | L6: Year built: 2023/2024; Delivery quarter estimated; Occ: CoStar 90% vs RealPage 97%; Rent: CoStar ask $1,429 vs RealPage eff $1,313
A7: Christopher Todd Communities at McDowell | B7: 1350 N 117th Ave | C7: 217 | D7: 2023 | E7: Q1 2023 | F7: STABILIZED / STABILIZING | G7: 0.949309 | H7: 0.968 | I7: 1576 | J7: 1602 | K7: CoStar+RealPage | L7: Year built: 2023/2024; Delivery quarter estimated
A8: Village Camelback Park | B8: 11200 W Camelback Rd | C8: 194 | D8: 2023 | E8: Q1 2023 | F8: STABILIZED / STABILIZING | G8: 0.773196 | H8: 0.918 | I8: 1874 | J8: 1794 | K8: CoStar+RealPage | L8: Delivery quarter estimated; Occ: CoStar 77% vs RealPage 92%
A9: Springs At Westgate | B9: 10020 W Glendale Ave | C9: 292 | D9: 2023 | E9: Q1 2023 | F9: STABILIZED / STABILIZING | G9: 0.784247 | H9: 0.87 | I9: 1516 | J9: 1517 | K9: CoStar+RealPage | L9: Year built: 2023/2024; Delivery quarter estimated; Occ: CoStar 78% vs RealPage 87%
A10: Parc Lofts | B10: 8727 W McDowell Rd | C10: 258 | D10: 2023 | E10: Q1 2023 | F10: STABILIZED / STABILIZING | G10: 0.899225 | H10: 0.942 | I10: 1567 | J10: 1591 | K10: CoStar+RealPage | L10: Delivery quarter estimated; Occ: CoStar 90% vs RealPage 94%
A11: The Crofton at Sheely Farms | B11: 9200 W McDowell Rd | C11: 167 | D11: 2023 | E11: Q1 2023 | F11: STABILIZED / STABILIZING | G11: 0.952096 | H11: 0.946 | I11: 1607 | J11: 1388 | K11: CoStar+RealPage | L11: Delivery quarter estimated; Rent: CoStar ask $1,607 vs RealPage eff $1,388
A12: District at Civic Square | B12: 15400 W Monte Vista Rd | C12: 352 | D12: 2023 | E12: Q1 2023 | F12: STABILIZED / STABILIZING | G12: 0.920455 | H12: 1 | I12: 1526 | J12: 1263 | K12: CoStar+RealPage | L12: Year built: 2023/2024; Delivery quarter estimated; Occ: CoStar 92% vs RealPage 100%; Rent: CoStar ask $1,526 vs RealPage eff $1,263
A13: BB Living at Civic Square | B13: 15125 W Oak St | C13: 290 | D13: 2023 | E13: Q1 2023 | F13: STABILIZED / STABILIZING | G13: 0.934483 | H13: 0.959 | I13: 2812 | J13: 2575 | K13: CoStar+RealPage | L13: Year built: 2023/2024; Delivery quarter estimated; Occ: CoStar 93% vs RealPage 96%; Rent: CoStar ask $2,812 vs RealPage eff $2,575
A14: Village at the BLVD | B14: 11175 W Roosevelt Rd | C14: 187 | D14: 2023 | E14: Q1 2023 | F14: STABILIZED / STABILIZING | G14: 0.935829 | H14: 0.963 | I14: 1964 | J14: 1902 | K14: CoStar+RealPage | L14: Year built: 2023/2024; Delivery quarter estimated; Occ: CoStar 94% vs RealPage 96%
A15: Acero Roosevelt | B15: 15400 W Roosevelt St | C15: 352 | D15: 2023 | E15: Q1 2023 | F15: STABILIZED / STABILIZING | G15: 0.892045 | H15: 0.94 | I15: 1632 | J15: 1236 | K15: CoStar+RealPage | L15: Year built: 2023/2024; Delivery quarter estimated; Occ: CoStar 89% vs RealPage 94%; Rent: CoStar ask $1,632 vs RealPage eff $1,236
... A17: Cabana Bullard | B17: 14780 W Van Buren St | C17: 336 | D17: 2023 | E17: Q1 2023 | F17: STABILIZED / STABILIZING | G17: 0.949405 | H17: 0.949 | I17: 1335 | J17: 1325 | K17: CoStar+RealPage | L17: Delivery quarter estimated
A18: Ironwood Homes at River Run | B18: 11901 W Windsor Ave | C18: 103 | D18: 2023 | E18: Q1 2023 | F18: STABILIZED / STABILIZING | G18: 0.893204 | I18: 2523 | K18: CoStar | L18: Delivery quarter estimated
A19: Cuvee Apartments | B19: 7200 N 91st Ave | C19: 310 | D19: 2023 | E19: Q1 2023 | F19: STABILIZED / STABILIZING | H19: 0.926 | J19: 1629 | K19: RealPage | L19: Delivery quarter estimated
A20: Avari Apartments | B20: 11580 W Corporate Dr | C20: 354 | D20: 2022 | E20: Q3 2022 | F20: STABILIZED / STABILIZING | G20: 0.951977 | H20: 1 | I20: 1574 | J20: 1583 | K20: CoStar+RealPage | L20: Year built: 2022/2023; Delivery quarter estimated; Occ: CoStar 95% vs RealPage 100%
A21: Sunset View Apartments | B21: 2323 N 150th Dr | C21: 286 | D21: 2022 | E21: Q2 2022 | F21: STABILIZED / STABILIZING | G21: 0.902098 | H21: 0.955 | I21: 1338 | J21: 1167 | K21: CoStar+RealPage | L21: Occ: CoStar 90% vs RealPage 96%; Rent: CoStar ask $1,338 vs RealPage eff $1,167
A22: Cyrene at Estrella | B22: 15430 W Baden St | C22: 64 | D22: 2022 | E22: Q1 2022 | F22: STABILIZED / STABILIZING | G22: 0.984375 | H22: 0.984 | I22: 2442 | J22: 2261 | K22: CoStar+RealPage | L22: Year built: 2022/2023; Delivery quarter estimated; Rent: CoStar ask $2,442 vs RealPage eff $2,261
A23: Luna Bear 94 | B23: 9000 W Indian School Rd | C23: 94 | D23: 2022 | E23: Q1 2022 | F23: STABILIZED / STABILIZING | G23: 0.989362 | H23: 1 | I23: 1913 | J23: 1982 | K23: CoStar+RealPage
A24: Avilla Western Garden | B24: 4041 N 97th Ave | C24: 195 | D24: 2026 | E24: Q2 2026 | F24: LEASING UP | G24: 0.446154 | H24: 0 | I24: 1829 | J24: 1681 | K24: CoStar+RealPage | L24: Delivery quarter estimated; Occ: CoStar 45% vs RealPage 0%; Rent: CoStar ask $1,829 vs RealPage eff $1,681; Verify rent/occ w/ HelloData
A25: Liberty at Estrella Falls | B25: 2505 N 153rd Dr | C25: 106 | D25: 2026 | E25: Q2 2026 | F25: LEASING UP | G25: 0.056604 | H25: 0.208 | I25: 2966 | J25: 1938 | K25: CoStar+RealPage | L25: Delivery quarter estimated; Occ: CoStar 6% vs RealPage 21%; Rent: CoStar ask $2,966 vs RealPage eff $1,938; Verify rent/occ w/ HelloData
A26: Rev3 at Avondale Station | B26: 9980 W Encanto Blvd | C26: 117 | D26: 2026 | E26: Q2 2026 | F26: LEASING UP | G26: 0.273504 | H26: 0 | I26: 2537 | J26: 2273 | K26: CoStar+RealPage | L26: Units: CoStar 117 vs RealPage 107; Delivery quarter estimated; Occ: CoStar 27% vs RealPage 0%; Rent: CoStar ask $2,537 vs RealPage eff $2,273; Verify rent/occ w/ HelloData
A27: Flatz 623 | B27: 11850 W Fillmore St | C27: 360 | D27: 2026 | E27: Q2 2026 | F27: LEASING UP | G27: 0.133333 | I27: 1411 | K27: CoStar | L27: Delivery quarter estimated; Verify rent/occ w/ HelloData
A28: Stately Avondale | B28: 12375 W Van Buren St | C28: 286 | D28: 2026 | E28: Q2 2026 | F28: LEASING UP | G28: 0.297203 | H28: 0 | I28: 1728 | J28: 1243 | K28: CoStar+RealPage | L28: Year built: 2026/2027; Delivery quarter estimated; Occ: CoStar 30% vs RealPage 0%; Rent: CoStar ask $1,728 vs RealPage eff $1,243; Verify rent/occ w/ HelloData
A29: Broadstone Ascend | B29: 12905 W Indian School Rd | C29: 432 | D29: 2025 | E29: Q4 2025 | F29: LEASING UP | G29: 0.875 | H29: 0.512 | I29: 1506 | J29: 1107 | K29: CoStar+RealPage | L29: Year built: 2025/2026; Delivery quarter estimated; Occ: CoStar 88% vs RealPage 51%; Rent: CoStar ask $1,506 vs RealPage eff $1,107; Verify rent/occ w/ HelloData
A30: Pradera Estates | B30: 12616 W Adair Dr | C30: 86 | D30: 2025 | E30: Q3 2025 | F30: LEASING UP | G30: 0.895349 | I30: 2474 | K30: CoStar | L30: Delivery quarter estimated; Verify rent/occ w/ HelloData
A31: Rev3 Encanto West | B31: 2150 N Avondale Blvd | C31: 84 | D31: 2025 | E31: Q3 2025 | F31: LEASING UP | G31: 0.52381 | H31: 0.714 | I31: 2319 | J31: 1833 | K31: CoStar+RealPage | L31: Units: CoStar 84 vs RealPage 78; Year built: 2025/2026; Occ: CoStar 52% vs RealPage 71%; Rent: CoStar ask $2,319 vs RealPage eff $1,833; Verify rent/occ w/ HelloData
A32: Villas Litchfield Park | B32: 12730 W Camelback Rd | C32: 153 | D32: 2025 | E32: Q3 2025 | F32: LEASING UP | G32: 0.810458 | H32: 0.856 | I32: 1913 | J32: 1538 | K32: CoStar+RealPage | L32: Delivery quarter estimated; Occ: CoStar 81% vs RealPage 86%; Rent: CoStar ask $1,913 vs RealPage eff $1,538; Verify rent/occ w/ HelloData
A33: Avalon Townhomes | B33: 13025 W Thomas Rd | C33: 70 | D33: 2025 | E33: Q3 2025 | F33: LEASING UP | G33: 0.857143 | H33: 0.857 | I33: 2325 | J33: 2169 | K33: CoStar+RealPage | L33: Delivery quarter estimated; Rent: CoStar ask $2,325 vs RealPage eff $2,169; Verify rent/occ w/ HelloData
A34: Villas on Van Buren | B34: 9835 W Van Buren St | C34: 143 | D34: 2025 | E34: Q3 2025 | F34: LEASING UP | G34: 0.496503 | H34: 0 | I34: 2085 | J34: 2095 | K34: CoStar+RealPage | L34: Year built: 2025/2026; Delivery quarter estimated; Occ: CoStar 50% vs RealPage 0%; Verify rent/occ w/ HelloData
A35: Agave Ranch | B35: 10060 W Desert Blvd | C35: 324 | D35: 2025 | E35: Q2 2025 | F35: LEASING UP | G35: 0.802469 | H35: 0 | I35: 1747 | J35: 1582 | K35: CoStar+RealPage | L35: Delivery quarter estimated; Occ: CoStar 80% vs RealPage 0%; Rent: CoStar ask $1,747 vs RealPage eff $1,582; Verify rent/occ w/ HelloData
A36: Alta Goodyear | B36: 14965 W Encanto Blvd | C36: 342 | D36: 2025 | E36: Q2 2025 | F36: LEASING UP | G36: 0.789474 | H36: 0.784 | I36: 1638 | J36: 1433 | K36: CoStar+RealPage | L36: Delivery quarter estimated; Rent: CoStar ask $1,638 vs RealPage eff $1,433; Verify rent/occ w/ HelloData
A37: Village at Skyline Ranch | B37: 13215 W Glendale Ave | C37: 167 | D37: 2025 | E37: Q2 2025 | F37: LEASING UP | G37: 0.39521 | H37: 0 | I37: 1773 | J37: 1632 | K37: CoStar+RealPage | L37: Year built: 2025/2026; Delivery quarter estimated; Occ: CoStar 40% vs RealPage 0%; Rent: CoStar ask $1,773 vs RealPage eff $1,632; Verify rent/occ w/ HelloData
A38: Avondale Commons | B38: 11650 W McDowell Rd | C38: 324 | D38: 2025 | E38: Q2 2025 | F38: LEASING UP | G38: 0.37037 | H38: 0.852 | I38: 1632 | J38: 1321 | K38: CoStar+RealPage | L38: Year built: 2025/2026; Delivery quarter estimated; Occ: CoStar 37% vs RealPage 85%; Rent: CoStar ask $1,632 vs RealPage eff $1,321; Verify rent/occ w/ HelloData
A39: Cabana Aldea | B39: 9910 W Montebello Ave | C39: 257 | D39: 2025 | E39: Q2 2025 | F39: LEASING UP | G39: 0.7393 | H39: 0.673 | I39: 1330 | J39: 1253 | K39: CoStar+RealPage | L39: Delivery quarter estimated; Occ: CoStar 74% vs RealPage 67%; Rent: CoStar ask $1,330 vs RealPage eff $1,253; Verify rent/occ w/ HelloData
A40: The Douglas | B40: 14935 W Van Buren St | C40: 307 | D40: 2025 | E40: Q2 2025 | F40: LEASING UP | G40: 0.583062 | H40: 0.59 | I40: 2076 | J40: 1561 | K40: CoStar+RealPage | L40: Delivery quarter estimated; Rent: CoStar ask $2,076 vs RealPage eff $1,561; Verify rent/occ w/ HelloData
A41: Broadstone Westgate | B41: 6851 N 93RD Ave | C41: 308 | D41: 2025 | E41: Q2 2025 | F41: LEASING UP | H41: 0.89 | J41: 1438 | K41: RealPage | L41: Delivery quarter estimated; Verify rent/occ w/ HelloData
...
