Workbook
Name CodeList: Codes!$A$5:$A$59

Sheet Dashboard
A1: Bella Mirage — Underwriting Intake
A2: Generated June 19, 2026 · RR-T12 Processor intake · Operating period Jan 2023 – Dec 2025 (36 mo, 3 statements stitched)
A3: Data vintage · Rent roll as-of 05/23/2026 · Latest financial statement thru Dec 2025
A4: SNAPSHOT | D4: UNIT MIX — mix-weighted market-rent indicators
A5: Units | B5: 715 | D5: Floor Plan | E5: Bed | F5: Bath | G5: Units | H5: Occ | I5: Vac | J5: Avg SF | K5: Avg Market Rent (per RR — not a mkt signal) | L5: Avg Contract Rent | M5: New Leases | N5: Renew Leases | O5: Avg New-Lease (last 5) | P5: New #1 | Q5: New #2 | R5: New #3 | S5: New #4 | T5: New #5 | U5: HD T90 Asking | V5: HD T90 Effective | W5: HD T365 Asking | X5: HD T365 Effective | Y5: HD90 YoY Asking | Z5: HD90 YoY Effective | AA5: Bed/Bath Src | AB5: HD Plan (website)
A6: Occupied / Vacant / Non-Rev | B6: 643 / 72 / 0 | D6: A1 | E6: 1 | F6: 1 | G6: 71 | H6: 65 | I6: 6 | J6: 739 | K6: 1153 | L6: 1196 | M6: 34 | N6: 31 | O6: 1088 | P6: 1055 | Q6: 1092 | R6: 1167 | S6: 1119 | T6: 1008 | U6: 1079 | V6: 1079 | W6: 1125 | X6: 1093 | Y6: -0.11545106 | Z6: -0.041378435 | AA6: inferred | AB6: Brook
A7: Occupancy % | B7: 0.8993007 | D7: A1R | E7: 1 | F7: 1 | G7: 16 | H7: 12 | I7: 4 | J7: 739 | K7: 1290 | L7: 1325 | M7: 5 | N7: 7 | O7: 1215 | P7: 1218 | Q7: 1134 | R7: 1102 | S7: 1408 | T7: 1215 | U7: 1178 | V7: 1178 | W7: 1211 | X7: 1175 | Y7: -0.16370739 | Z7: -0.094230769 | AA7: inferred | AB7: Brook
A8: Total Rentable SF | B8: 677256 | D8: A2 | E8: 1 | F8: 1 | G8: 196 | H8: 179 | I8: 17 | J8: 777 | K8: 1206 | L8: 1246 | M8: 88 | N8: 91 | O8: 1164 | P8: 1066 | Q8: 1180 | R8: 1148 | S8: 1143 | T8: 1281 | U8: 1160 | V8: 1160 | W8: 1162 | X8: 1142 | Y8: -0.077481014 | Z8: 0.0034438034 | AA8: inferred | AB8: Cascade
A9: New / Renewal leases | B9: 318 / 325 | D9: A2R | E9: 1 | F9: 1 | G9: 50 | H9: 40 | I9: 10 | J9: 777 | K9: 1320 | L9: 1321 | M9: 27 | N9: 13 | O9: 1226 | P9: 1266 | Q9: 1238 | R9: 1249 | S9: 1192 | T9: 1184 | U9: 1234 | V9: 1234 | W9: 1256 | X9: 1223 | Y9: -0.04894027 | Z9: 0.031772575 | AA9: inferred | AB9: Cascade
A10: — Market Rent Indicators (true signal) — | D10: B1 | E10: 2 | F10: 2 | G10: 116 | H10: 111 | I10: 5 | J10: 947 | K10: 1418 | L10: 1445 | M10: 53 | N10: 58 | O10: 1347 | P10: 1466 | Q10: 1207 | R10: 1290 | S10: 1333 | T10: 1438 | U10: 1340 | V10: 1340 | W10: 1329 | X10: 1299 | Y10: -0.039404893 | Z10: 0.044571503 | AA10: inferred | AB10: Rain
A11: HelloData asking, T90 (mix-wtd) | B11: 1391 | D11: B1R | E11: 2 | F11: 2 | G11: 34 | H11: 28 | I11: 6 | J11: 947 | K11: 1543 | L11: 1504 | M11: 20 | N11: 8 | O11: 1471 | P11: 1394 | Q11: 1449 | R11: 1606 | S11: 1423 | T11: 1484 | U11: 1383 | V11: 1383 | W11: 1470 | X11: 1438 | Y11: -0.063219688 | Z11: 0.017244197 | AA11: inferred | AB11: Rain
A12: HelloData effective, T90 (mix-wtd) | B12: 1391 | D12: B2 | E12: 2 | F12: 2 | G12: 17 | H12: 16 | I12: 1 | J12: 1040 | K12: 1586 | L12: 1574 | M12: 7 | N12: 9 | O12: 1559 | P12: 1586 | Q12: 1638 | R12: 1443 | S12: 1623 | T12: 1505 | U12: 1579 | V12: 1579 | W12: 1540 | X12: 1500 | Y12: 0.035862672 | Z12: 0.12491095 | AA12: inferred | AB12: Isla
A13: New-lease contract, T90 (avg) | B13: 1329 | D13: B2R | E13: 2 | F13: 2 | G13: 4 | H13: 4 | I13: 0 | J13: 1040 | K13: 1702 | L13: 1822 | M13: 2 | N13: 2 | O13: 1792 | P13: 1771 | Q13: 1813 | U13: 1813 | V13: 1813 | W13: 1813 | X13: 1813 | Y13: 0.1893724 | Z13: 0.29161719 | AA13: inferred | AB13: Isla
A14: — T12 Annualized (most recent 12 mo.) — | D14: B3 | E14: 2 | F14: 2 | G14: 15 | H14: 13 | I14: 2 | J14: 1173 | K14: 1824 | L14: 1702 | M14: 5 | N14: 8 | O14: 1653 | P14: 1617 | Q14: 1543 | R14: 1659 | S14: 1654 | T14: 1791 | U14: 1780 | V14: 1780 | W14: 1638 | X14: 1593 | Y14: 0.031884058 | Z14: 0.11809045 | AA14: inferred | AB14: Harbor
A15: Effective Gross Revenue (T12) | B15: 13325549 | D15: B4 | E15: 2 | F15: 2 | G15: 86 | H15: 77 | I15: 9 | J15: 1187 | K15: 1690 | L15: 1589 | M15: 32 | N15: 45 | O15: 1699 | P15: 1716 | Q15: 1868 | R15: 1589 | S15: 1618 | T15: 1706 | U15: 1630 | V15: 1630 | W15: 1514 | X15: 1475 | Y15: 0.013573723 | Z15: 0.10132853 | AA15: inferred | AB15: Maya
A16: Operating Expenses (T12) | B16: 4420512.9 | D16: B4.2 | E16: 2 | F16: 2 | G16: 15 | H16: 12 | I16: 3 | J16: 1184 | K16: 1833 | L16: 1731 | M16: 5 | N16: 7 | O16: 1729 | P16: 1588 | Q16: 1608 | R16: 1745 | S16: 1850 | T16: 1855 | U16: 1766 | V16: 1766 | W16: 1709 | X16: 1672 | Y16: 0.012034384 | Z16: 0.10375 | AA16: inferred | AB16: Reef
A17: Net Operating Income (T12) | B17: 8905036.4 | D17: B4R | E17: 2 | F17: 2 | G17: 16 | H17: 15 | I17: 1 | J17: 1187 | K17: 1821 | L17: 1635 | M17: 9 | N17: 6 | O17: 1545 | P17: 1523 | Q17: 1530 | R17: 1552 | S17: 1543 | T17: 1578 | U17: 1618 | V17: 1618 | W17: 1535 | X17: 1535 | Y17: -0.063638993 | Z17: 0.017924528 | AA17: inferred | AB17: Maya
A18: Operating Margin (T12) | B18: 0.66826787 | D18: C1 | E18: 3 | F18: 2 | G18: 41 | H18: 37 | I18: 4 | J18: 1258 | K18: 1896 | L18: 1794 | M18: 14 | N18: 23 | O18: 1765 | P18: 1699 | Q18: 1770 | R18: 1944 | S18: 1707 | T18: 1706 | U18: 1828 | V18: 1828 | W18: 1750 | X18: 1750 | Y18: -0.0039224232 | Z18: 0.073004695 | AA18: inferred | AB18: Talise
D19: C1R | E19: 3 | F19: 2 | G19: 18 | H19: 16 | I19: 2 | J19: 1258 | K19: 2023 | L19: 2013 | M19: 9 | N19: 7 | O19: 1943 | P19: 1978 | Q19: 1792 | R19: 1862 | S19: 2140 | T19: 1943 | U19: 2129 | V19: 2129 | W19: 1958 | X19: 1941 | Y19: 0.14972323 | Z19: 0.23689179 | AA19: inferred | AB19: Talise
D20: C2 | E20: 3 | F20: 2 | G20: 20 | H20: 18 | I20: 2 | J20: 1364 | K20: 2130 | L20: 1995 | M20: 8 | N20: 10 | O20: 1983 | P20: 1999 | Q20: 1777 | R20: 2041 | S20: 2049 | T20: 2049 | U20: 2057 | V20: 2057 | W20: 2012 | X20: 1961 | Y20: 0.078940467 | Z20: 0.16543909 | AA20: inferred | AB20: Marin
D21: TOTAL / AVG | G21: 715 | H21: 643 | I21: 72 | J21: 947 | K21: 1457 | L21: 1445 | M21: 318 | N21: 325 | O21: 1375 | U21: 1391 | V21: 1391 | W21: 1370 | X21: 1343 | Y21: -0.040394429 | Z21: 0.041621377
D22: New-lease = lease start ≤ move-in (renewals excluded). HD T90/T365 = executed (off-market) asking/effective; HD90 YoY compares the trailing 90 days to the same window a year ago.
A24: ⚑ UNDERWRITING FLAGS
A25: • Jan 2023–Dec 2023 sourced from a summary-level statement; sub-line detail (concessions, loss-to-lease, RUBS, etc.) is not itemized for those months and reads as 0 in those codes.
A26: • 'trash/doortodoor' ($90/mo, RUBS-style recovery) -- confirm whether it nets against the trash expense or books as Other Income (RT).
A27: • Seasonality: executed asking rents peak in Jul and trough in Dec (~10% spread across the HelloData history).
A28: • HelloData asking-rent YoY (same calendar month): -5.8% average across 25 month-pair(s).
A29: • Loss-to-Lease moved from $-72,859 (Jan 2023) to $89,986 (Dec 2025) -- a $162,846 swing; rents are catching up to market.
A30: • Annualized EGR: T3 $12,656,543 vs T12 $13,325,549 (-5.0%) -- recent run-rate is below the trailing year.
A31: • Annualized NOI: T3 $8,469,822 vs T12 $8,905,036 (-4.9%).
A32: • Year-over-year EGR (same calendar month): Jan 2024 -0%, Feb 2024 +2%, Mar 2024 +1%, Apr 2024 +0%, May 2024 +1%, Jun 2024 +2%, Jul 2024 +3%, Aug 2024 +1%, Sep 2024 +3%, Oct 2024 +4%, Nov 2024 +2%, Dec 2024 +5%, Jan 2025 -3%, Feb 2025 -2%, Mar 2025 +1%, Apr 2025 +2%, May 2025 +2%, Jun 2025 +0%, Jul 2025 +1%, Aug 2025 -0%, Sep 2025 -5%, Oct 2025 -7%, Nov 2025 -8%, Dec 2025 -10% (avg -0.2%). On a lease-up this reflects occupancy ramp more than rent growth — see the Lease Trend tab for per-unit market-rent movement.
A34: HOW TO USE → paste into the TMG acquisition model
A35: 1. Review 'T12 Categorized' col A (amber). Every GL line appears once with all months flowing across; edit a code via the dropdown to re-map. Category (col B) and OS Summary roll up automatically. Overlapping months are sourced from the freshest statement so nothing double-counts.
A36: 2. 'OS Summary' is the standardized chart of accounts (live SUMIFS, most recent 12 months). Copy A1:Q77 → model 'OS Summary Dump' A1 (Paste Special → Values).
... A40: 6. The unit mix (with new-lease + HD T90/T365/YoY market-rent indicators) is on this Dashboard; check 'Lease Trend' (seasonality / market-rent trajectory) and 'Reconciliation' (contract-rent ↔ AGPR tie-out) before underwriting. Paste targets only — do NOT populate the model itself from here.

Sheet T12 Categorized
A1: Code | B1: Category | C1: Line Item (raw GL) | D1: 44927 | E1: 44958 | F1: 44986 | G1: 45017 | H1: 45047 | I1: 45078 | J1: 45108 | K1: 45139 | L1: 45170 | M1: 45200 | N1: 45231 | O1: 45261 | P1: 45292 | Q1: 45323 | R1: 45352 | S1: 45383 | T1: 45413 | U1: 45444 | V1: 45474 | W1: 45505 | X1: 45536 | Y1: 45566 | Z1: 45597 | AA1: 45627 | AB1: 45658 | AC1: 45689 | AD1: 45717 | AE1: 45748 | AF1: 45778 | AG1: 45809 | AH1: 45839 | AI1: 45870 | AJ1: 45901 | AK1: 45931 | AL1: 45962 | AM1: 45992 | AN1: T12 Total
C2: Stitched from: Bella T12 2023 (Jan 2023–Dec 2023) · Bella T12 2024 (Jan 2024–Dec 2024) · Bella T12 2025 (Jan 2025–Dec 2025). Each month is sourced from the freshest statement covering it; blank cells = that line not itemized in the statement owning that month.
C3: INCOME
A4: Rentinc | B4: =IFERROR(VLOOKUP($A4,Codes!$A:$B,2,FALSE()),"") | C4: Market Rent | D4: 1202135 | E4: 1202135 | F4: 1203860 | G4: 1203860 | H4: 1203860 | I4: 1203860 | J4: 1203860 | K4: 1203860 | L4: 1203860 | M4: 1203860 | N4: 1203860 | O4: 1203860 | P4: 1203860 | Q4: 1203860 | R4: 1203860 | S4: 1203860 | T4: 1203860 | U4: 1203860 | V4: 1203860 | W4: 1203860 | X4: 1203860 | Y4: 1203860 | Z4: 1203860 | AA4: 1203860 | AB4: 1203860 | AC4: 1203536.6 | AD4: 1203860 | AE4: 1203860 | AF4: 1203860 | AG4: 1210063 | AH4: 1210063 | AI4: 1219673 | AJ4: 1219673 | AK4: 1068808 | AL4: 993633 | AM4: 949933 | AN4: =SUM(AB4:AM4)
A5: ltl | B5: =IFERROR(VLOOKUP($A5,Codes!$A:$B,2,FALSE()),"") | C5: Gain / Loss To Lease | D5: -72859.49 | E5: -6765.71 | F5: -28066.12 | G5: -45208.78 | H5: -165653.61 | I5: -86227.22 | J5: -81434.07 | K5: -81536.9 | L5: -82079.39 | M5: -83739.02 | N5: -86749.96 | O5: -91437.55 | P5: -96136.61 | Q5: -92712.74 | R5: -97016.32 | S5: -102520.66 | T5: -98174.24 | U5: -96977.6 | V5: -97226.32 | W5: -100400.38 | X5: -102203.79 | Y5: -101963.66 | Z5: -103217.57 | AA5: -93282.6 | AB5: -111910.07 | AC5: -119197.7 | AD5: -119723.97 | AE5: -122944.21 | AF5: -121684.6 | AG5: -129818.96 | AH5: -132527.69 | AI5: -144836.41 | AJ5: -146457.7 | AK5: -5111.86 | AL5: 60499.02 | AM5: 89986.12 | AN5: =SUM(AB5:AM5)
A6: conc | B6: =IFERROR(VLOOKUP($A6,Codes!$A:$B,2,FALSE()),"") | C6: Res. Rent Concessions | D6: -1319.01 | E6: -230.3 | F6: -227.26 | G6: 672.41 | H6: -497.9 | I6: -575.57 | J6: -2759.4 | K6: -12085.85 | L6: -1593.22 | M6: -6592.23 | N6: -12726.4 | O6: -18420.97 | P6: -8071.87 | Q6: -12416.89 | R6: -5909.94 | S6: 26398.7 | T6: 0 | U6: 0 | V6: 0 | W6: 0 | X6: 0 | Y6: 0 | Z6: 0 | AA6: 0 | AN6: =SUM(AB6:AM6)
A7: conc | B7: =IFERROR(VLOOKUP($A7,Codes!$A:$B,2,FALSE()),"") | C7: One-Time Concessions | D7: 0 | E7: 0 | F7: 713.72 | G7: 0 | H7: 0 | I7: 0 | J7: 0 | K7: 0 | L7: 0 | M7: 0 | N7: 0 | O7: 0 | P7: 250 | Q7: 0 | R7: 0 | S7: -26004.53 | T7: -1968.24 | U7: -7674.86 | V7: -15018.95 | W7: -1968.92 | X7: -3434.02 | Y7: 3279.09 | Z7: -3967.32 | AA7: -1492.6 | AB7: 1023.94 | AC7: 2266 | AD7: 1680 | AE7: -325 | AF7: -589 | AG7: 883 | AH7: -1241 | AI7: -30 | AJ7: -2389.33 | AK7: -8809.13 | AL7: -8744.08 | AM7: -5805.06 | AN7: =SUM(AB7:AM7)
A8: vac | B8: =IFERROR(VLOOKUP($A8,Codes!$A:$B,2,FALSE()),"") | C8: Vacancy Loss | D8: -80881.93 | E8: -134644.72 | F8: -180138.43 | G8: -212318.84 | H8: -124265.31 | I8: -95331.65 | J8: -121495.95 | K8: -120108.53 | L8: -96474.17 | M8: -108619.53 | N8: -111081.02 | O8: -79539.11 | P8: -80089.2 | Q8: -78903.74 | R8: -72275.01 | S8: -70834.23 | T8: -84106.2 | U8: -79407.72 | V8: -65222.16 | W8: -66261.6 | X8: -65786.32 | Y8: -83792.81 | Z8: -78065.14 | AA8: -68751.46 | AB8: -81128.24 | AC8: -74193.14 | AD8: -73650.77 | AE8: -68216.19 | AF8: -75005.87 | AG8: -71531.57 | AH8: -65223.88 | AI8: -76573.08 | AJ8: -89133.35 | AK8: -81831.06 | AL8: -103704.55 | AM8: -88770.86 | AN8: =SUM(AB8:AM8)
A9: nr | B9: =IFERROR(VLOOKUP($A9,Codes!$A:$B,2,FALSE()),"") | C9: Employee Units | D9: -2103.6 | E9: -2791.55 | F9: -4816.34 | G9: -4903.07 | H9: -4920.22 | I9: -4557.59 | J9: -4529 | K9: -5197.95 | L9: -5338.8 | M9: -5009.54 | N9: -5078.8 | O9: -5078.8 | P9: -6942.86 | Q9: -6132.01 | R9: -6558.4 | S9: -6558.4 | T9: -6558.4 | U9: -6558.4 | V9: -6558.4 | W9: -5164.02 | X9: -5269.55 | Y9: -6738.61 | Z9: -5783.07 | AA9: -6561.8 | AB9: 333.8 | AC9: -3853.41 | AD9: -4400.4 | AE9: -2944.8 | AF9: -2944.8 | AG9: -16635.21 | AH9: -7081.2 | AI9: -7927.2 | AJ9: -7648.18 | AK9: -7572.2 | AL9: -7788.24 | AM9: -7255.35 | AN9: =SUM(AB9:AM9)
A10: nr | B10: =IFERROR(VLOOKUP($A10,Codes!$A:$B,2,FALSE()),"") | C10: Model & Storage Units | D10: -1475 | E10: -1475 | F10: -1475 | G10: -1475 | H10: -1475 | I10: -1475 | J10: -1475 | K10: -1475 | L10: -1475 | M10: -1475 | N10: -1475 | O10: -1475 | P10: -1475 | Q10: -1475 | R10: -1475 | S10: -1475 | T10: -1475 | U10: -1475 | V10: -1475 | W10: -1475 | X10: 0 | Y10: 0 | Z10: 0 | AA10: 0 | AN10: =SUM(AB10:AM10)
A11: Rentinc | B11: =IFERROR(VLOOKUP($A11,Codes!$A:$B,2,FALSE()),"") | C11: Guest Suite | D11: 0 | E11: 0 | F11: -1955 | G11: -1955 | H11: -1955 | I11: -1955 | J11: -1875 | K11: -1875 | L11: -1875 | M11: -1875 | N11: -1875 | O11: -1875 | P11: -1875 | Q11: -1875 | R11: -1875 | S11: -1875 | T11: -1875 | U11: -1875 | V11: -1875 | W11: -1875 | X11: -1875 | Y11: -1875 | Z11: -1875 | AA11: -1875 | AB11: -1875 | AC11: -1875 | AD11: -1875 | AE11: -1875 | AF11: -1875 | AG11: -1890 | AH11: -1890 | AI11: -1900 | AJ11: -1900 | AK11: -1957 | AL11: 0 | AM11: 0 | AN11: =SUM(AB11:AM11)
A12: cl | B12: =IFERROR(VLOOKUP($A12,Codes!$A:$B,2,FALSE()),"") | C12: Bad Debt - Rent | D12: -24054.96 | E12: -38106.75 | F12: 33120.5 | G12: 75977.5 | H12: 87475.26 | I12: -4649.34 | J12: -6723.15 | K12: 9881.98 | L12: -9233.24 | M12: -4365.53 | N12: 11429.75 | O12: -14437.34 | P12: -8447.76 | Q12: -9974.99 | R12: -13746.79 | S12: -11077.77 | T12: 159.07 | U12: -6102.47 | V12: -6908.49 | W12: -8388.75 | X12: -10543.92 | Y12: -15175.14 | Z12: -1356.96 | AA12: -12193.47 | AB12: -13671 | AC12: -15889.14 | AD12: -2668.89 | AE12: -2694.81 | AF12: -3900.28 | AG12: -10686.8 | AH12: -5557.97 | AI12: -13284.54 | AJ12: -8921.83 | AK12: -15370.77 | AL12: -18576.97 | AM12: -10406.52 | AN12: =SUM(AB12:AM12)
A13: cl | B13: =IFERROR(VLOOKUP($A13,Codes!$A:$B,2,FALSE()),"") | C13: Bad Debt Recovery - Rent | D13: 120 | E13: 137.51 | F13: -19044.76 | G13: -54.01 | H13: 2143.14 | I13: -1380.87 | J13: -486.37 | K13: 263.59 | L13: 274.27 | M13: 130.93 | N13: 1410.62 | O13: 4264.53 | P13: -3853.07 | Q13: 154.15 | R13: 85.84 | S13: 152.23 | T13: 80.76 | U13: 6381 | V13: -5871.88 | W13: 184.94 | X13: 746.14 | Y13: 157.56 | Z13: 205.13 | AA13: 310.38 | AB13: 0 | AC13: 0 | AD13: 0 | AE13: -1000 | AF13: -140.36 | AG13: 0.01 | AH13: 0 | AI13: 0 | AJ13: 1603.65 | AK13: 0 | AL13: 890.22 | AM13: 0 | AN13: =SUM(AB13:AM13)
A14: OI | B14: =IFERROR(VLOOKUP($A14,Codes!$A:$B,2,FALSE()),"") | C14: Administrative Fees | D14: 7608.2 | E14: 3325 | F14: 6505 | G14: 5945.39 | H14: 6600 | I14: 2489.99 | J14: 3475 | K14: 4625 | L14: 2250 | M14: 3721.36 | N14: 8425 | O14: 6050 | P14: 8499.89 | Q14: 12200 | R14: 4500 | S14: 1850 | T14: 1000 | U14: 3875 | V14: 1425 | W14: 2700 | X14: 150 | Y14: 2800 | Z14: 550 | AA14: 3814.2 | AB14: 3200 | AC14: 2775 | AD14: 5750 | AE14: 5850 | AF14: 6975 | AG14: 6625 | AH14: 4525 | AI14: 7351 | AJ14: 3900 | AK14: 3250 | AL14: 1775 | AM14: 4825 | AN14: =SUM(AB14:AM14)
A15: OI | B15: =IFERROR(VLOOKUP($A15,Codes!$A:$B,2,FALSE()),"") | C15: Application Fees | D15: 3705.12 | E15: 2622.66 | F15: 4200 | G15: 2310 | H15: 3410 | I15: 1530 | J15: 2970 | K15: 3537.34 | L15: 1595 | M15: 2255 | N15: 3025 | O15: 2860 | P15: 3465 | Q15: 4125 | R15: 2200 | S15: 2145 | T15: 1320 | U15: 4565 | V15: 2640 | W15: 2305 | X15: 2805 | Y15: 2701.38 | Z15: 4070 | AA15: 4180 | AB15: 3628.62 | AC15: 1375 | AD15: 4015 | AE15: 3685 | AF15: 3520 | AG15: 2748.62 | AH15: 3465 | AI15: 2750 | AJ15: 1925 | AK15: 1760 | AL15: 2795 | AM15: 4080 | AN15: =SUM(AB15:AM15)
A16: cable | B16: =IFERROR(VLOOKUP($A16,Codes!$A:$B,2,FALSE()),"") | C16: Cable TV Commissions | D16: 0 | E16: 16902.07 | F16: 0 | G16: 0 | H16: 17242.21 | I16: 0 | J16: 0 | K16: 16924.83 | L16: 0 | M16: 0 | N16: 16112.48 | O16: 0 | P16: 0 | Q16: 16338.6 | R16: 0 | S16: 0 | T16: 0 | U16: 0 | V16: 0 | W16: 0 | X16: 0 | Y16: 32776.73 | Z16: 16811.3 | AA16: 0 | AB16: 0 | AC16: 32437.08 | AD16: 0 | AE16: 0 | AF16: -8183.37 | AG16: 7784.9 | AH16: 0 | AI16: 15244.46 | AJ16: 0 | AK16: 0 | AL16: 13971.32 | AM16: 0 | AN16: =SUM(AB16:AM16)
A17: OI | B17: =IFERROR(VLOOKUP($A17,Codes!$A:$B,2,FALSE()),"") | C17: Club Room Rental Fees | D17: 0 | E17: 0 | F17: 0 | G17: 0 | H17: 0 | I17: 0 | J17: 0 | K17: 0 | L17: 0 | M17: 0 | N17: 300 | O17: 0 | P17: -100 | Q17: 0 | R17: 0 | S17: 0 | T17: 100 | U17: 400 | V17: -100 | W17: 0 | X17: 0 | Y17: 0 | Z17: 0 | AA17: 0 | AB17: 0 | AC17: 0 | AD17: 150 | AE17: 400 | AF17: 200 | AG17: 350 | AH17: 50 | AI17: 175 | AJ17: 500 | AK17: 200 | AL17: 250 | AM17: 0 | AN17: =SUM(AB17:AM17)
A18: OI | B18: =IFERROR(VLOOKUP($A18,Codes!$A:$B,2,FALSE()),"") | C18: Damages | D18: 2656.13 | E18: 6402.3 | F18: 15395.63 | G18: 5202.16 | H18: 3438.92 | I18: 4228.08 | J18: 3335.25 | K18: 6299.72 | L18: 2150.23 | M18: 4979.48 | N18: 4278.51 | O18: 1715.35 | P18: 8915.82 | Q18: 3895.72 | R18: 6687.06 | S18: 3911.98 | T18: 6903.33 | U18: 1316.19 | V18: 3704.53 | W18: 2540.16 | X18: 3468.08 | Y18: 2790.87 | Z18: 4376.22 | AA18: 4017.94 | AB18: 4488.89 | AC18: 2377.48 | AD18: 7307.5 | AE18: 8587.54 | AF18: 5723.99 | AG18: 5525.06 | AH18: 5526.19 | AI18: 5169.02 | AJ18: 4593.44 | AK18: 5256.41 | AL18: 2539.26 | AM18: 4669.66 | AN18: =SUM(AB18:AM18)
A19: park | B19: =IFERROR(VLOOKUP($A19,Codes!$A:$B,2,FALSE()),"") | C19: Garage Income | D19: 6650.25 | E19: 7247.74 | F19: 6602.92 | G19: 7030.08 | H19: 6912.52 | I19: 7071.33 | J19: 6646.91 | K19: 6375.57 | L19: 6529.01 | M19: 6484.16 | N19: 6739.17 | O19: 6883.23 | P19: 7217.27 | Q19: 7419.66 | R19: 7505.32 | S19: 7212.86 | T19: 7270.48 | U19: 7734.98 | V19: 7577.25 | W19: 7743.55 | X19: 7549.81 | Y19: 7506.13 | Z19: 7454.4 | AA19: 7611.95 | AB19: 7643.72 | AC19: 7472.01 | AD19: 7246.15 | AE19: 7055.12 | AF19: 7234.2 | AG19: 7166.13 | AH19: 7056.78 | AI19: 6979 | AJ19: 7445.2 | AK19: 6786.31 | AL19: 6411.47 | AM19: 6128.82 | AN19: =SUM(AB19:AM19)
A20: OI | B20: =IFERROR(VLOOKUP($A20,Codes!$A:$B,2,FALSE()),"") | C20: Insufficient Notice Fees | D20: 0 | E20: 0 | F20: 1536.25 | G20: 0 | H20: 0 | I20: 0 | J20: 799.15 | K20: 5112.88 | L20: 1864.23 | M20: 5314.51 | N20: 646.1 | O20: 277.56 | P20: 7745.47 | Q20: 8493.98 | R20: 2463.35 | S20: 4303.93 | T20: 1266.89 | U20: 858.04 | V20: 4595.27 | W20: 3527.97 | X20: 4872.42 | Y20: 2844.99 | Z20: 3215.15 | AA20: 3064.67 | AB20: 6510.85 | AC20: 6278.01 | AD20: 4157.39 | AE20: 6430.7 | AF20: 9404.49 | AG20: 8752.65 | AH20: 2522.45 | AI20: 3071.61 | AJ20: 4745.03 | AK20: 4249.6 | AL20: 6754.05 | AM20: 2285.83 | AN20: =SUM(AB20:AM20)
A21: OI | B21: =IFERROR(VLOOKUP($A21,Codes!$A:$B,2,FALSE()),"") | C21: Interest Income | P21: 0 | Q21: 0 | R21: 72.39 | S21: 50.58 | T21: 27.61 | U21: 0 | V21: 1514.39 | W21: 1370.51 | X21: 3044.09 | Y21: 3035.7 | Z21: 754.63 | AA21: 1365.89 | AB21: 1473.43 | AC21: 1562.08 | AD21: 1814.32 | AE21: 2047.99 | AF21: 800.22 | AG21: 888.04 | AH21: 1544.03 | AI21: 882.89 | AJ21: 1156.09 | AK21: 1420.31 | AL21: 506.43 | AM21: 603.88 | AN21: =SUM(AB21:AM21)
A22: OI | B22: =IFERROR(VLOOKUP($A22,Codes!$A:$B,2,FALSE()),"") | C22: Late Charge Fees | D22: 18149.66 | E22: 13280.24 | F22: 7850.16 | G22: 11855 | H22: 12873.76 | I22: 14147.52 | J22: 15209.02 | K22: 14717.58 | L22: 19229.76 | M22: 16035 | N22: 15040 | O22: 15986 | P22: 16350 | Q22: 16810 | R22: 12795 | S22: 13825.41 | T22: 13564.64 | U22: 17721.64 | V22: 12895 | W22: 15750 | X22: 17393.15 | Y22: 10201.22 | Z22: 17541.93 | AA22: 17489.81 | AB22: 12210 | AC22: 13380.84 | AD22: 15245 | AE22: 11615.72 | AF22: 14420.88 | AG22: 15769.99 | AH22: 12322.55 | AI22: 14727.77 | AJ22: 16195 | AK22: 15120 | AL22: 15185.95 | AM22: 11582.38 | AN22: =SUM(AB22:AM22)
A23: OI | B23: =IFERROR(VLOOKUP($A23,Codes!$A:$B,2,FALSE()),"") | C23: Lease Cancellation Fee | D23: 12702.36 | E23: 5992 | F23: 6084.33 | G23: 0 | H23: 4167.99 | I23: 3404.65 | J23: 10524.15 | K23: 5740.25 | L23: 2822.54 | M23: 1245.87 | N23: 7525.65 | O23: 2806 | P23: 18049.56 | Q23: 14855.24 | R23: 7297.98 | S23: 3532.07 | T23: 10265.51 | U23: 9089.95 | V23: 21343.51 | W23: 2110.29 | X23: 17060.67 | Y23: 8898.7 | Z23: 5856.33 | AA23: 7151.58 | AB23: 5306.5 | AC23: 7090.94 | AD23: 6408.01 | AE23: 11138.04 | AF23: 23243.23 | AG23: 4860.59 | AH23: 14324.01 | AI23: 8839.3 | AJ23: 11698.5 | AK23: 652.1 | AL23: 1669.69 | AM23: 4915.2 | AN23: =SUM(AB23:AM23)
A24: OI | B24: =IFERROR(VLOOKUP($A24,Codes!$A:$B,2,FALSE()),"") | C24: Legal Fees | D24: 3310.74 | E24: 3236.26 | F24: 3908 | G24: 3252 | H24: 4025.12 | I24: 4843 | J24: 5839.11 | K24: 6939.87 | L24: 7021.9 | M24: 5785.5 | N24: 5943 | O24: 4749.46 | P24: 8035.96 | Q24: 7677.84 | R24: 3866 | S24: 5102.04 | T24: 6667.72 | U24: 5493 | V24: 5721.82 | W24: 8195.45 | X24: 8376.88 | Y24: 4166 | Z24: 11187.73 | AA24: 9120.2 | AB24: 4847.21 | AC24: 10247 | AD24: 8343.31 | AE24: 6890.42 | AF24: 10641.88 | AG24: 8273.8 | AH24: 6320.71 | AI24: 9453.87 | AJ24: 6435.01 | AK24: 9299 | AL24: 10309.19 | AM24: 6425.66 | AN24: =SUM(AB24:AM24)
A25: OI | B25: =IFERROR(VLOOKUP($A25,Codes!$A:$B,2,FALSE()),"") | C25: Locks / Key Income | D25: 100 | E25: 150 | F25: 50 | G25: 0 | H25: 50 | I25: 170 | J25: 50 | K25: 55 | L25: 180 | M25: 550 | N25: 75 | O25: 150 | P25: 585 | Q25: 290 | R25: 465 | S25: 305 | T25: 570 | U25: 210 | V25: 110 | W25: 10 | X25: 110 | Y25: 150 | Z25: 160 | AA25: 50 | AB25: 150 | AC25: 180 | AD25: 5 | AE25: 245 | AF25: 210 | AG25: 270 | AH25: 540 | AI25: 180 | AJ25: 297.73 | AK25: 320 | AL25: 60 | AM25: 250 | AN25: =SUM(AB25:AM25)
A26: Rentinc | B26: =IFERROR(VLOOKUP($A26,Codes!$A:$B,2,FALSE()),"") | C26: Month-to-Month Premiums | D26: 2.76 | E26: 4.1 | F26: 290.77 | G26: 4.86 | H26: 3.44 | I26: 8.77 | J26: 8.13 | K26: 12.18 | L26: 11.49 | M26: 220.75 | N26: 13.56 | O26: 13.28 | P26: 18.87 | Q26: 16.56 | R26: 12.29 | S26: 8.05 | T26: 10.1 | U26: 11.4 | V26: 11.55 | W26: 6.1 | X26: 5.77 | Y26: 816.39 | Z26: 5.59 | AA26: 76.67 | AB26: 0.38 | AC26: 6.25 | AD26: 10.68 | AE26: 10.02 | AF26: 17.35 | AG26: 18.44 | AH26: 21.22 | AI26: 20.64 | AJ26: 9.64 | AK26: 11.18 | AL26: 11.8 | AM26: 4.31 | AN26: =SUM(AB26:AM26)
A27: OI | B27: =IFERROR(VLOOKUP($A27,Codes!$A:$B,2,FALSE()),"") | C27: NSF Fees | D27: 650 | E27: 300 | F27: 400 | G27: 550 | H27: 700 | I27: 250 | J27: 850 | K27: 500 | L27: 600 | M27: 850 | N27: -50 | O27: 450 | P27: 400 | Q27: 550 | R27: 400 | S27: 850 | T27: 500 | U27: 950 | V27: 450 | W27: 950 | X27: 675 | Y27: 500 | Z27: 900 | AA27: 750 | AB27: 600 | AC27: 650 | AD27: 650 | AE27: 300 | AF27: 500 | AG27: 1100 | AH27: 300 | AI27: 700 | AJ27: 1050 | AK27: 750 | AL27: 550 | AM27: 500 | AN27: =SUM(AB27:AM27)
A28: OI | B28: =IFERROR(VLOOKUP($A28,Codes!$A:$B,2,FALSE()),"") | C28: Package Concierge/Locker Income | D28: 600.2 | E28: 625.07 | F28: 639.2 | G28: 656.4 | H28: 650.39 | I28: 656 | J28: 644.85 | K28: 653.04 | L28: 656.78 | M28: 652.54 | N28: 657.17 | O28: 664.04 | P28: 667.82 | Q28: 665.83 | R28: 664.38 | S28: 665.52 | T28: 665.7 | U28: 662.69 | V28: 670.19 | W28: 671.39 | X28: 672.62 | Y28: 665.12 | Z28: 667.26 | AA28: 666.1 | AB28: 656.78 | AC28: 660.54 | AD28: 668.25 | AE28: 667.31 | AF28: 667.36 | AG28: 667.52 | AH28: 668.24 | AI28: 660.05 | AJ28: 655.35 | AK28: 651.04 | AL28: 934.79 | AM28: 715.62 | AN28: =SUM(AB28:AM28)
A29: park | B29: =IFERROR(VLOOKUP($A29,Codes!$A:$B,2,FALSE()),"") | C29: Parking / Carport Income | D29: 1731.28 | E29: 1796.25 | F29: 1751.84 | G29: 7067.58 | H29: 1899.03 | I29: 1879.5 | J29: -1319.79 | K29: 1807.42 | L29: 1810 | M29: 1904.68 | N29: 5379.71 | O29: 1871.29 | P29: 3903.78 | Q29: 1859.83 | R29: 1639.35 | S29: 1742.17 | T29: 3247.66 | U29: 1796.67 | V29: 1946.56 | W29: -189.28 | X29: 3628.97 | Y29: 1578.49 | Z29: 3818 | AA29: 1598.54 | AB29: 3035.66 | AC29: 1311.96 | AD29: 1408.44 | AE29: 3198.33 | AF29: 1278.07 | AG29: 1312.83 | AH29: 1212.26 | AI29: 2736.59 | AJ29: 1195.49 | AK29: 896.77 | AL29: 10825.85 | AM29: 594.19 | AN29: =SUM(AB29:AM29)
A30: OI | B30: =IFERROR(VLOOKUP($A30,Codes!$A:$B,2,FALSE()),"") | C30: Pet Fees - Non-Refundable | D30: 1800 | E30: 1900 | F30: 2200 | G30: -100 | H30: 1200 | I30: 917 | J30: 1200 | K30: 1230.97 | L30: 1200 | M30: 300 | N30: 0 | O30: 900 | P30: 1200 | Q30: 1800 | R30: 2100 | S30: 600 | T30: 300 | U30: 1211 | V30: 1500 | W30: 900 | X30: 600 | Y30: 2219.35 | Z30: 600 | AA30: 550 | AB30: 880 | AC30: 38.39 | AD30: 1800 | AE30: 1230 | AF30: 930 | AG30: 3944.67 | AH30: -70 | AI30: 1530 | AJ30: 630 | AK30: 1831 | AL30: 375 | AM30: 1594.52 | AN30: =SUM(AB30:AM30)
A31: OI | B31: =IFERROR(VLOOKUP($A31,Codes!$A:$B,2,FALSE()),"") | C31: Pet Rent | D31: 3995.99 | E31: 3938.12 | F31: 3922.53 | G31: 3693.79 | H31: 3496.39 | I31: 3537.77 | J31: 3540.33 | K31: 3426.03 | L31: 3387.33 | M31: 3203.44 | N31: 2954.37 | O31: 2975.8 | P31: 2861.36 | Q31: 3002.26 | R31: 3104.85 | S31: 3110.57 | T31: 3024.14 | U31: 3025.35 | V31: 3149.11 | W31: 2780.64 | X31: 2972.82 | Y31: 2939.72 | Z31: 2966.85 | AA31: 3060.74 | AB31: 3036.48 | AC31: 2822.39 | AD31: 2665.2 | AE31: 2800.78 | AF31: 2717.48 | AG31: 2581 | AH31: 2796.8 | AI31: 2570.2 | AJ31: 2691.42 | AK31: 2704.67 | AL31: 2702.91 | AM31: 3073.11 | AN31: =SUM(AB31:AM31)
A32: OI | B32: =IFERROR(VLOOKUP($A32,Codes!$A:$B,2,FALSE()),"") | C32: Renter's Insurance Fees | D32: 83.76 | E32: -2071.23 | F32: -5027.84 | G32: 6244.57 | H32: 119.1 | I32: 394.24 | J32: -299.32 | K32: 244.2 | L32: -153.49 | M32: 3766.34 | N32: -992.22 | O32: -6476.8 | P32: -1648.29 | Q32: -1809.07 | R32: -2536.45 | S32: 5128.25 | T32: -3682.22 | U32: -128.61 | V32: 213.68 | W32: 743.22 | X32: 405.06 | Y32: 5173.2 | Z32: 354.66 | AA32: 463.5 | AB32: 582.48 | AC32: 497.88 | AD32: 766.02 | AE32: 915 | AF32: 629.39 | AG32: 518.46 | AH32: 509.1 | AI32: 432.66 | AJ32: 289.86 | AK32: 471.3 | AL32: 140.28 | AM32: 57.06 | AN32: =SUM(AB32:AM32)
A33: OI | B33: =IFERROR(VLOOKUP($A33,Codes!$A:$B,2,FALSE()),"") | C33: Transfer Fee | D33: 500 | E33: 2750 | F33: 750 | G33: 250 | H33: 1250 | I33: 1750 | J33: 750 | K33: 2250 | L33: 1250 | M33: 2000 | N33: 250 | O33: 2500 | P33: 1250 | Q33: 1250 | R33: 1500 | S33: 1000 | T33: 1000 | U33: -250 | V33: 500 | W33: 750 | X33: 1750 | Y33: 1750 | Z33: 2250 | AA33: 1500 | AB33: 1500 | AC33: 1500 | AD33: 1500 | AE33: 500 | AF33: 500 | AG33: 4750 | AH33: 2000 | AI33: 1000 | AJ33: 750 | AK33: 750 | AL33: 2250 | AM33: 1500 | AN33: =SUM(AB33:AM33)
... A41: OI | B41: =IFERROR(VLOOKUP($A41,Codes!$A:$B,2,FALSE()),"") | C41: Miscellaneous Income | D41: 24 | E41: 30 | F41: 88 | G41: 24 | H41: 27 | I41: 29 | J41: 6522.16 | K41: 56 | L41: 26 | M41: 0 | N41: 17 | O41: 23 | P41: 0 | Q41: 81 | R41: 40 | S41: 20 | T41: 19 | U41: 0 | V41: 36 | W41: 3841.56 | X41: -1959.62 | Y41: 17 | Z41: 16 | AA41: 15 | AB41: 15 | AC41: 14 | AD41: 16 | AE41: 19 | AF41: 16 | AG41: 11 | AH41: 12 | AI41: 16.7 | AJ41: 17 | AK41: 0 | AL41: 18 | AM41: 0 | AN41: =SUM(AB41:AM41)
A42: OI | B42: =IFERROR(VLOOKUP($A42,Codes!$A:$B,2,FALSE()),"") | C42: Smart Home Income | AB42: 0 | AC42: 0 | AD42: 0 | AE42: 0 | AF42: 0 | AG42: 0 | AH42: 0 | AI42: 0 | AJ42: 0 | AK42: 0 | AL42: 0 | AM42: 198.73 | AN42: =SUM(AB42:AM42)
A43: OI | B43: =IFERROR(VLOOKUP($A43,Codes!$A:$B,2,FALSE()),"") | C43: Guest Suite Income | AB43: 0 | AC43: 0 | AD43: 0 | AE43: 0 | AF43: 448 | AG43: 0 | AH43: 150 | AI43: 844 | AJ43: 0 | AK43: 0 | AL43: 245 | AM43: 0 | AN43: =SUM(AB43:AM43)
A44: RF | B44: =IFERROR(VLOOKUP($A44,Codes!$A:$B,2,FALSE()),"") | C44: Electric Rebill | AB44: 0 | AC44: 0 | AD44: 0 | AE44: 0 | AF44: 0 | AG44: 0 | AH44: 0 | AI44: 0 | AJ44: 0 | AK44: 0 | AL44: 0 | AM44: 571.29 | AN44: =SUM(AB44:AM44)
A45: Rentinc | B45: =IFERROR(VLOOKUP($A45,Codes!$A:$B,2,FALSE()),"") | C45: Prior Period Rent Adjustment | D45: 0 | E45: 0 | F45: -104.26 | G45: 0 | H45: 0 | I45: 0 | J45: 0 | K45: 0 | L45: 0 | M45: 0 | N45: 0 | O45: 0 | AN45: =SUM(AB45:AM45)
A46: nr | B46: =IFERROR(VLOOKUP($A46,Codes!$A:$B,2,FALSE()),"") | C46: Down Unit Loss | D46: 0 | E46: -1955 | F46: 0 | G46: -1125 | H46: -1875 | I46: -1875 | J46: 0 | K46: 0 | L46: 0 | M46: 0 | N46: 0 | O46: 0 | AN46: =SUM(AB46:AM46)
A47: conc | B47: =IFERROR(VLOOKUP($A47,Codes!$A:$B,2,FALSE()),"") | C47: Recurring Concessions | D47: 0 | E47: 0 | F47: -1 | G47: 0 | H47: 0 | I47: 0 | J47: 0 | K47: 0 | L47: 0 | M47: 0 | N47: 0 | O47: 0 | AN47: =SUM(AB47:AM47)
...

Sheet OS Summary
B1: Bella Mirage
B2: Operating Statement — Standardized (live rollup)
B3: Adjusted Amounts ($ totals) — most recent 12 months · model paste target (A1:Q77)
C4: Annual | D4: Annual | E4: Annual | F4: Monthly | G4: Monthly | H4: Monthly | I4: Monthly | J4: Monthly | K4: Monthly | L4: Monthly | M4: Monthly | N4: Monthly | O4: Monthly | P4: Monthly | Q4: Monthly
F5: 45658 | G5: 45689 | H5: 45717 | I5: 45748 | J5: 45778 | K5: 45809 | L5: 45839 | M5: 45870 | N5: 45901 | O5: 45931 | P5: 45962 | Q5: 45992
A6: Code | B6: Effective Gross Revenue
A7: Rentinc | B7: Rental Income | F7: =SUMIFS('T12 Categorized'!AB:AB,'T12 Categorized'!$A:$A,$A7) | G7: =SUMIFS('T12 Categorized'!AC:AC,'T12 Categorized'!$A:$A,$A7) | H7: =SUMIFS('T12 Categorized'!AD:AD,'T12 Categorized'!$A:$A,$A7) | I7: =SUMIFS('T12 Categorized'!AE:AE,'T12 Categorized'!$A:$A,$A7) | J7: =SUMIFS('T12 Categorized'!AF:AF,'T12 Categorized'!$A:$A,$A7) | K7: =SUMIFS('T12 Categorized'!AG:AG,'T12 Categorized'!$A:$A,$A7) | L7: =SUMIFS('T12 Categorized'!AH:AH,'T12 Categorized'!$A:$A,$A7) | M7: =SUMIFS('T12 Categorized'!AI:AI,'T12 Categorized'!$A:$A,$A7) | N7: =SUMIFS('T12 Categorized'!AJ:AJ,'T12 Categorized'!$A:$A,$A7) | O7: =SUMIFS('T12 Categorized'!AK:AK,'T12 Categorized'!$A:$A,$A7) | P7: =SUMIFS('T12 Categorized'!AL:AL,'T12 Categorized'!$A:$A,$A7) | Q7: =SUMIFS('T12 Categorized'!AM:AM,'T12 Categorized'!$A:$A,$A7)
A8: OI | B8: Other Income | F8: =SUMIFS('T12 Categorized'!AB:AB,'T12 Categorized'!$A:$A,$A8) | G8: =SUMIFS('T12 Categorized'!AC:AC,'T12 Categorized'!$A:$A,$A8) | H8: =SUMIFS('T12 Categorized'!AD:AD,'T12 Categorized'!$A:$A,$A8) | I8: =SUMIFS('T12 Categorized'!AE:AE,'T12 Categorized'!$A:$A,$A8) | J8: =SUMIFS('T12 Categorized'!AF:AF,'T12 Categorized'!$A:$A,$A8) | K8: =SUMIFS('T12 Categorized'!AG:AG,'T12 Categorized'!$A:$A,$A8) | L8: =SUMIFS('T12 Categorized'!AH:AH,'T12 Categorized'!$A:$A,$A8) | M8: =SUMIFS('T12 Categorized'!AI:AI,'T12 Categorized'!$A:$A,$A8) | N8: =SUMIFS('T12 Categorized'!AJ:AJ,'T12 Categorized'!$A:$A,$A8) | O8: =SUMIFS('T12 Categorized'!AK:AK,'T12 Categorized'!$A:$A,$A8) | P8: =SUMIFS('T12 Categorized'!AL:AL,'T12 Categorized'!$A:$A,$A8) | Q8: =SUMIFS('T12 Categorized'!AM:AM,'T12 Categorized'!$A:$A,$A8)
A9: RWS | B9: Rubs Water / Sewage | F9: =SUMIFS('T12 Categorized'!AB:AB,'T12 Categorized'!$A:$A,$A9) | G9: =SUMIFS('T12 Categorized'!AC:AC,'T12 Categorized'!$A:$A,$A9) | H9: =SUMIFS('T12 Categorized'!AD:AD,'T12 Categorized'!$A:$A,$A9) | I9: =SUMIFS('T12 Categorized'!AE:AE,'T12 Categorized'!$A:$A,$A9) | J9: =SUMIFS('T12 Categorized'!AF:AF,'T12 Categorized'!$A:$A,$A9) | K9: =SUMIFS('T12 Categorized'!AG:AG,'T12 Categorized'!$A:$A,$A9) | L9: =SUMIFS('T12 Categorized'!AH:AH,'T12 Categorized'!$A:$A,$A9) | M9: =SUMIFS('T12 Categorized'!AI:AI,'T12 Categorized'!$A:$A,$A9) | N9: =SUMIFS('T12 Categorized'!AJ:AJ,'T12 Categorized'!$A:$A,$A9) | O9: =SUMIFS('T12 Categorized'!AK:AK,'T12 Categorized'!$A:$A,$A9) | P9: =SUMIFS('T12 Categorized'!AL:AL,'T12 Categorized'!$A:$A,$A9) | Q9: =SUMIFS('T12 Categorized'!AM:AM,'T12 Categorized'!$A:$A,$A9)
A10: RT | B10: Rubs Trash | F10: =SUMIFS('T12 Categorized'!AB:AB,'T12 Categorized'!$A:$A,$A10) | G10: =SUMIFS('T12 Categorized'!AC:AC,'T12 Categorized'!$A:$A,$A10) | H10: =SUMIFS('T12 Categorized'!AD:AD,'T12 Categorized'!$A:$A,$A10) | I10: =SUMIFS('T12 Categorized'!AE:AE,'T12 Categorized'!$A:$A,$A10) | J10: =SUMIFS('T12 Categorized'!AF:AF,'T12 Categorized'!$A:$A,$A10) | K10: =SUMIFS('T12 Categorized'!AG:AG,'T12 Categorized'!$A:$A,$A10) | L10: =SUMIFS('T12 Categorized'!AH:AH,'T12 Categorized'!$A:$A,$A10) | M10: =SUMIFS('T12 Categorized'!AI:AI,'T12 Categorized'!$A:$A,$A10) | N10: =SUMIFS('T12 Categorized'!AJ:AJ,'T12 Categorized'!$A:$A,$A10) | O10: =SUMIFS('T12 Categorized'!AK:AK,'T12 Categorized'!$A:$A,$A10) | P10: =SUMIFS('T12 Categorized'!AL:AL,'T12 Categorized'!$A:$A,$A10) | Q10: =SUMIFS('T12 Categorized'!AM:AM,'T12 Categorized'!$A:$A,$A10)
A11: RF | B11: Rubs Fees | F11: =SUMIFS('T12 Categorized'!AB:AB,'T12 Categorized'!$A:$A,$A11) | G11: =SUMIFS('T12 Categorized'!AC:AC,'T12 Categorized'!$A:$A,$A11) | H11: =SUMIFS('T12 Categorized'!AD:AD,'T12 Categorized'!$A:$A,$A11) | I11: =SUMIFS('T12 Categorized'!AE:AE,'T12 Categorized'!$A:$A,$A11) | J11: =SUMIFS('T12 Categorized'!AF:AF,'T12 Categorized'!$A:$A,$A11) | K11: =SUMIFS('T12 Categorized'!AG:AG,'T12 Categorized'!$A:$A,$A11) | L11: =SUMIFS('T12 Categorized'!AH:AH,'T12 Categorized'!$A:$A,$A11) | M11: =SUMIFS('T12 Categorized'!AI:AI,'T12 Categorized'!$A:$A,$A11) | N11: =SUMIFS('T12 Categorized'!AJ:AJ,'T12 Categorized'!$A:$A,$A11) | O11: =SUMIFS('T12 Categorized'!AK:AK,'T12 Categorized'!$A:$A,$A11) | P11: =SUMIFS('T12 Categorized'!AL:AL,'T12 Categorized'!$A:$A,$A11) | Q11: =SUMIFS('T12 Categorized'!AM:AM,'T12 Categorized'!$A:$A,$A11)
A12: park | B12: Garage / Parking | F12: =SUMIFS('T12 Categorized'!AB:AB,'T12 Categorized'!$A:$A,$A12) | G12: =SUMIFS('T12 Categorized'!AC:AC,'T12 Categorized'!$A:$A,$A12) | H12: =SUMIFS('T12 Categorized'!AD:AD,'T12 Categorized'!$A:$A,$A12) | I12: =SUMIFS('T12 Categorized'!AE:AE,'T12 Categorized'!$A:$A,$A12) | J12: =SUMIFS('T12 Categorized'!AF:AF,'T12 Categorized'!$A:$A,$A12) | K12: =SUMIFS('T12 Categorized'!AG:AG,'T12 Categorized'!$A:$A,$A12) | L12: =SUMIFS('T12 Categorized'!AH:AH,'T12 Categorized'!$A:$A,$A12) | M12: =SUMIFS('T12 Categorized'!AI:AI,'T12 Categorized'!$A:$A,$A12) | N12: =SUMIFS('T12 Categorized'!AJ:AJ,'T12 Categorized'!$A:$A,$A12) | O12: =SUMIFS('T12 Categorized'!AK:AK,'T12 Categorized'!$A:$A,$A12) | P12: =SUMIFS('T12 Categorized'!AL:AL,'T12 Categorized'!$A:$A,$A12) | Q12: =SUMIFS('T12 Categorized'!AM:AM,'T12 Categorized'!$A:$A,$A12)
A13: CI | B13: Corporate Income | F13: =SUMIFS('T12 Categorized'!AB:AB,'T12 Categorized'!$A:$A,$A13) | G13: =SUMIFS('T12 Categorized'!AC:AC,'T12 Categorized'!$A:$A,$A13) | H13: =SUMIFS('T12 Categorized'!AD:AD,'T12 Categorized'!$A:$A,$A13) | I13: =SUMIFS('T12 Categorized'!AE:AE,'T12 Categorized'!$A:$A,$A13) | J13: =SUMIFS('T12 Categorized'!AF:AF,'T12 Categorized'!$A:$A,$A13) | K13: =SUMIFS('T12 Categorized'!AG:AG,'T12 Categorized'!$A:$A,$A13) | L13: =SUMIFS('T12 Categorized'!AH:AH,'T12 Categorized'!$A:$A,$A13) | M13: =SUMIFS('T12 Categorized'!AI:AI,'T12 Categorized'!$A:$A,$A13) | N13: =SUMIFS('T12 Categorized'!AJ:AJ,'T12 Categorized'!$A:$A,$A13) | O13: =SUMIFS('T12 Categorized'!AK:AK,'T12 Categorized'!$A:$A,$A13) | P13: =SUMIFS('T12 Categorized'!AL:AL,'T12 Categorized'!$A:$A,$A13) | Q13: =SUMIFS('T12 Categorized'!AM:AM,'T12 Categorized'!$A:$A,$A13)
A14: cable | B14: Cable Income | F14: =SUMIFS('T12 Categorized'!AB:AB,'T12 Categorized'!$A:$A,$A14) | G14: =SUMIFS('T12 Categorized'!AC:AC,'T12 Categorized'!$A:$A,$A14) | H14: =SUMIFS('T12 Categorized'!AD:AD,'T12 Categorized'!$A:$A,$A14) | I14: =SUMIFS('T12 Categorized'!AE:AE,'T12 Categorized'!$A:$A,$A14) | J14: =SUMIFS('T12 Categorized'!AF:AF,'T12 Categorized'!$A:$A,$A14) | K14: =SUMIFS('T12 Categorized'!AG:AG,'T12 Categorized'!$A:$A,$A14) | L14: =SUMIFS('T12 Categorized'!AH:AH,'T12 Categorized'!$A:$A,$A14) | M14: =SUMIFS('T12 Categorized'!AI:AI,'T12 Categorized'!$A:$A,$A14) | N14: =SUMIFS('T12 Categorized'!AJ:AJ,'T12 Categorized'!$A:$A,$A14) | O14: =SUMIFS('T12 Categorized'!AK:AK,'T12 Categorized'!$A:$A,$A14) | P14: =SUMIFS('T12 Categorized'!AL:AL,'T12 Categorized'!$A:$A,$A14) | Q14: =SUMIFS('T12 Categorized'!AM:AM,'T12 Categorized'!$A:$A,$A14)
A15: ltl | B15: (Loss to Lease) / Gain to Lease | F15: =SUMIFS('T12 Categorized'!AB:AB,'T12 Categorized'!$A:$A,$A15) | G15: =SUMIFS('T12 Categorized'!AC:AC,'T12 Categorized'!$A:$A,$A15) | H15: =SUMIFS('T12 Categorized'!AD:AD,'T12 Categorized'!$A:$A,$A15) | I15: =SUMIFS('T12 Categorized'!AE:AE,'T12 Categorized'!$A:$A,$A15) | J15: =SUMIFS('T12 Categorized'!AF:AF,'T12 Categorized'!$A:$A,$A15) | K15: =SUMIFS('T12 Categorized'!AG:AG,'T12 Categorized'!$A:$A,$A15) | L15: =SUMIFS('T12 Categorized'!AH:AH,'T12 Categorized'!$A:$A,$A15) | M15: =SUMIFS('T12 Categorized'!AI:AI,'T12 Categorized'!$A:$A,$A15) | N15: =SUMIFS('T12 Categorized'!AJ:AJ,'T12 Categorized'!$A:$A,$A15) | O15: =SUMIFS('T12 Categorized'!AK:AK,'T12 Categorized'!$A:$A,$A15) | P15: =SUMIFS('T12 Categorized'!AL:AL,'T12 Categorized'!$A:$A,$A15) | Q15: =SUMIFS('T12 Categorized'!AM:AM,'T12 Categorized'!$A:$A,$A15)
A16: vac | B16: Vacancy | F16: =SUMIFS('T12 Categorized'!AB:AB,'T12 Categorized'!$A:$A,$A16) | G16: =SUMIFS('T12 Categorized'!AC:AC,'T12 Categorized'!$A:$A,$A16) | H16: =SUMIFS('T12 Categorized'!AD:AD,'T12 Categorized'!$A:$A,$A16) | I16: =SUMIFS('T12 Categorized'!AE:AE,'T12 Categorized'!$A:$A,$A16) | J16: =SUMIFS('T12 Categorized'!AF:AF,'T12 Categorized'!$A:$A,$A16) | K16: =SUMIFS('T12 Categorized'!AG:AG,'T12 Categorized'!$A:$A,$A16) | L16: =SUMIFS('T12 Categorized'!AH:AH,'T12 Categorized'!$A:$A,$A16) | M16: =SUMIFS('T12 Categorized'!AI:AI,'T12 Categorized'!$A:$A,$A16) | N16: =SUMIFS('T12 Categorized'!AJ:AJ,'T12 Categorized'!$A:$A,$A16) | O16: =SUMIFS('T12 Categorized'!AK:AK,'T12 Categorized'!$A:$A,$A16) | P16: =SUMIFS('T12 Categorized'!AL:AL,'T12 Categorized'!$A:$A,$A16) | Q16: =SUMIFS('T12 Categorized'!AM:AM,'T12 Categorized'!$A:$A,$A16)
A17: cl | B17: Collection Loss / Bad Debt | F17: =SUMIFS('T12 Categorized'!AB:AB,'T12 Categorized'!$A:$A,$A17) | G17: =SUMIFS('T12 Categorized'!AC:AC,'T12 Categorized'!$A:$A,$A17) | H17: =SUMIFS('T12 Categorized'!AD:AD,'T12 Categorized'!$A:$A,$A17) | I17: =SUMIFS('T12 Categorized'!AE:AE,'T12 Categorized'!$A:$A,$A17) | J17: =SUMIFS('T12 Categorized'!AF:AF,'T12 Categorized'!$A:$A,$A17) | K17: =SUMIFS('T12 Categorized'!AG:AG,'T12 Categorized'!$A:$A,$A17) | L17: =SUMIFS('T12 Categorized'!AH:AH,'T12 Categorized'!$A:$A,$A17) | M17: =SUMIFS('T12 Categorized'!AI:AI,'T12 Categorized'!$A:$A,$A17) | N17: =SUMIFS('T12 Categorized'!AJ:AJ,'T12 Categorized'!$A:$A,$A17) | O17: =SUMIFS('T12 Categorized'!AK:AK,'T12 Categorized'!$A:$A,$A17) | P17: =SUMIFS('T12 Categorized'!AL:AL,'T12 Categorized'!$A:$A,$A17) | Q17: =SUMIFS('T12 Categorized'!AM:AM,'T12 Categorized'!$A:$A,$A17)
A18: nr | B18: Non-Revenue Units | F18: =SUMIFS('T12 Categorized'!AB:AB,'T12 Categorized'!$A:$A,$A18) | G18: =SUMIFS('T12 Categorized'!AC:AC,'T12 Categorized'!$A:$A,$A18) | H18: =SUMIFS('T12 Categorized'!AD:AD,'T12 Categorized'!$A:$A,$A18) | I18: =SUMIFS('T12 Categorized'!AE:AE,'T12 Categorized'!$A:$A,$A18) | J18: =SUMIFS('T12 Categorized'!AF:AF,'T12 Categorized'!$A:$A,$A18) | K18: =SUMIFS('T12 Categorized'!AG:AG,'T12 Categorized'!$A:$A,$A18) | L18: =SUMIFS('T12 Categorized'!AH:AH,'T12 Categorized'!$A:$A,$A18) | M18: =SUMIFS('T12 Categorized'!AI:AI,'T12 Categorized'!$A:$A,$A18) | N18: =SUMIFS('T12 Categorized'!AJ:AJ,'T12 Categorized'!$A:$A,$A18) | O18: =SUMIFS('T12 Categorized'!AK:AK,'T12 Categorized'!$A:$A,$A18) | P18: =SUMIFS('T12 Categorized'!AL:AL,'T12 Categorized'!$A:$A,$A18) | Q18: =SUMIFS('T12 Categorized'!AM:AM,'T12 Categorized'!$A:$A,$A18)
A19: conc | B19: Concessions | F19: =SUMIFS('T12 Categorized'!AB:AB,'T12 Categorized'!$A:$A,$A19) | G19: =SUMIFS('T12 Categorized'!AC:AC,'T12 Categorized'!$A:$A,$A19) | H19: =SUMIFS('T12 Categorized'!AD:AD,'T12 Categorized'!$A:$A,$A19) | I19: =SUMIFS('T12 Categorized'!AE:AE,'T12 Categorized'!$A:$A,$A19) | J19: =SUMIFS('T12 Categorized'!AF:AF,'T12 Categorized'!$A:$A,$A19) | K19: =SUMIFS('T12 Categorized'!AG:AG,'T12 Categorized'!$A:$A,$A19) | L19: =SUMIFS('T12 Categorized'!AH:AH,'T12 Categorized'!$A:$A,$A19) | M19: =SUMIFS('T12 Categorized'!AI:AI,'T12 Categorized'!$A:$A,$A19) | N19: =SUMIFS('T12 Categorized'!AJ:AJ,'T12 Categorized'!$A:$A,$A19) | O19: =SUMIFS('T12 Categorized'!AK:AK,'T12 Categorized'!$A:$A,$A19) | P19: =SUMIFS('T12 Categorized'!AL:AL,'T12 Categorized'!$A:$A,$A19) | Q19: =SUMIFS('T12 Categorized'!AM:AM,'T12 Categorized'!$A:$A,$A19)
B20: Effective Gross Revenue | F20: =SUM(F7:F19) | G20: =SUM(G7:G19) | H20: =SUM(H7:H19) | I20: =SUM(I7:I19) | J20: =SUM(J7:J19) | K20: =SUM(K7:K19) | L20: =SUM(L7:L19) | M20: =SUM(M7:M19) | ... Q20: =SUM(Q7:Q19)
B22: Operating Expenses
A23: Pay | B23: Payroll | F23: =SUMIFS('T12 Categorized'!AB:AB,'T12 Categorized'!$A:$A,$A23) | G23: =SUMIFS('T12 Categorized'!AC:AC,'T12 Categorized'!$A:$A,$A23) | H23: =SUMIFS('T12 Categorized'!AD:AD,'T12 Categorized'!$A:$A,$A23) | I23: =SUMIFS('T12 Categorized'!AE:AE,'T12 Categorized'!$A:$A,$A23) | J23: =SUMIFS('T12 Categorized'!AF:AF,'T12 Categorized'!$A:$A,$A23) | K23: =SUMIFS('T12 Categorized'!AG:AG,'T12 Categorized'!$A:$A,$A23) | L23: =SUMIFS('T12 Categorized'!AH:AH,'T12 Categorized'!$A:$A,$A23) | M23: =SUMIFS('T12 Categorized'!AI:AI,'T12 Categorized'!$A:$A,$A23) | N23: =SUMIFS('T12 Categorized'!AJ:AJ,'T12 Categorized'!$A:$A,$A23) | O23: =SUMIFS('T12 Categorized'!AK:AK,'T12 Categorized'!$A:$A,$A23) | P23: =SUMIFS('T12 Categorized'!AL:AL,'T12 Categorized'!$A:$A,$A23) | Q23: =SUMIFS('T12 Categorized'!AM:AM,'T12 Categorized'!$A:$A,$A23)
A24: PB | B24: Payroll Burden | F24: =SUMIFS('T12 Categorized'!AB:AB,'T12 Categorized'!$A:$A,$A24) | G24: =SUMIFS('T12 Categorized'!AC:AC,'T12 Categorized'!$A:$A,$A24) | H24: =SUMIFS('T12 Categorized'!AD:AD,'T12 Categorized'!$A:$A,$A24) | I24: =SUMIFS('T12 Categorized'!AE:AE,'T12 Categorized'!$A:$A,$A24) | J24: =SUMIFS('T12 Categorized'!AF:AF,'T12 Categorized'!$A:$A,$A24) | K24: =SUMIFS('T12 Categorized'!AG:AG,'T12 Categorized'!$A:$A,$A24) | L24: =SUMIFS('T12 Categorized'!AH:AH,'T12 Categorized'!$A:$A,$A24) | M24: =SUMIFS('T12 Categorized'!AI:AI,'T12 Categorized'!$A:$A,$A24) | N24: =SUMIFS('T12 Categorized'!AJ:AJ,'T12 Categorized'!$A:$A,$A24) | O24: =SUMIFS('T12 Categorized'!AK:AK,'T12 Categorized'!$A:$A,$A24) | P24: =SUMIFS('T12 Categorized'!AL:AL,'T12 Categorized'!$A:$A,$A24) | Q24: =SUMIFS('T12 Categorized'!AM:AM,'T12 Categorized'!$A:$A,$A24)
A25: PBo | B25: Payroll Bonuses | F25: =SUMIFS('T12 Categorized'!AB:AB,'T12 Categorized'!$A:$A,$A25) | G25: =SUMIFS('T12 Categorized'!AC:AC,'T12 Categorized'!$A:$A,$A25) | H25: =SUMIFS('T12 Categorized'!AD:AD,'T12 Categorized'!$A:$A,$A25) | I25: =SUMIFS('T12 Categorized'!AE:AE,'T12 Categorized'!$A:$A,$A25) | J25: =SUMIFS('T12 Categorized'!AF:AF,'T12 Categorized'!$A:$A,$A25) | K25: =SUMIFS('T12 Categorized'!AG:AG,'T12 Categorized'!$A:$A,$A25) | L25: =SUMIFS('T12 Categorized'!AH:AH,'T12 Categorized'!$A:$A,$A25) | M25: =SUMIFS('T12 Categorized'!AI:AI,'T12 Categorized'!$A:$A,$A25) | N25: =SUMIFS('T12 Categorized'!AJ:AJ,'T12 Categorized'!$A:$A,$A25) | O25: =SUMIFS('T12 Categorized'!AK:AK,'T12 Categorized'!$A:$A,$A25) | P25: =SUMIFS('T12 Categorized'!AL:AL,'T12 Categorized'!$A:$A,$A25) | Q25: =SUMIFS('T12 Categorized'!AM:AM,'T12 Categorized'!$A:$A,$A25)
A26: adv | B26: Marketing / Advertising | F26: =SUMIFS('T12 Categorized'!AB:AB,'T12 Categorized'!$A:$A,$A26) | G26: =SUMIFS('T12 Categorized'!AC:AC,'T12 Categorized'!$A:$A,$A26) | H26: =SUMIFS('T12 Categorized'!AD:AD,'T12 Categorized'!$A:$A,$A26) | I26: =SUMIFS('T12 Categorized'!AE:AE,'T12 Categorized'!$A:$A,$A26) | J26: =SUMIFS('T12 Categorized'!AF:AF,'T12 Categorized'!$A:$A,$A26) | K26: =SUMIFS('T12 Categorized'!AG:AG,'T12 Categorized'!$A:$A,$A26) | L26: =SUMIFS('T12 Categorized'!AH:AH,'T12 Categorized'!$A:$A,$A26) | M26: =SUMIFS('T12 Categorized'!AI:AI,'T12 Categorized'!$A:$A,$A26) | N26: =SUMIFS('T12 Categorized'!AJ:AJ,'T12 Categorized'!$A:$A,$A26) | O26: =SUMIFS('T12 Categorized'!AK:AK,'T12 Categorized'!$A:$A,$A26) | P26: =SUMIFS('T12 Categorized'!AL:AL,'T12 Categorized'!$A:$A,$A26) | Q26: =SUMIFS('T12 Categorized'!AM:AM,'T12 Categorized'!$A:$A,$A26)
A27: GA | B27: General & Administrative | F27: =SUMIFS('T12 Categorized'!AB:AB,'T12 Categorized'!$A:$A,$A27) | G27: =SUMIFS('T12 Categorized'!AC:AC,'T12 Categorized'!$A:$A,$A27) | H27: =SUMIFS('T12 Categorized'!AD:AD,'T12 Categorized'!$A:$A,$A27) | I27: =SUMIFS('T12 Categorized'!AE:AE,'T12 Categorized'!$A:$A,$A27) | J27: =SUMIFS('T12 Categorized'!AF:AF,'T12 Categorized'!$A:$A,$A27) | K27: =SUMIFS('T12 Categorized'!AG:AG,'T12 Categorized'!$A:$A,$A27) | L27: =SUMIFS('T12 Categorized'!AH:AH,'T12 Categorized'!$A:$A,$A27) | M27: =SUMIFS('T12 Categorized'!AI:AI,'T12 Categorized'!$A:$A,$A27) | N27: =SUMIFS('T12 Categorized'!AJ:AJ,'T12 Categorized'!$A:$A,$A27) | O27: =SUMIFS('T12 Categorized'!AK:AK,'T12 Categorized'!$A:$A,$A27) | P27: =SUMIFS('T12 Categorized'!AL:AL,'T12 Categorized'!$A:$A,$A27) | Q27: =SUMIFS('T12 Categorized'!AM:AM,'T12 Categorized'!$A:$A,$A27)
A28: turn | B28: Turnover | F28: =SUMIFS('T12 Categorized'!AB:AB,'T12 Categorized'!$A:$A,$A28) | G28: =SUMIFS('T12 Categorized'!AC:AC,'T12 Categorized'!$A:$A,$A28) | H28: =SUMIFS('T12 Categorized'!AD:AD,'T12 Categorized'!$A:$A,$A28) | I28: =SUMIFS('T12 Categorized'!AE:AE,'T12 Categorized'!$A:$A,$A28) | J28: =SUMIFS('T12 Categorized'!AF:AF,'T12 Categorized'!$A:$A,$A28) | K28: =SUMIFS('T12 Categorized'!AG:AG,'T12 Categorized'!$A:$A,$A28) | L28: =SUMIFS('T12 Categorized'!AH:AH,'T12 Categorized'!$A:$A,$A28) | M28: =SUMIFS('T12 Categorized'!AI:AI,'T12 Categorized'!$A:$A,$A28) | N28: =SUMIFS('T12 Categorized'!AJ:AJ,'T12 Categorized'!$A:$A,$A28) | O28: =SUMIFS('T12 Categorized'!AK:AK,'T12 Categorized'!$A:$A,$A28) | P28: =SUMIFS('T12 Categorized'!AL:AL,'T12 Categorized'!$A:$A,$A28) | Q28: =SUMIFS('T12 Categorized'!AM:AM,'T12 Categorized'!$A:$A,$A28)
A29: inter/exte | B29: R&M Interior / Exterior | F29: =SUMIFS('T12 Categorized'!AB:AB,'T12 Categorized'!$A:$A,$A29) | G29: =SUMIFS('T12 Categorized'!AC:AC,'T12 Categorized'!$A:$A,$A29) | H29: =SUMIFS('T12 Categorized'!AD:AD,'T12 Categorized'!$A:$A,$A29) | I29: =SUMIFS('T12 Categorized'!AE:AE,'T12 Categorized'!$A:$A,$A29) | J29: =SUMIFS('T12 Categorized'!AF:AF,'T12 Categorized'!$A:$A,$A29) | K29: =SUMIFS('T12 Categorized'!AG:AG,'T12 Categorized'!$A:$A,$A29) | L29: =SUMIFS('T12 Categorized'!AH:AH,'T12 Categorized'!$A:$A,$A29) | M29: =SUMIFS('T12 Categorized'!AI:AI,'T12 Categorized'!$A:$A,$A29) | N29: =SUMIFS('T12 Categorized'!AJ:AJ,'T12 Categorized'!$A:$A,$A29) | O29: =SUMIFS('T12 Categorized'!AK:AK,'T12 Categorized'!$A:$A,$A29) | P29: =SUMIFS('T12 Categorized'!AL:AL,'T12 Categorized'!$A:$A,$A29) | Q29: =SUMIFS('T12 Categorized'!AM:AM,'T12 Categorized'!$A:$A,$A29)
A30: cont | B30: Contract | F30: =SUMIFS('T12 Categorized'!AB:AB,'T12 Categorized'!$A:$A,$A30) | G30: =SUMIFS('T12 Categorized'!AC:AC,'T12 Categorized'!$A:$A,$A30) | H30: =SUMIFS('T12 Categorized'!AD:AD,'T12 Categorized'!$A:$A,$A30) | I30: =SUMIFS('T12 Categorized'!AE:AE,'T12 Categorized'!$A:$A,$A30) | J30: =SUMIFS('T12 Categorized'!AF:AF,'T12 Categorized'!$A:$A,$A30) | K30: =SUMIFS('T12 Categorized'!AG:AG,'T12 Categorized'!$A:$A,$A30) | L30: =SUMIFS('T12 Categorized'!AH:AH,'T12 Categorized'!$A:$A,$A30) | M30: =SUMIFS('T12 Categorized'!AI:AI,'T12 Categorized'!$A:$A,$A30) | N30: =SUMIFS('T12 Categorized'!AJ:AJ,'T12 Categorized'!$A:$A,$A30) | O30: =SUMIFS('T12 Categorized'!AK:AK,'T12 Categorized'!$A:$A,$A30) | P30: =SUMIFS('T12 Categorized'!AL:AL,'T12 Categorized'!$A:$A,$A30) | Q30: =SUMIFS('T12 Categorized'!AM:AM,'T12 Categorized'!$A:$A,$A30)
A31: Safe | B31: Life Safety / Elevators | F31: =SUMIFS('T12 Categorized'!AB:AB,'T12 Categorized'!$A:$A,$A31) | G31: =SUMIFS('T12 Categorized'!AC:AC,'T12 Categorized'!$A:$A,$A31) | H31: =SUMIFS('T12 Categorized'!AD:AD,'T12 Categorized'!$A:$A,$A31) | I31: =SUMIFS('T12 Categorized'!AE:AE,'T12 Categorized'!$A:$A,$A31) | J31: =SUMIFS('T12 Categorized'!AF:AF,'T12 Categorized'!$A:$A,$A31) | K31: =SUMIFS('T12 Categorized'!AG:AG,'T12 Categorized'!$A:$A,$A31) | L31: =SUMIFS('T12 Categorized'!AH:AH,'T12 Categorized'!$A:$A,$A31) | M31: =SUMIFS('T12 Categorized'!AI:AI,'T12 Categorized'!$A:$A,$A31) | N31: =SUMIFS('T12 Categorized'!AJ:AJ,'T12 Categorized'!$A:$A,$A31) | O31: =SUMIFS('T12 Categorized'!AK:AK,'T12 Categorized'!$A:$A,$A31) | P31: =SUMIFS('T12 Categorized'!AL:AL,'T12 Categorized'!$A:$A,$A31) | Q31: =SUMIFS('T12 Categorized'!AM:AM,'T12 Categorized'!$A:$A,$A31)
A32: HAF | B32: Homeowners Association Fees | F32: =SUMIFS('T12 Categorized'!AB:AB,'T12 Categorized'!$A:$A,$A32) | G32: =SUMIFS('T12 Categorized'!AC:AC,'T12 Categorized'!$A:$A,$A32) | H32: =SUMIFS('T12 Categorized'!AD:AD,'T12 Categorized'!$A:$A,$A32) | I32: =SUMIFS('T12 Categorized'!AE:AE,'T12 Categorized'!$A:$A,$A32) | J32: =SUMIFS('T12 Categorized'!AF:AF,'T12 Categorized'!$A:$A,$A32) | K32: =SUMIFS('T12 Categorized'!AG:AG,'T12 Categorized'!$A:$A,$A32) | L32: =SUMIFS('T12 Categorized'!AH:AH,'T12 Categorized'!$A:$A,$A32) | M32: =SUMIFS('T12 Categorized'!AI:AI,'T12 Categorized'!$A:$A,$A32) | N32: =SUMIFS('T12 Categorized'!AJ:AJ,'T12 Categorized'!$A:$A,$A32) | O32: =SUMIFS('T12 Categorized'!AK:AK,'T12 Categorized'!$A:$A,$A32) | P32: =SUMIFS('T12 Categorized'!AL:AL,'T12 Categorized'!$A:$A,$A32) | Q32: =SUMIFS('T12 Categorized'!AM:AM,'T12 Categorized'!$A:$A,$A32)
A33: UT | B33: Utilities Trash | F33: =SUMIFS('T12 Categorized'!AB:AB,'T12 Categorized'!$A:$A,$A33) | G33: =SUMIFS('T12 Categorized'!AC:AC,'T12 Categorized'!$A:$A,$A33) | H33: =SUMIFS('T12 Categorized'!AD:AD,'T12 Categorized'!$A:$A,$A33) | I33: =SUMIFS('T12 Categorized'!AE:AE,'T12 Categorized'!$A:$A,$A33) | J33: =SUMIFS('T12 Categorized'!AF:AF,'T12 Categorized'!$A:$A,$A33) | K33: =SUMIFS('T12 Categorized'!AG:AG,'T12 Categorized'!$A:$A,$A33) | L33: =SUMIFS('T12 Categorized'!AH:AH,'T12 Categorized'!$A:$A,$A33) | M33: =SUMIFS('T12 Categorized'!AI:AI,'T12 Categorized'!$A:$A,$A33) | N33: =SUMIFS('T12 Categorized'!AJ:AJ,'T12 Categorized'!$A:$A,$A33) | O33: =SUMIFS('T12 Categorized'!AK:AK,'T12 Categorized'!$A:$A,$A33) | P33: =SUMIFS('T12 Categorized'!AL:AL,'T12 Categorized'!$A:$A,$A33) | Q33: =SUMIFS('T12 Categorized'!AM:AM,'T12 Categorized'!$A:$A,$A33)
A34: UWS | B34: Utilities Water Sewer | F34: =SUMIFS('T12 Categorized'!AB:AB,'T12 Categorized'!$A:$A,$A34) | G34: =SUMIFS('T12 Categorized'!AC:AC,'T12 Categorized'!$A:$A,$A34) | H34: =SUMIFS('T12 Categorized'!AD:AD,'T12 Categorized'!$A:$A,$A34) | I34: =SUMIFS('T12 Categorized'!AE:AE,'T12 Categorized'!$A:$A,$A34) | J34: =SUMIFS('T12 Categorized'!AF:AF,'T12 Categorized'!$A:$A,$A34) | K34: =SUMIFS('T12 Categorized'!AG:AG,'T12 Categorized'!$A:$A,$A34) | L34: =SUMIFS('T12 Categorized'!AH:AH,'T12 Categorized'!$A:$A,$A34) | M34: =SUMIFS('T12 Categorized'!AI:AI,'T12 Categorized'!$A:$A,$A34) | N34: =SUMIFS('T12 Categorized'!AJ:AJ,'T12 Categorized'!$A:$A,$A34) | O34: =SUMIFS('T12 Categorized'!AK:AK,'T12 Categorized'!$A:$A,$A34) | P34: =SUMIFS('T12 Categorized'!AL:AL,'T12 Categorized'!$A:$A,$A34) | Q34: =SUMIFS('T12 Categorized'!AM:AM,'T12 Categorized'!$A:$A,$A34)
... A41: site | B41: R&M Site | F41: =SUMIFS('T12 Categorized'!AB:AB,'T12 Categorized'!$A:$A,$A41) | G41: =SUMIFS('T12 Categorized'!AC:AC,'T12 Categorized'!$A:$A,$A41) | H41: =SUMIFS('T12 Categorized'!AD:AD,'T12 Categorized'!$A:$A,$A41) | I41: =SUMIFS('T12 Categorized'!AE:AE,'T12 Categorized'!$A:$A,$A41) | J41: =SUMIFS('T12 Categorized'!AF:AF,'T12 Categorized'!$A:$A,$A41) | K41: =SUMIFS('T12 Categorized'!AG:AG,'T12 Categorized'!$A:$A,$A41) | L41: =SUMIFS('T12 Categorized'!AH:AH,'T12 Categorized'!$A:$A,$A41) | M41: =SUMIFS('T12 Categorized'!AI:AI,'T12 Categorized'!$A:$A,$A41) | N41: =SUMIFS('T12 Categorized'!AJ:AJ,'T12 Categorized'!$A:$A,$A41) | O41: =SUMIFS('T12 Categorized'!AK:AK,'T12 Categorized'!$A:$A,$A41) | P41: =SUMIFS('T12 Categorized'!AL:AL,'T12 Categorized'!$A:$A,$A41) | Q41: =SUMIFS('T12 Categorized'!AM:AM,'T12 Categorized'!$A:$A,$A41)
B42: Operating Expenses | F42: =SUM(F23:F41) | G42: =SUM(G23:G41) | H42: =SUM(H23:H41) | I42: =SUM(I23:I41) | J42: =SUM(J23:J41) | K42: =SUM(K23:K41) | L42: =SUM(L23:L41) | M42: =SUM(M23:M41) | ... Q42: =SUM(Q23:Q41)
B44: Net Operating Income | F44: =F20-F42 | G44: =G20-G42 | H44: =H20-H42 | I44: =I20-I42 | J44: =J20-J42 | K44: =K20-K42 | L44: =L20-L42 | M44: =M20-M42 | ... Q44: =Q20-Q42
B46: Non-Operating Revenue
A47: dispro | B47: Disposition Proceeds | F47: =SUMIFS('T12 Categorized'!AB:AB,'T12 Categorized'!$A:$A,$A47) | G47: =SUMIFS('T12 Categorized'!AC:AC,'T12 Categorized'!$A:$A,$A47) | H47: =SUMIFS('T12 Categorized'!AD:AD,'T12 Categorized'!$A:$A,$A47) | I47: =SUMIFS('T12 Categorized'!AE:AE,'T12 Categorized'!$A:$A,$A47) | J47: =SUMIFS('T12 Categorized'!AF:AF,'T12 Categorized'!$A:$A,$A47) | K47: =SUMIFS('T12 Categorized'!AG:AG,'T12 Categorized'!$A:$A,$A47) | L47: =SUMIFS('T12 Categorized'!AH:AH,'T12 Categorized'!$A:$A,$A47) | M47: =SUMIFS('T12 Categorized'!AI:AI,'T12 Categorized'!$A:$A,$A47) | N47: =SUMIFS('T12 Categorized'!AJ:AJ,'T12 Categorized'!$A:$A,$A47) | O47: =SUMIFS('T12 Categorized'!AK:AK,'T12 Categorized'!$A:$A,$A47) | P47: =SUMIFS('T12 Categorized'!AL:AL,'T12 Categorized'!$A:$A,$A47) | Q47: =SUMIFS('T12 Categorized'!AM:AM,'T12 Categorized'!$A:$A,$A47)
B48: Non-Operating Revenue | F48: =SUM(F47:F47) | G48: =SUM(G47:G47) | H48: =SUM(H47:H47) | I48: =SUM(I47:I47) | J48: =SUM(J47:J47) | K48: =SUM(K47:K47) | L48: =SUM(L47:L47) | M48: =SUM(M47:M47) | ... Q48: =SUM(Q47:Q47)
B50: Non-Operating Expenses
...

Sheet Rent Roll (One-Line)
A1: Unit No. | B1: Floor Plan | C1: Net sf | D1: Bed | E1: Bath | F1: Lease Type | G1: Occupancy Status | H1: Market Rent | I1: Contractual Rent | J1: Net Effective Rent | K1: Lease Start Date | L1: Lease Expiration | M1: Move In Date | O1: Scheduled Charges by Code (monthly $)
O2: rent | P2: techfee | Q2: garage | R2: empdisc | S2: conc/renew | T2: petrent | U2: package | V2: carport | W2: conc/other | X2: eviction | Y2: trash/doortodoor | Z2: mtm
A3: 0111 | B3: A2 | C3: 777 | D3: 1 | E3: 1 | F3: Market | G3: Occupied | H3: 1127 | I3: 1185 | J3: 1185 | K3: 09/13/2025 | L3: 09/12/2026 | M3: 09/13/2025 | O3: 1185 | U3: 1
A4: 0112 | B4: A2R | C4: 777 | D4: 1 | E4: 1 | F4: Market | G4: Occupied | H4: 1327 | I4: 1258 | J4: 1258 | K4: 06/09/2025 | L4: 08/08/2026 | M4: 06/09/2025 | O4: 1258 | U4: 1
A5: 0113 | B5: A2 | C5: 777 | D5: 1 | E5: 1 | F5: Market | G5: Occupied | H5: 1187 | I5: 1091 | J5: 1091 | K5: 01/20/2026 | L5: 04/12/2027 | M5: 01/20/2026 | O5: 1091 | P5: 35 | U5: 3
A6: 0114 | B6: A2 | C6: 777 | D6: 1 | E6: 1 | F6: Market | G6: Occupied | H6: 1127 | I6: 1222 | J6: 1222 | K6: 08/30/2025 | L6: 09/29/2026 | M6: 08/30/2025 | O6: 1222 | U6: 1
A7: 0115 | B7: A2R | C7: 777 | D7: 1 | E7: 1 | F7: Market | G7: Occupied | H7: 1327 | I7: 1262 | J7: 1262 | K7: 01/16/2026 | L7: 04/22/2027 | M7: 01/16/2026 | O7: 1262 | P7: 35 | U7: 3
A8: 0116 | B8: A2 | C8: 777 | D8: 1 | E8: 1 | F8: Market | G8: Occupied | H8: 1127 | I8: 1230 | J8: 1230 | K8: 05/15/2026 | L8: 07/14/2027 | M8: 04/15/2025 | O8: 1230 | P8: 35 | S8: -300 | U8: 3
A9: 0117 | B9: A2R | C9: 777 | D9: 1 | E9: 1 | F9: Market | G9: Occupied | H9: 1327 | I9: 1242 | J9: 1242 | K9: 02/06/2026 | L9: 05/06/2027 | M9: 02/06/2026 | O9: 1242 | P9: 35 | U9: 3
A10: 0118 | B10: A2 | C10: 777 | D10: 1 | E10: 1 | F10: Market | G10: Occupied | H10: 1167 | I10: 1352 | J10: 1352 | K10: 08/19/2025 | L10: 11/18/2026 | M10: 01/19/2022 | O10: 1352 | U10: 1
A11: 0121 | B11: A2 | C11: 777 | D11: 1 | E11: 1 | F11: Market | G11: Vacant | H11: 1167 | I11: 0 | J11: 0
A12: 0122 | B12: A2 | C12: 777 | D12: 1 | E12: 1 | F12: Market | G12: Occupied | H12: 1107 | I12: 1260 | J12: 1260 | K12: 01/09/2026 | L12: 01/15/2027 | M12: 09/02/2023 | O12: 1260 | U12: 3
A13: 0123 | B13: A2R | C13: 777 | D13: 1 | E13: 1 | F13: Market | G13: Vacant | H13: 1307 | I13: 0 | J13: 0
A14: 0124 | B14: A2 | C14: 777 | D14: 1 | E14: 1 | F14: Market | G14: Occupied | H14: 1107 | I14: 1130 | J14: 1130 | K14: 05/08/2026 | L14: 08/07/2027 | M14: 02/15/2025 | O14: 1130 | P14: 35 | S14: -300 | U14: 3
A15: 0125 | B15: A2 | C15: 777 | D15: 1 | E15: 1 | F15: Market | G15: Occupied | H15: 1107 | I15: 1346 | J15: 1346 | K15: 08/20/2025 | L15: 08/26/2026 | M15: 05/13/2022 | O15: 1346 | U15: 1
A16: 0126 | B16: A2 | C16: 777 | D16: 1 | E16: 1 | F16: Market | G16: Occupied | H16: 1107 | I16: 1202 | J16: 1202 | K16: 08/23/2025 | L16: 09/22/2026 | M16: 08/23/2025 | O16: 1202 | U16: 1
A17: 0127 | B17: A2R | C17: 777 | D17: 1 | E17: 1 | F17: Market | G17: Occupied | H17: 1307 | I17: 1443 | J17: 1443 | K17: 08/19/2025 | L17: 08/25/2026 | M17: 05/19/2023 | O17: 1443 | U17: 1
A18: 0128 | B18: A2 | C18: 777 | D18: 1 | E18: 1 | F18: Market | G18: Occupied | H18: 1107 | I18: 1243 | J18: 1243 | K18: 12/03/2025 | L18: 03/02/2027 | M18: 12/03/2025 | O18: 1243 | U18: 1
A19: 0132 | B19: A2R | C19: 777 | D19: 1 | E19: 1 | F19: Market | G19: Occupied | H19: 1307 | I19: 1353 | J19: 1353 | K19: 03/27/2025 | L19: 06/26/2026 | M19: 03/27/2025 | O19: 1353 | T19: 30 | U19: 1
A20: 0133 | B20: A2R | C20: 777 | D20: 1 | E20: 1 | F20: Market | G20: Occupied | H20: 1307 | I20: 1435 | J20: 1435 | K20: 04/20/2026 | L20: 07/19/2027 | M20: 10/20/2023 | O20: 1435 | P20: 35 | U20: 3
A21: 0136 | B21: A2R | C21: 777 | D21: 1 | E21: 1 | F21: Market | G21: Occupied | H21: 1307 | I21: 1139 | J21: 1139 | K21: 11/28/2025 | L21: 02/20/2027 | M21: 11/28/2025 | O21: 1139 | U21: 3
A22: 0137 | B22: A2 | C22: 777 | D22: 1 | E22: 1 | F22: Market | G22: Occupied | H22: 1107 | I22: 1186 | J22: 1186 | K22: 06/15/2025 | L22: 08/14/2026 | M22: 06/15/2025 | O22: 1186 | U22: 1
A23: 0211 | B23: B4 | C23: 1187 | D23: 2 | E23: 2 | F23: Market | G23: Occupied | H23: 1691 | I23: 1743 | J23: 1743 | K23: 09/18/2025 | L23: 09/17/2026 | M23: 08/18/2020 | O23: 1743 | T23: 40 | U23: 1
A24: 0212 | B24: B1 | C24: 947 | D24: 2 | E24: 2 | F24: Market | G24: Occupied | H24: 1427 | I24: 1465 | J24: 1465 | K24: 06/23/2025 | L24: 09/22/2026 | M24: 06/23/2025 | O24: 1465 | U24: 1
A25: 0213 | B25: B1 | C25: 947 | D25: 2 | E25: 2 | F25: Market | G25: Occupied | H25: 1427 | I25: 1464 | J25: 1464 | K25: 02/17/2026 | L25: 03/23/2027 | M25: 11/17/2023 | O25: 1464 | U25: 3
A26: 0214 | B26: B4 | C26: 1187 | D26: 2 | E26: 2 | F26: Market | G26: Occupied | H26: 1691 | I26: 1527 | J26: 1527 | K26: 05/05/2025 | L26: 08/04/2026 | M26: 05/05/2025 | O26: 1527 | Q26: 125 | U26: 1
A27: 0215 | B27: B4 | C27: 1187 | D27: 2 | E27: 2 | F27: Market | G27: Occupied | H27: 1691 | I27: 1456 | J27: 1456 | K27: 11/22/2025 | L27: 01/21/2027 | M27: 11/22/2025 | O27: 1456 | U27: 3
A28: 0216 | B28: B1R | C28: 947 | D28: 2 | E28: 2 | F28: Market | G28: Occupied | H28: 1552 | I28: 1738 | J28: 1738 | K28: 05/06/2025 | L28: 06/05/2026 | M28: 02/01/2024 | O28: 1738 | T28: 40 | U28: 1
A29: 0217 | B29: B1R | C29: 947 | D29: 2 | E29: 2 | F29: Market | G29: Occupied | H29: 1552 | I29: 1467 | J29: 1467 | K29: 10/08/2025 | L29: 10/07/2026 | M29: 10/08/2025 | O29: 1467 | U29: 1
A30: 0218 | B30: B4 | C30: 1187 | D30: 2 | E30: 2 | F30: Market | G30: Occupied | H30: 1691 | I30: 1723 | J30: 1723 | K30: 05/02/2025 | L30: 07/26/2026 | M30: 01/27/2024 | O30: 1723 | U30: 1
A31: 0221 | B31: B4 | C31: 1187 | D31: 2 | E31: 2 | F31: Market | G31: Occupied | H31: 1596 | I31: 1396 | J31: 1396 | K31: 07/16/2025 | L31: 10/15/2026 | M31: 07/16/2025 | O31: 1396 | U31: 1
A32: 0222 | B32: B1 | C32: 947 | D32: 2 | E32: 2 | F32: Market | G32: Occupied | H32: 1332 | I32: 1437 | J32: 1437 | K32: 07/09/2025 | L32: 07/08/2026 | M32: 03/09/2023 | O32: 1437 | T32: 30 | U32: 1
A33: 0223 | B33: B1 | C33: 947 | D33: 2 | E33: 2 | F33: Market | G33: Occupied | H33: 1332 | I33: 1410 | J33: 1410 | K33: 11/12/2025 | L33: 11/11/2026 | M33: 06/28/2018 | O33: 1410 | U33: 1
