Workbook
Name CodeList: Codes!$A$5:$A$59

Sheet Dashboard
A1: Aura Beacon Island — Underwriting Intake
A2: Generated June 23, 2026 · RR-T12 Processor intake · Operating period May 2025 – Apr 2026 (12 mo)
A3: Data vintage · Rent roll as-of 05/23/2026 · Latest financial statement thru Apr 2026
A4: SNAPSHOT | D4: UNIT MIX — mix-weighted market-rent indicators
A5: Units | B5: 290 | D5: Floor Plan | E5: Bed | F5: Bath | G5: Units | H5: Occ | I5: Vac | J5: Avg SF | K5: Avg Market Rent (per RR — not a mkt signal) | L5: Avg Contract Rent | M5: New Leases | N5: Renew Leases | O5: Avg New-Lease (last 5) | P5: New #1 | Q5: New #2 | R5: New #3 | S5: New #4 | T5: New #5 | U5: HD T90 Asking | V5: HD T90 Effective | W5: HD T365 Asking | X5: HD T365 Effective | Y5: HD90 YoY Asking | Z5: HD90 YoY Effective | AA5: Bed/Bath Src | AB5: HD Plan (website)
A6: Occupied / Vacant / Non-Rev | B6: 272 / 18 / 0 | D6: A1-abi | E6: 1 | F6: 1 | G6: 14 | H6: 12 | I6: 2 | J6: 690 | K6: 1577 | L6: 1433 | M6: 4 | N6: 8 | O6: 1374 | P6: 1350 | Q6: 1350 | R6: 1299 | S6: 1499 | U6: 1505 | V6: 1336 | W6: 1440 | X6: 1256 | Y6: 0.014150943 | Z6: -0.099561995 | AA6: HelloData | AB6: A1
A7: Occupancy % | B7: 0.93793103 | D7: A2-abi | E7: 1 | F7: 1 | G7: 29 | H7: 26 | I7: 3 | J7: 698 | K7: 1712 | L7: 1503 | M7: 16 | N7: 10 | O7: 1449 | P7: 1660 | Q7: 1399 | R7: 1399 | S7: 1399 | T7: 1387 | U7: 1590 | V7: 1448 | W7: 1510 | X7: 1309 | Y7: -0.053769841 | Z7: -0.0071991772 | AA7: HelloData | AB7: A2
A8: Total Rentable SF | B8: 266411 | D8: A3-abi | E8: 1 | F8: 1 | G8: 46 | H8: 42 | I8: 4 | J8: 719 | K8: 1592 | L8: 1490 | M8: 24 | N8: 18 | O8: 1575 | P8: 1550 | Q8: 1550 | R8: 1595 | S8: 1630 | T8: 1550 | U8: 1549 | V8: 1357 | W8: 1493 | X8: 1284 | Y8: -0.017195431 | Z8: 0.045776819 | AA8: HelloData | AB8: A3
A9: New / Renewal leases | B9: 0 / 0 | D9: A3.8-abi | E9: 1 | F9: 1 | G9: 2 | H9: 2 | I9: 0 | J9: 739 | K9: 1565 | L9: 1460 | M9: 0 | N9: 2 | AA9: HelloData | AB9: A3
A10: — Market Rent Indicators (true signal) — | D10: A4-abi | E10: 1 | F10: 1 | G10: 18 | H10: 18 | I10: 0 | J10: 736 | K10: 1687 | L10: 1522 | M10: 8 | N10: 10 | O10: 1386 | P10: 1384 | Q10: 1304 | R10: 1395 | S10: 1395 | T10: 1450 | W10: 1417 | X10: 1178 | AA10: HelloData | AB10: A4
A11: HelloData asking, T90 (mix-wtd) | B11: 1832 | D11: A5-abi | E11: 1 | F11: 1 | G11: 21 | H11: 21 | I11: 0 | J11: 762 | K11: 1601 | L11: 1567 | M11: 10 | N11: 11 | O11: 1613 | P11: 2272 | Q11: 1565 | R11: 1398 | S11: 1433 | T11: 1398 | U11: 1565 | V11: 1339 | W11: 1466 | X11: 1225 | Y11: -0.039877301 | Z11: -0.027596224 | AA11: HelloData | AB11: A5
A12: HelloData effective, T90 (mix-wtd) | B12: 1623 | D12: A5.3-abi | E12: 1 | F12: 1 | G12: 3 | H12: 3 | I12: 0 | J12: 762 | K12: 1605 | L12: 1500 | M12: 2 | N12: 1 | O12: 1495 | P12: 1385 | Q12: 1605 | U12: 1590 | V12: 1418 | W12: 1517 | X12: 1398 | AA12: HelloData | AB12: A5
A13: New-lease contract, T90 (avg) | B13: 1823 | D13: A6-abi | E13: 1 | F13: 1 | G13: 26 | H13: 24 | I13: 2 | J13: 803 | K13: 1755 | L13: 1709 | M13: 12 | N13: 12 | O13: 1608 | P13: 1600 | Q13: 1599 | R13: 1510 | S13: 1510 | T13: 1820 | U13: 1717 | V13: 1469 | W13: 1698 | X13: 1451 | Y13: -0.015296367 | Z13: -0.058936579 | AA13: HelloData | AB13: A6
A14: — T12 Annualized (most recent 12 mo.) — | D14: A7-abi | E14: 1 | F14: 1 | G14: 18 | H14: 17 | I14: 1 | J14: 941 | K14: 1857 | L14: 1841 | M14: 12 | N14: 5 | O14: 1795 | P14: 1860 | Q14: 1800 | R14: 1769 | S14: 1895 | T14: 1650 | U14: 1845 | V14: 1712 | W14: 1818 | X14: 1598 | Y14: 0.0033990483 | Z14: 0.0094339623 | AA14: HelloData | AB14: A7
A15: Effective Gross Revenue (T12) | B15: 6032933 | D15: B1-abi | E15: 2 | F15: 2 | G15: 48 | H15: 46 | I15: 2 | J15: 1082 | K15: 2254 | L15: 2165 | M15: 24 | N15: 22 | O15: 2606 | P15: 4170 | Q15: 2165 | R15: 2305 | S15: 2130 | T15: 2260 | U15: 2200 | V15: 2014 | W15: 2103 | X15: 1842 | Y15: 0.022463207 | Z15: 0.023981019 | AA15: HelloData | AB15: B1
A16: Operating Expenses (T12) | B16: 2631211.9 | D16: B1.7-abi | E16: 2 | F16: 2 | G16: 2 | H16: 2 | I16: 0 | J16: 1082 | K16: 2238 | L16: 2044 | M16: 2 | N16: 0 | O16: 2044 | P16: 1899 | Q16: 2190 | W16: 1884 | X16: 1519 | AA16: HelloData | AB16: B1
A17: Net Operating Income (T12) | B17: 3401721.1 | D17: B2-abi | E17: 2 | F17: 2 | G17: 27 | H17: 26 | I17: 1 | J17: 1109 | K17: 2127 | L17: 2089 | M17: 12 | N17: 14 | O17: 2123 | P17: 2035 | Q17: 2115 | R17: 2080 | S17: 2035 | T17: 2350 | U17: 2105 | V17: 1815 | W17: 2060 | X17: 1839 | Y17: -0.070640177 | Z17: -0.084898131 | AA17: HelloData | AB17: B2
A18: Operating Margin (T12) | B18: 0.56385859 | D18: B2.3-abi | E18: 2 | F18: 2 | G18: 2 | H18: 2 | I18: 0 | J18: 1155 | K18: 2328 | L18: 2298 | M18: 1 | N18: 1 | O18: 2350 | P18: 2350 | W18: 2335 | X18: 1973 | AA18: HelloData | AB18: B2
D19: B3-abi | E19: 2 | F19: 2 | G19: 18 | H19: 18 | I19: 0 | J19: 1213 | K19: 2172 | L19: 2135 | M19: 9 | N19: 9 | O19: 2142 | P19: 2175 | Q19: 2130 | R19: 2175 | S19: 2130 | T19: 2099 | U19: 2145 | V19: 1836 | W19: 2128 | X19: 1773 | Y19: -0.0069444444 | Z19: 0.0062100457 | AA19: HelloData | AB19: B3
D20: TH-abi | E20: 2 | F20: 2 | G20: 2 | H20: 2 | I20: 0 | J20: 1381 | K20: 3410 | L20: 3022 | M20: 1 | N20: 1 | O20: 3410 | P20: 3410 | U20: 3395 | V20: 2908 | W20: 3395 | X20: 2889 | Y20: 0 | Z20: 0.013240418 | AA20: HelloData(unit) | AB20: TH1
D21: TH.1-abi | E21: 2 | F21: 2 | G21: 1 | H21: 0 | I21: 1 | J21: 1461 | K21: 3785 | L21: 0 | M21: 0 | N21: 0 | AA21: HelloData(unit) | AB21: TH1
D22: C1-abi | E22: 3 | F22: 2 | G22: 11 | H22: 9 | I22: 2 | J22: 1564 | K22: 2898 | L22: 2739 | M22: 2 | N22: 7 | O22: 2778 | P22: 2905 | Q22: 2650 | W22: 2762 | X22: 2299 | AA22: HelloData | AB22: C1
D23: C1.2-abi | E23: 3 | F23: 2 | G23: 1 | H23: 1 | I23: 0 | J23: 1564 | K23: 2925 | L23: 2550 | M23: 1 | N23: 0 | O23: 2550 | P23: 2550 | W23: 2535 | X23: 2044 | AA23: HelloData | AB23: C1
D24: TH.2-abi | G24: 1 | H24: 1 | I24: 0 | J24: 1427 | K24: 3955 | L24: 3955 | M24: 0 | N24: 1 | AA24: unknown
D25: TOTAL / AVG | G25: 290 | H25: 272 | I25: 18 | J25: 919 | K25: 1928 | L25: 1826 | M25: 140 | N25: 132 | O25: 1877 | U25: 1832 | V25: 1623 | W25: 1795 | X25: 1547 | Y25: -0.017189554 | Z25: -0.0098067061
D26: New-lease = lease start ≤ move-in (renewals excluded). HD T90/T365 = executed (off-market) asking/effective; HD90 YoY compares the trailing 90 days to the same window a year ago.
A28: ⚑ UNDERWRITING FLAGS
A29: • HelloData reflects the website 'Total Monthly', which can bundle mandatory fees. HD market rent here is shown NET of $15.00/mo (explicit override). See 'Reconciliation → HelloData Asking: Fee Netting' for the full derivation.
A30: • New-Lease Contract / unit history draws on 2 rent rolls (current 05/23/2026 + older 02/26/2024); older rolls supply signings that have since turned over. The dashboard and unit mix use the current rent roll only.
A31: • Seasonality: executed asking rents peak in Apr and trough in Nov (~15% spread across the HelloData history).
A32: • HelloData asking-rent YoY (same calendar month): -1.7% average across 25 month-pair(s).
A33: • Annualized EGR: T3 $5,989,462 vs T12 $6,032,933 (-0.7%) -- recent run-rate is below the trailing year.
A34: • Annualized NOI: T3 $3,479,043 vs T12 $3,401,721 (+2.3%).
A36: HOW TO USE → paste into the TMG acquisition model
A37: 1. Review 'T12 Categorized' col A (amber). Every GL line appears once with all months flowing across; edit a code via the dropdown to re-map. Category (col B) and OS Summary roll up automatically.
A38: 2. 'OS Summary' is the standardized chart of accounts (live SUMIFS, most recent 12 months). Copy A1:Q77 → model 'OS Summary Dump' A1 (Paste Special → Values).
A39: 3. 'T12 Categorized' → copy Code, Category, Line Item + the most recent 12 month columns (NOT the Total column) → model 'T12 Dump' A2.
A40: 4. 'Rent Roll (One-Line) 05-23-26' (newest rent roll) → copy the core columns A2:M(last) → model 'RR Dump' A2. (The per-unit charge-code columns to the right of the gap are reference detail, not a model paste target.)
... A42: 6. The unit mix (with new-lease + HD T90/T365/YoY market-rent indicators) is on this Dashboard; check 'Lease Trend' (seasonality / market-rent trajectory) and 'Reconciliation' (contract-rent ↔ AGPR tie-out) before underwriting. Paste targets only — do NOT populate the model itself from here.

Sheet T12 Categorized
A1: Code | B1: Category | C1: Line Item (raw GL) | D1: 45778 | E1: 45809 | F1: 45839 | G1: 45870 | H1: 45901 | I1: 45931 | J1: 45962 | K1: 45992 | L1: 46023 | M1: 46054 | N1: 46082 | O1: 46113 | P1: Total
C2: INCOME
A3: Rentinc | B3: =IFERROR(VLOOKUP($A3,Codes!$A:$B,2,FALSE()),"") -> Rental Income | C3: Gross Mkt Rent Potential | D3: 559150 | E3: 559150 | F3: 559150 | G3: 559150 | H3: 559150 | I3: 559150 | J3: 559150 | K3: 559150 | L3: 559150 | M3: 559150 | N3: 559150 | O3: 559150 | P3: =SUM(D3:O3) -> 6709800
A4: ltl | B4: =IFERROR(VLOOKUP($A4,Codes!$A:$B,2,FALSE()),"") -> (Loss to Lease) / Gain to Lease | C4: Gain/Loss To Lease | D4: -27581 | E4: -27745 | F4: -26926 | G4: -25054 | H4: -24168 | I4: -23750 | J4: -24711 | K4: -24276 | L4: -24152 | M4: -27423 | N4: -28527 | O4: -28582 | P4: =SUM(D4:O4) -> -312895
A5: vac | B5: =IFERROR(VLOOKUP($A5,Codes!$A:$B,2,FALSE()),"") -> Vacancy | C5: Vacancy | D5: -32059.41 | E5: -39950.81 | F5: -32160.7 | G5: -36295.85 | H5: -45481.47 | I5: -33225.96 | J5: -39789.69 | K5: -54891.16 | L5: -63024.55 | M5: -51062.94 | N5: -37121.02 | O5: -36993.26 | P5: =SUM(D5:O5) -> -502056.82
A6: nr | B6: =IFERROR(VLOOKUP($A6,Codes!$A:$B,2,FALSE()),"") -> Non-Revenue Units | C6: Models | D6: -2340 | E6: -2340 | F6: -2340 | G6: -2340 | H6: -2340 | I6: -2340 | J6: -2340 | K6: -2340 | L6: -2340 | M6: -2340 | N6: -2340 | O6: -2340 | P6: =SUM(D6:O6) -> -28080
A7: nr | B7: =IFERROR(VLOOKUP($A7,Codes!$A:$B,2,FALSE()),"") -> Non-Revenue Units | C7: Employee Units | D7: -780 | E7: -780 | F7: -780 | G7: -780 | H7: -780 | I7: -780 | J7: -780 | K7: -780 | L7: -780 | M7: -780 | N7: -780 | O7: 0 | P7: =SUM(D7:O7) -> -8580
A8: conc | B8: =IFERROR(VLOOKUP($A8,Codes!$A:$B,2,FALSE()),"") -> Concessions | C8: Non-Recurring Concessions | D8: -51396.97 | E8: -36344.5 | F8: -41734.5 | G8: -40560 | H8: -23142 | I8: -21379.5 | J8: -23729 | K8: -23776 | L8: -29613.92 | M8: -31630 | N8: -41571.5 | O8: -45133.5 | P8: =SUM(D8:O8) -> -410011.39
A9: cl | B9: =IFERROR(VLOOKUP($A9,Codes!$A:$B,2,FALSE()),"") -> Collection Loss / Bad Debt | C9: Less: Writeoffs | D9: 0 | E9: -1848.4 | F9: 0 | G9: 0 | H9: 0 | I9: -228 | J9: 0 | K9: 0 | L9: -590.33 | M9: -35.6 | N9: 0 | O9: 0 | P9: =SUM(D9:O9) -> -2702.33
A10: cl | B10: =IFERROR(VLOOKUP($A10,Codes!$A:$B,2,FALSE()),"") -> Collection Loss / Bad Debt | C10: Write Off Rent Recovery | D10: 578.27 | E10: 1879.47 | F10: 769.11 | G10: 435.61 | H10: 1925.3 | I10: 589.48 | J10: 717.3 | K10: 655.42 | L10: 599.36 | M10: 779.74 | N10: 317.12 | O10: 794.2 | P10: =SUM(D10:O10) -> 10040.38
A11: park | B11: =IFERROR(VLOOKUP($A11,Codes!$A:$B,2,FALSE()),"") -> Garage / Parking | C11: Garage | D11: 17933.17 | E11: 17644.06 | F11: 17812.97 | G11: 17705.81 | H11: 17039.62 | I11: 18121.15 | J11: 19020.19 | K11: 18158.39 | L11: 18462.74 | M11: 17206.53 | N11: 18794.28 | O11: 17540.68 | P11: =SUM(D11:O11) -> 215439.59
A12: park | B12: =IFERROR(VLOOKUP($A12,Codes!$A:$B,2,FALSE()),"") -> Garage / Parking | C12: Carport | D12: 2127.33 | E12: 2102.45 | F12: 2038.51 | G12: 2079.53 | H12: 2420.92 | I12: 2363.18 | J12: 2017.34 | K12: 1968.54 | L12: 2014.68 | M12: 1888.53 | N12: 2091.97 | O12: 2092.55 | P12: =SUM(D12:O12) -> 25205.53
A13: park | B13: =IFERROR(VLOOKUP($A13,Codes!$A:$B,2,FALSE()),"") -> Garage / Parking | C13: Storage | D13: 145 | E13: 203.06 | F13: 165.65 | G13: 145 | H13: 145 | I13: 172.1 | J13: 183.83 | K13: 160 | L13: 160 | M13: 160 | N13: 160 | O13: 160 | P13: =SUM(D13:O13) -> 1959.64
A14: Rentinc | B14: =IFERROR(VLOOKUP($A14,Codes!$A:$B,2,FALSE()),"") -> Rental Income | C14: Mtm Premium | D14: 1212.9 | E14: 1133.33 | F14: 1122.58 | G14: 464.52 | H14: 400 | I14: 619.35 | J14: 200 | K14: 670.97 | L14: 516.13 | M14: 557.14 | N14: 982.26 | O14: 736.66 | P14: =SUM(D14:O14) -> 8615.84
... A33: RF | B33: =IFERROR(VLOOKUP($A33,Codes!$A:$B,2,FALSE()),"") -> Rubs Fees | C33: Reimbursed Pest Control | D33: 1291.59 | E33: 1301.26 | F33: 1340.74 | G33: 1341.46 | H33: 1310.48 | I33: 1317.11 | J33: 1313.62 | K33: 1331.48 | L33: 1302.91 | M33: 1236.96 | N33: 1214.7 | O33: 1329.41 | P33: =SUM(D33:O33) -> 15631.72
C34: OPERATING EXPENSES
A35: Pay | B35: =IFERROR(VLOOKUP($A35,Codes!$A:$B,2,FALSE()),"") -> Payroll | C35: Manager | D35: 11183.45 | E35: 6763.32 | F35: 6417.17 | G35: 7455.63 | H35: 7109.48 | I35: 10144.98 | J35: 6763.33 | K35: 7455.62 | L35: 6417.17 | M35: 7455.63 | N35: 7548.71 | O35: 11183.46 | P35: =SUM(D35:O35) -> 95897.95
A36: Pay | B36: =IFERROR(VLOOKUP($A36,Codes!$A:$B,2,FALSE()),"") -> Payroll | C36: Assistant Manager | D36: 4985.05 | E36: 3181.73 | F36: 3484.61 | G36: 3459.09 | H36: 3496.35 | I36: 1821.58 | J36: 2674.18 | K36: 3445.1 | L36: 3233.37 | M36: 3364.43 | N36: 3195.15 | O36: 20.29 | P36: =SUM(D36:O36) -> 36360.93
A37: Pay | B37: =IFERROR(VLOOKUP($A37,Codes!$A:$B,2,FALSE()),"") -> Payroll | C37: Leasing Consultant | D37: 4815.47 | E37: 3201.04 | F37: 2469.79 | G37: 2622.8 | H37: 3183.66 | I37: 4160.93 | J37: 3024.4 | K37: 2801.38 | L37: 3131.45 | M37: 3080.91 | N37: 3225.07 | O37: 2285.55 | P37: =SUM(D37:O37) -> 38002.45
A38: Pay | B38: =IFERROR(VLOOKUP($A38,Codes!$A:$B,2,FALSE()),"") -> Payroll | C38: Divisional Maint Mgr | D38: 0 | E38: 0 | F38: 0 | G38: 249.68 | H38: 0 | I38: 0 | J38: 0 | K38: 0 | L38: 0 | M38: 0 | N38: 0 | O38: 0 | P38: =SUM(D38:O38) -> 249.68
A39: Pay | B39: =IFERROR(VLOOKUP($A39,Codes!$A:$B,2,FALSE()),"") -> Payroll | C39: Maintenance Manager | D39: 8573.27 | E39: 5709.81 | F39: 5306.73 | G39: 9256.24 | H39: 5620.23 | I39: 8255.05 | J39: 5721.34 | K39: 5443.68 | L39: 5105.94 | M39: 5492.05 | N39: 5945.75 | O39: 8045.39 | P39: =SUM(D39:O39) -> 78475.48
A40: Pay | B40: =IFERROR(VLOOKUP($A40,Codes!$A:$B,2,FALSE()),"") -> Payroll | C40: Asst Maintenance Mgr | D40: 424.39 | E40: 0 | F40: 264.7 | G40: 713.81 | H40: 1.35 | I40: 0 | J40: 0 | K40: 0 | L40: 0 | M40: 0 | N40: 0 | O40: 0 | P40: =SUM(D40:O40) -> 1404.25
A41: Pay | B41: =IFERROR(VLOOKUP($A41,Codes!$A:$B,2,FALSE()),"") -> Payroll | C41: Maintenance Technician | D41: 7238.87 | E41: 4407.65 | F41: 3360.95 | G41: 0 | H41: 2692.2 | I41: 6805.36 | J41: 4405.9 | K41: 4379.48 | L41: 4196.6 | M41: 4537.2 | N41: 4324 | O41: 6688.79 | P41: =SUM(D41:O41) -> 53037
A42: Pay | B42: =IFERROR(VLOOKUP($A42,Codes!$A:$B,2,FALSE()),"") -> Payroll | C42: Porter/Grounds Person | D42: 4058.81 | E42: 2560.33 | F42: 2541.82 | G42: 1573.42 | H42: 2356.5 | I42: 1740.96 | J42: 3101.56 | K42: 3122.56 | L42: 3108.76 | M42: 3017.86 | N42: 2971.06 | O42: 4372.44 | P42: =SUM(D42:O42) -> 34526.08
A43: Pay | B43: =IFERROR(VLOOKUP($A43,Codes!$A:$B,2,FALSE()),"") -> Payroll | C43: Housekeeper | D43: 4448.69 | E43: 2567.02 | F43: 2456.43 | G43: 2764.12 | H43: 1488.14 | I43: 4444.05 | J43: 2180.93 | K43: 2847.61 | L43: 2373.07 | M43: 2949.66 | N43: 2963.83 | O43: 4169.19 | P43: =SUM(D43:O43) -> 35652.74
A44: PBo | B44: =IFERROR(VLOOKUP($A44,Codes!$A:$B,2,FALSE()),"") -> Payroll Bonuses | C44: Bonuses | D44: 5804.95 | E44: 2953.87 | F44: 2444.96 | G44: 4250.44 | H44: 7587 | I44: 3435.35 | J44: 1055.26 | K44: 4772.8 | L44: 7182.49 | M44: 2932.09 | N44: 11664.54 | O44: 5933.22 | P44: =SUM(D44:O44) -> 60016.97
A45: PB | B45: =IFERROR(VLOOKUP($A45,Codes!$A:$B,2,FALSE()),"") -> Payroll Burden | C45: Payroll Taxes - Administrative | D45: 1870.45 | E45: 1208.23 | F45: 1157.02 | G45: 1404.62 | H45: 1235.74 | I45: 1444.62 | J45: 1245.42 | K45: 1278.47 | L45: 1553.4 | M45: 1726.13 | N45: 1549.35 | O45: 1804.01 | P45: =SUM(D45:O45) -> 17477.46
A46: PB | B46: =IFERROR(VLOOKUP($A46,Codes!$A:$B,2,FALSE()),"") -> Payroll Burden | C46: Payroll Taxes - Maintenance | D46: 1898.48 | E46: 1177.76 | F46: 1304.91 | G46: 1421.7 | H46: 1056.7 | I46: 1899.14 | J46: 1349.98 | K46: 1332.07 | L46: 1554.69 | M46: 1835.24 | N46: 1678.04 | O46: 2104.93 | P46: =SUM(D46:O46) -> 18613.64
... A137: ret | B137: =IFERROR(VLOOKUP($A137,Codes!$A:$B,2,FALSE()),"") -> Real Estate Taxes | C137: Homeowners Association Fees | D137: 0 | E137: 0 | F137: 0 | G137: 0 | H137: 0 | I137: 57792.2 | J137: 0 | K137: 0 | L137: 0 | M137: 0 | N137: 0 | O137: 0 | P137: =SUM(D137:O137) -> 57792.2
A139: Outliers & Notable Patterns (amber month cells = > 3.5× that line's median)
A140: • Plumbing Supplies: Aug 2025 = $5,655 (55.4× the line's median) — one-off / reclass worth checking.
A141: • Marketing Dues & Subscriptions: Dec 2025 = $4,639 (10.9× the line's median) — one-off / reclass worth checking.
A142: • Internet Listing Service (ILS): May 2025 = $5,290 (7.0× the line's median) — one-off / reclass worth checking.
A143: • Training & Education: May 2025 = $2,708 (5.3× the line's median) — one-off / reclass worth checking.
A144: • Fire/Life Safety: May 2025 = $8,341 (4.9× the line's median) — one-off / reclass worth checking.
A145: • Locator/Broker Fees: Jul 2025 = $9,580 (4.7× the line's median) — one-off / reclass worth checking.
A146: • Water Irrigation: Jul 2025 = $5,908 (4.2× the line's median) — one-off / reclass worth checking.
A147: • Temp Help - Maintenance: Jun 2025 = $11,823 (4.1× the line's median) — one-off / reclass worth checking.

Sheet OS Summary
B1: Aura Beacon Island
B2: Operating Statement — Standardized (live rollup)
B3: Adjusted Amounts ($ totals) — model paste target (A1:Q77)
C4: Annual | D4: Annual | E4: Annual | F4: Monthly | G4: Monthly | H4: Monthly | I4: Monthly | J4: Monthly | K4: Monthly | L4: Monthly | M4: Monthly | N4: Monthly | O4: Monthly | P4: Monthly | Q4: Monthly
F5: 45778 | G5: 45809 | H5: 45839 | I5: 45870 | J5: 45901 | K5: 45931 | L5: 45962 | M5: 45992 | N5: 46023 | O5: 46054 | P5: 46082 | Q5: 46113
A6: Code | B6: Effective Gross Revenue
A7: Rentinc | B7: Rental Income | F7: =SUMIFS('T12 Categorized'!D:D,'T12 Categorized'!$A:$A,$A7) -> 560362.9 | G7: =SUMIFS('T12 Categorized'!E:E,'T12 Categorized'!$A:$A,$A7) -> 560283.33 | H7: =SUMIFS('T12 Categorized'!F:F,'T12 Categorized'!$A:$A,$A7) -> 560272.58 | I7: =SUMIFS('T12 Categorized'!G:G,'T12 Categorized'!$A:$A,$A7) -> 559614.52 | J7: =SUMIFS('T12 Categorized'!H:H,'T12 Categorized'!$A:$A,$A7) -> 559550 | K7: =SUMIFS('T12 Categorized'!I:I,'T12 Categorized'!$A:$A,$A7) -> 559769.35 | L7: =SUMIFS('T12 Categorized'!J:J,'T12 Categorized'!$A:$A,$A7) -> 559350 | M7: =SUMIFS('T12 Categorized'!K:K,'T12 Categorized'!$A:$A,$A7) -> 559820.97 | N7: =SUMIFS('T12 Categorized'!L:L,'T12 Categorized'!$A:$A,$A7) -> 559666.13 | O7: =SUMIFS('T12 Categorized'!M:M,'T12 Categorized'!$A:$A,$A7) -> 559707.14 | P7: =SUMIFS('T12 Categorized'!N:N,'T12 Categorized'!$A:$A,$A7) -> 560132.26 | Q7: =SUMIFS('T12 Categorized'!O:O,'T12 Categorized'!$A:$A,$A7) -> 559886.66
A8: OI | B8: Other Income | F8: =SUMIFS('T12 Categorized'!D:D,'T12 Categorized'!$A:$A,$A8) -> 8089.05 | G8: =SUMIFS('T12 Categorized'!E:E,'T12 Categorized'!$A:$A,$A8) -> 13543.97 | H8: =SUMIFS('T12 Categorized'!F:F,'T12 Categorized'!$A:$A,$A8) -> 2301.9 | I8: =SUMIFS('T12 Categorized'!G:G,'T12 Categorized'!$A:$A,$A8) -> 7760.52 | J8: =SUMIFS('T12 Categorized'!H:H,'T12 Categorized'!$A:$A,$A8) -> 16194.51 | K8: =SUMIFS('T12 Categorized'!I:I,'T12 Categorized'!$A:$A,$A8) -> 15595.09 | L8: =SUMIFS('T12 Categorized'!J:J,'T12 Categorized'!$A:$A,$A8) -> 21356.58 | M8: =SUMIFS('T12 Categorized'!K:K,'T12 Categorized'!$A:$A,$A8) -> 6500.52 | N8: =SUMIFS('T12 Categorized'!L:L,'T12 Categorized'!$A:$A,$A8) -> 11917.51 | O8: =SUMIFS('T12 Categorized'!M:M,'T12 Categorized'!$A:$A,$A8) -> 10691.33 | P8: =SUMIFS('T12 Categorized'!N:N,'T12 Categorized'!$A:$A,$A8) -> 17428.26 | Q8: =SUMIFS('T12 Categorized'!O:O,'T12 Categorized'!$A:$A,$A8) -> 23681.5
A9: RWS | B9: Rubs Water / Sewage | F9: =SUMIFS('T12 Categorized'!D:D,'T12 Categorized'!$A:$A,$A9) -> 6959.11 | G9: =SUMIFS('T12 Categorized'!E:E,'T12 Categorized'!$A:$A,$A9) -> 7143.5 | H9: =SUMIFS('T12 Categorized'!F:F,'T12 Categorized'!$A:$A,$A9) -> 7380.64 | I9: =SUMIFS('T12 Categorized'!G:G,'T12 Categorized'!$A:$A,$A9) -> 7337.77 | J9: =SUMIFS('T12 Categorized'!H:H,'T12 Categorized'!$A:$A,$A9) -> 7228.83 | K9: =SUMIFS('T12 Categorized'!I:I,'T12 Categorized'!$A:$A,$A9) -> 7292.49 | L9: =SUMIFS('T12 Categorized'!J:J,'T12 Categorized'!$A:$A,$A9) -> 6808.47 | M9: =SUMIFS('T12 Categorized'!K:K,'T12 Categorized'!$A:$A,$A9) -> 6969.01 | N9: =SUMIFS('T12 Categorized'!L:L,'T12 Categorized'!$A:$A,$A9) -> 6428.92 | O9: =SUMIFS('T12 Categorized'!M:M,'T12 Categorized'!$A:$A,$A9) -> 6438.11 | P9: =SUMIFS('T12 Categorized'!N:N,'T12 Categorized'!$A:$A,$A9) -> 6786.85 | Q9: =SUMIFS('T12 Categorized'!O:O,'T12 Categorized'!$A:$A,$A9) -> 6531.75
A10: RT | B10: Rubs Trash | F10: =SUMIFS('T12 Categorized'!D:D,'T12 Categorized'!$A:$A,$A10) -> 7588.49 | G10: =SUMIFS('T12 Categorized'!E:E,'T12 Categorized'!$A:$A,$A10) -> 7495.05 | H10: =SUMIFS('T12 Categorized'!F:F,'T12 Categorized'!$A:$A,$A10) -> 7663.84 | I10: =SUMIFS('T12 Categorized'!G:G,'T12 Categorized'!$A:$A,$A10) -> 7618.37 | J10: =SUMIFS('T12 Categorized'!H:H,'T12 Categorized'!$A:$A,$A10) -> 7467.65 | K10: =SUMIFS('T12 Categorized'!I:I,'T12 Categorized'!$A:$A,$A10) -> 7585.84 | L10: =SUMIFS('T12 Categorized'!J:J,'T12 Categorized'!$A:$A,$A10) -> 7579.56 | M10: =SUMIFS('T12 Categorized'!K:K,'T12 Categorized'!$A:$A,$A10) -> 6915.2 | N10: =SUMIFS('T12 Categorized'!L:L,'T12 Categorized'!$A:$A,$A10) -> 7073.64 | O10: =SUMIFS('T12 Categorized'!M:M,'T12 Categorized'!$A:$A,$A10) -> 6874.17 | P10: =SUMIFS('T12 Categorized'!N:N,'T12 Categorized'!$A:$A,$A10) -> 7143.6 | Q10: =SUMIFS('T12 Categorized'!O:O,'T12 Categorized'!$A:$A,$A10) -> 7132.04
A11: RF | B11: Rubs Fees | F11: =SUMIFS('T12 Categorized'!D:D,'T12 Categorized'!$A:$A,$A11) -> 1537.67 | G11: =SUMIFS('T12 Categorized'!E:E,'T12 Categorized'!$A:$A,$A11) -> 1543.28 | H11: =SUMIFS('T12 Categorized'!F:F,'T12 Categorized'!$A:$A,$A11) -> 1471.98 | I11: =SUMIFS('T12 Categorized'!G:G,'T12 Categorized'!$A:$A,$A11) -> 1528.12 | J11: =SUMIFS('T12 Categorized'!H:H,'T12 Categorized'!$A:$A,$A11) -> 1318.6 | K11: =SUMIFS('T12 Categorized'!I:I,'T12 Categorized'!$A:$A,$A11) -> 1411.99 | L11: =SUMIFS('T12 Categorized'!J:J,'T12 Categorized'!$A:$A,$A11) -> 1434.13 | M11: =SUMIFS('T12 Categorized'!K:K,'T12 Categorized'!$A:$A,$A11) -> 1736.61 | N11: =SUMIFS('T12 Categorized'!L:L,'T12 Categorized'!$A:$A,$A11) -> 1383.14 | O11: =SUMIFS('T12 Categorized'!M:M,'T12 Categorized'!$A:$A,$A11) -> 1258.28 | P11: =SUMIFS('T12 Categorized'!N:N,'T12 Categorized'!$A:$A,$A11) -> 1310.28 | Q11: =SUMIFS('T12 Categorized'!O:O,'T12 Categorized'!$A:$A,$A11) -> 1480.36
A12: park | B12: Garage / Parking | F12: =SUMIFS('T12 Categorized'!D:D,'T12 Categorized'!$A:$A,$A12) -> 20205.5 | G12: =SUMIFS('T12 Categorized'!E:E,'T12 Categorized'!$A:$A,$A12) -> 19949.57 | H12: =SUMIFS('T12 Categorized'!F:F,'T12 Categorized'!$A:$A,$A12) -> 20017.13 | I12: =SUMIFS('T12 Categorized'!G:G,'T12 Categorized'!$A:$A,$A12) -> 19930.34 | J12: =SUMIFS('T12 Categorized'!H:H,'T12 Categorized'!$A:$A,$A12) -> 19605.54 | K12: =SUMIFS('T12 Categorized'!I:I,'T12 Categorized'!$A:$A,$A12) -> 20656.43 | L12: =SUMIFS('T12 Categorized'!J:J,'T12 Categorized'!$A:$A,$A12) -> 21221.36 | M12: =SUMIFS('T12 Categorized'!K:K,'T12 Categorized'!$A:$A,$A12) -> 20286.93 | N12: =SUMIFS('T12 Categorized'!L:L,'T12 Categorized'!$A:$A,$A12) -> 20637.42 | O12: =SUMIFS('T12 Categorized'!M:M,'T12 Categorized'!$A:$A,$A12) -> 19255.06 | P12: =SUMIFS('T12 Categorized'!N:N,'T12 Categorized'!$A:$A,$A12) -> 21046.25 | Q12: =SUMIFS('T12 Categorized'!O:O,'T12 Categorized'!$A:$A,$A12) -> 19793.23
A13: CI | B13: Corporate Income | F13: =SUMIFS('T12 Categorized'!D:D,'T12 Categorized'!$A:$A,$A13) -> 0 | G13: =SUMIFS('T12 Categorized'!E:E,'T12 Categorized'!$A:$A,$A13) -> 0 | H13: =SUMIFS('T12 Categorized'!F:F,'T12 Categorized'!$A:$A,$A13) -> 0 | I13: =SUMIFS('T12 Categorized'!G:G,'T12 Categorized'!$A:$A,$A13) -> 0 | J13: =SUMIFS('T12 Categorized'!H:H,'T12 Categorized'!$A:$A,$A13) -> 0 | K13: =SUMIFS('T12 Categorized'!I:I,'T12 Categorized'!$A:$A,$A13) -> 0 | L13: =SUMIFS('T12 Categorized'!J:J,'T12 Categorized'!$A:$A,$A13) -> 0 | M13: =SUMIFS('T12 Categorized'!K:K,'T12 Categorized'!$A:$A,$A13) -> 0 | N13: =SUMIFS('T12 Categorized'!L:L,'T12 Categorized'!$A:$A,$A13) -> 0 | O13: =SUMIFS('T12 Categorized'!M:M,'T12 Categorized'!$A:$A,$A13) -> 0 | P13: =SUMIFS('T12 Categorized'!N:N,'T12 Categorized'!$A:$A,$A13) -> 0 | Q13: =SUMIFS('T12 Categorized'!O:O,'T12 Categorized'!$A:$A,$A13) -> 0
A14: cable | B14: Cable Income | F14: =SUMIFS('T12 Categorized'!D:D,'T12 Categorized'!$A:$A,$A14) -> 0 | G14: =SUMIFS('T12 Categorized'!E:E,'T12 Categorized'!$A:$A,$A14) -> 0 | H14: =SUMIFS('T12 Categorized'!F:F,'T12 Categorized'!$A:$A,$A14) -> 0 | I14: =SUMIFS('T12 Categorized'!G:G,'T12 Categorized'!$A:$A,$A14) -> 0 | J14: =SUMIFS('T12 Categorized'!H:H,'T12 Categorized'!$A:$A,$A14) -> 0 | K14: =SUMIFS('T12 Categorized'!I:I,'T12 Categorized'!$A:$A,$A14) -> 0 | L14: =SUMIFS('T12 Categorized'!J:J,'T12 Categorized'!$A:$A,$A14) -> 0 | M14: =SUMIFS('T12 Categorized'!K:K,'T12 Categorized'!$A:$A,$A14) -> 0 | N14: =SUMIFS('T12 Categorized'!L:L,'T12 Categorized'!$A:$A,$A14) -> 0 | O14: =SUMIFS('T12 Categorized'!M:M,'T12 Categorized'!$A:$A,$A14) -> 0 | P14: =SUMIFS('T12 Categorized'!N:N,'T12 Categorized'!$A:$A,$A14) -> 0 | Q14: =SUMIFS('T12 Categorized'!O:O,'T12 Categorized'!$A:$A,$A14) -> 0
A15: ltl | B15: (Loss to Lease) / Gain to Lease | F15: =SUMIFS('T12 Categorized'!D:D,'T12 Categorized'!$A:$A,$A15) -> -27581 | G15: =SUMIFS('T12 Categorized'!E:E,'T12 Categorized'!$A:$A,$A15) -> -27745 | H15: =SUMIFS('T12 Categorized'!F:F,'T12 Categorized'!$A:$A,$A15) -> -26926 | I15: =SUMIFS('T12 Categorized'!G:G,'T12 Categorized'!$A:$A,$A15) -> -25054 | J15: =SUMIFS('T12 Categorized'!H:H,'T12 Categorized'!$A:$A,$A15) -> -24168 | K15: =SUMIFS('T12 Categorized'!I:I,'T12 Categorized'!$A:$A,$A15) -> -23750 | L15: =SUMIFS('T12 Categorized'!J:J,'T12 Categorized'!$A:$A,$A15) -> -24711 | M15: =SUMIFS('T12 Categorized'!K:K,'T12 Categorized'!$A:$A,$A15) -> -24276 | N15: =SUMIFS('T12 Categorized'!L:L,'T12 Categorized'!$A:$A,$A15) -> -24152 | O15: =SUMIFS('T12 Categorized'!M:M,'T12 Categorized'!$A:$A,$A15) -> -27423 | P15: =SUMIFS('T12 Categorized'!N:N,'T12 Categorized'!$A:$A,$A15) -> -28527 | Q15: =SUMIFS('T12 Categorized'!O:O,'T12 Categorized'!$A:$A,$A15) -> -28582
A16: vac | B16: Vacancy | F16: =SUMIFS('T12 Categorized'!D:D,'T12 Categorized'!$A:$A,$A16) -> -32059.41 | G16: =SUMIFS('T12 Categorized'!E:E,'T12 Categorized'!$A:$A,$A16) -> -39950.81 | H16: =SUMIFS('T12 Categorized'!F:F,'T12 Categorized'!$A:$A,$A16) -> -32160.7 | I16: =SUMIFS('T12 Categorized'!G:G,'T12 Categorized'!$A:$A,$A16) -> -36295.85 | J16: =SUMIFS('T12 Categorized'!H:H,'T12 Categorized'!$A:$A,$A16) -> -45481.47 | K16: =SUMIFS('T12 Categorized'!I:I,'T12 Categorized'!$A:$A,$A16) -> -33225.96 | L16: =SUMIFS('T12 Categorized'!J:J,'T12 Categorized'!$A:$A,$A16) -> -39789.69 | M16: =SUMIFS('T12 Categorized'!K:K,'T12 Categorized'!$A:$A,$A16) -> -54891.16 | N16: =SUMIFS('T12 Categorized'!L:L,'T12 Categorized'!$A:$A,$A16) -> -63024.55 | O16: =SUMIFS('T12 Categorized'!M:M,'T12 Categorized'!$A:$A,$A16) -> -51062.94 | P16: =SUMIFS('T12 Categorized'!N:N,'T12 Categorized'!$A:$A,$A16) -> -37121.02 | Q16: =SUMIFS('T12 Categorized'!O:O,'T12 Categorized'!$A:$A,$A16) -> -36993.26
A17: cl | B17: Collection Loss / Bad Debt | F17: =SUMIFS('T12 Categorized'!D:D,'T12 Categorized'!$A:$A,$A17) -> 578.27 | G17: =SUMIFS('T12 Categorized'!E:E,'T12 Categorized'!$A:$A,$A17) -> 31.07 | H17: =SUMIFS('T12 Categorized'!F:F,'T12 Categorized'!$A:$A,$A17) -> 769.11 | I17: =SUMIFS('T12 Categorized'!G:G,'T12 Categorized'!$A:$A,$A17) -> 435.61 | J17: =SUMIFS('T12 Categorized'!H:H,'T12 Categorized'!$A:$A,$A17) -> 1925.3 | K17: =SUMIFS('T12 Categorized'!I:I,'T12 Categorized'!$A:$A,$A17) -> 361.48 | L17: =SUMIFS('T12 Categorized'!J:J,'T12 Categorized'!$A:$A,$A17) -> 717.3 | M17: =SUMIFS('T12 Categorized'!K:K,'T12 Categorized'!$A:$A,$A17) -> 655.42 | N17: =SUMIFS('T12 Categorized'!L:L,'T12 Categorized'!$A:$A,$A17) -> 9.03 | O17: =SUMIFS('T12 Categorized'!M:M,'T12 Categorized'!$A:$A,$A17) -> 744.14 | P17: =SUMIFS('T12 Categorized'!N:N,'T12 Categorized'!$A:$A,$A17) -> 317.12 | Q17: =SUMIFS('T12 Categorized'!O:O,'T12 Categorized'!$A:$A,$A17) -> 794.2
A18: nr | B18: Non-Revenue Units | F18: =SUMIFS('T12 Categorized'!D:D,'T12 Categorized'!$A:$A,$A18) -> -3120 | G18: =SUMIFS('T12 Categorized'!E:E,'T12 Categorized'!$A:$A,$A18) -> -3120 | H18: =SUMIFS('T12 Categorized'!F:F,'T12 Categorized'!$A:$A,$A18) -> -3120 | I18: =SUMIFS('T12 Categorized'!G:G,'T12 Categorized'!$A:$A,$A18) -> -3120 | J18: =SUMIFS('T12 Categorized'!H:H,'T12 Categorized'!$A:$A,$A18) -> -3120 | K18: =SUMIFS('T12 Categorized'!I:I,'T12 Categorized'!$A:$A,$A18) -> -3120 | L18: =SUMIFS('T12 Categorized'!J:J,'T12 Categorized'!$A:$A,$A18) -> -3120 | M18: =SUMIFS('T12 Categorized'!K:K,'T12 Categorized'!$A:$A,$A18) -> -3120 | N18: =SUMIFS('T12 Categorized'!L:L,'T12 Categorized'!$A:$A,$A18) -> -3120 | O18: =SUMIFS('T12 Categorized'!M:M,'T12 Categorized'!$A:$A,$A18) -> -3120 | P18: =SUMIFS('T12 Categorized'!N:N,'T12 Categorized'!$A:$A,$A18) -> -3120 | Q18: =SUMIFS('T12 Categorized'!O:O,'T12 Categorized'!$A:$A,$A18) -> -2340
A19: conc | B19: Concessions | F19: =SUMIFS('T12 Categorized'!D:D,'T12 Categorized'!$A:$A,$A19) -> -51396.97 | G19: =SUMIFS('T12 Categorized'!E:E,'T12 Categorized'!$A:$A,$A19) -> -36344.5 | H19: =SUMIFS('T12 Categorized'!F:F,'T12 Categorized'!$A:$A,$A19) -> -41734.5 | I19: =SUMIFS('T12 Categorized'!G:G,'T12 Categorized'!$A:$A,$A19) -> -40560 | J19: =SUMIFS('T12 Categorized'!H:H,'T12 Categorized'!$A:$A,$A19) -> -23142 | K19: =SUMIFS('T12 Categorized'!I:I,'T12 Categorized'!$A:$A,$A19) -> -21379.5 | L19: =SUMIFS('T12 Categorized'!J:J,'T12 Categorized'!$A:$A,$A19) -> -23729 | M19: =SUMIFS('T12 Categorized'!K:K,'T12 Categorized'!$A:$A,$A19) -> -23776 | N19: =SUMIFS('T12 Categorized'!L:L,'T12 Categorized'!$A:$A,$A19) -> -29613.92 | O19: =SUMIFS('T12 Categorized'!M:M,'T12 Categorized'!$A:$A,$A19) -> -31630 | P19: =SUMIFS('T12 Categorized'!N:N,'T12 Categorized'!$A:$A,$A19) -> -41571.5 | Q19: =SUMIFS('T12 Categorized'!O:O,'T12 Categorized'!$A:$A,$A19) -> -45133.5
B20: Effective Gross Revenue | F20: =SUM(F7:F19) -> 491163.61 | G20: =SUM(G7:G19) -> 502829.46 | H20: =SUM(H7:H19) -> 495935.98 | I20: =SUM(I7:I19) -> 499195.4 | J20: =SUM(J7:J19) -> 517378.96 | K20: =SUM(K7:K19) -> 531197.21 | L20: =SUM(L7:L19) -> 527117.71 | M20: =SUM(M7:M19) -> 496821.5 | ... Q20: =SUM(Q7:Q19) -> 506250.98
B22: Operating Expenses
A23: Pay | B23: Payroll | F23: =SUMIFS('T12 Categorized'!D:D,'T12 Categorized'!$A:$A,$A23) -> 47514.19 | G23: =SUMIFS('T12 Categorized'!E:E,'T12 Categorized'!$A:$A,$A23) -> 42160.49 | H23: =SUMIFS('T12 Categorized'!F:F,'T12 Categorized'!$A:$A,$A23) -> 35025.93 | I23: =SUMIFS('T12 Categorized'!G:G,'T12 Categorized'!$A:$A,$A23) -> 35609.56 | J23: =SUMIFS('T12 Categorized'!H:H,'T12 Categorized'!$A:$A,$A23) -> 26120.12 | K23: =SUMIFS('T12 Categorized'!I:I,'T12 Categorized'!$A:$A,$A23) -> 43340.74 | L23: =SUMIFS('T12 Categorized'!J:J,'T12 Categorized'!$A:$A,$A23) -> 29301.81 | M23: =SUMIFS('T12 Categorized'!K:K,'T12 Categorized'!$A:$A,$A23) -> 35972.44 | N23: =SUMIFS('T12 Categorized'!L:L,'T12 Categorized'!$A:$A,$A23) -> 29885.56 | O23: =SUMIFS('T12 Categorized'!M:M,'T12 Categorized'!$A:$A,$A23) -> 31936.37 | P23: =SUMIFS('T12 Categorized'!N:N,'T12 Categorized'!$A:$A,$A23) -> 33109.17 | Q23: =SUMIFS('T12 Categorized'!O:O,'T12 Categorized'!$A:$A,$A23) -> 40455.79
A24: PB | B24: Payroll Burden | F24: =SUMIFS('T12 Categorized'!D:D,'T12 Categorized'!$A:$A,$A24) -> 4854.84 | G24: =SUMIFS('T12 Categorized'!E:E,'T12 Categorized'!$A:$A,$A24) -> 3083.18 | H24: =SUMIFS('T12 Categorized'!F:F,'T12 Categorized'!$A:$A,$A24) -> 3169.32 | I24: =SUMIFS('T12 Categorized'!G:G,'T12 Categorized'!$A:$A,$A24) -> 3555.02 | J24: =SUMIFS('T12 Categorized'!H:H,'T12 Categorized'!$A:$A,$A24) -> 2864.74 | K24: =SUMIFS('T12 Categorized'!I:I,'T12 Categorized'!$A:$A,$A24) -> 4025.34 | L24: =SUMIFS('T12 Categorized'!J:J,'T12 Categorized'!$A:$A,$A24) -> 3286.26 | M24: =SUMIFS('T12 Categorized'!K:K,'T12 Categorized'!$A:$A,$A24) -> 3300.42 | N24: =SUMIFS('T12 Categorized'!L:L,'T12 Categorized'!$A:$A,$A24) -> 3831.22 | O24: =SUMIFS('T12 Categorized'!M:M,'T12 Categorized'!$A:$A,$A24) -> 4210.74 | P24: =SUMIFS('T12 Categorized'!N:N,'T12 Categorized'!$A:$A,$A24) -> 3927.4 | Q24: =SUMIFS('T12 Categorized'!O:O,'T12 Categorized'!$A:$A,$A24) -> 4864.51
A25: PBo | B25: Payroll Bonuses | F25: =SUMIFS('T12 Categorized'!D:D,'T12 Categorized'!$A:$A,$A25) -> 5804.95 | G25: =SUMIFS('T12 Categorized'!E:E,'T12 Categorized'!$A:$A,$A25) -> 2953.87 | H25: =SUMIFS('T12 Categorized'!F:F,'T12 Categorized'!$A:$A,$A25) -> 2444.96 | I25: =SUMIFS('T12 Categorized'!G:G,'T12 Categorized'!$A:$A,$A25) -> 4250.44 | J25: =SUMIFS('T12 Categorized'!H:H,'T12 Categorized'!$A:$A,$A25) -> 7587 | K25: =SUMIFS('T12 Categorized'!I:I,'T12 Categorized'!$A:$A,$A25) -> 3435.35 | L25: =SUMIFS('T12 Categorized'!J:J,'T12 Categorized'!$A:$A,$A25) -> 1055.26 | M25: =SUMIFS('T12 Categorized'!K:K,'T12 Categorized'!$A:$A,$A25) -> 4772.8 | N25: =SUMIFS('T12 Categorized'!L:L,'T12 Categorized'!$A:$A,$A25) -> 7182.49 | O25: =SUMIFS('T12 Categorized'!M:M,'T12 Categorized'!$A:$A,$A25) -> 2932.09 | P25: =SUMIFS('T12 Categorized'!N:N,'T12 Categorized'!$A:$A,$A25) -> 11664.54 | Q25: =SUMIFS('T12 Categorized'!O:O,'T12 Categorized'!$A:$A,$A25) -> 5933.22
A26: adv | B26: Marketing / Advertising | F26: =SUMIFS('T12 Categorized'!D:D,'T12 Categorized'!$A:$A,$A26) -> 23263.22 | G26: =SUMIFS('T12 Categorized'!E:E,'T12 Categorized'!$A:$A,$A26) -> 24143.28 | H26: =SUMIFS('T12 Categorized'!F:F,'T12 Categorized'!$A:$A,$A26) -> 32636.04 | I26: =SUMIFS('T12 Categorized'!G:G,'T12 Categorized'!$A:$A,$A26) -> 12131.77 | J26: =SUMIFS('T12 Categorized'!H:H,'T12 Categorized'!$A:$A,$A26) -> 15473.02 | K26: =SUMIFS('T12 Categorized'!I:I,'T12 Categorized'!$A:$A,$A26) -> 14952.05 | L26: =SUMIFS('T12 Categorized'!J:J,'T12 Categorized'!$A:$A,$A26) -> 25697.55 | M26: =SUMIFS('T12 Categorized'!K:K,'T12 Categorized'!$A:$A,$A26) -> 26197.6 | N26: =SUMIFS('T12 Categorized'!L:L,'T12 Categorized'!$A:$A,$A26) -> 10870.19 | O26: =SUMIFS('T12 Categorized'!M:M,'T12 Categorized'!$A:$A,$A26) -> 17144.65 | P26: =SUMIFS('T12 Categorized'!N:N,'T12 Categorized'!$A:$A,$A26) -> 10647.48 | Q26: =SUMIFS('T12 Categorized'!O:O,'T12 Categorized'!$A:$A,$A26) -> 22087.03
A27: GA | B27: General & Administrative | F27: =SUMIFS('T12 Categorized'!D:D,'T12 Categorized'!$A:$A,$A27) -> 11338.36 | G27: =SUMIFS('T12 Categorized'!E:E,'T12 Categorized'!$A:$A,$A27) -> 7288.34 | H27: =SUMIFS('T12 Categorized'!F:F,'T12 Categorized'!$A:$A,$A27) -> 7195.74 | I27: =SUMIFS('T12 Categorized'!G:G,'T12 Categorized'!$A:$A,$A27) -> 9145.64 | J27: =SUMIFS('T12 Categorized'!H:H,'T12 Categorized'!$A:$A,$A27) -> 10112.75 | K27: =SUMIFS('T12 Categorized'!I:I,'T12 Categorized'!$A:$A,$A27) -> 7104.98 | L27: =SUMIFS('T12 Categorized'!J:J,'T12 Categorized'!$A:$A,$A27) -> 7130.14 | M27: =SUMIFS('T12 Categorized'!K:K,'T12 Categorized'!$A:$A,$A27) -> 7674.87 | N27: =SUMIFS('T12 Categorized'!L:L,'T12 Categorized'!$A:$A,$A27) -> 2992.56 | O27: =SUMIFS('T12 Categorized'!M:M,'T12 Categorized'!$A:$A,$A27) -> 9888.61 | P27: =SUMIFS('T12 Categorized'!N:N,'T12 Categorized'!$A:$A,$A27) -> 7589.01 | Q27: =SUMIFS('T12 Categorized'!O:O,'T12 Categorized'!$A:$A,$A27) -> 8156.05
A28: turn | B28: Turnover | F28: =SUMIFS('T12 Categorized'!D:D,'T12 Categorized'!$A:$A,$A28) -> 12238.95 | G28: =SUMIFS('T12 Categorized'!E:E,'T12 Categorized'!$A:$A,$A28) -> 7301.18 | H28: =SUMIFS('T12 Categorized'!F:F,'T12 Categorized'!$A:$A,$A28) -> 9642.41 | I28: =SUMIFS('T12 Categorized'!G:G,'T12 Categorized'!$A:$A,$A28) -> 5349.9 | J28: =SUMIFS('T12 Categorized'!H:H,'T12 Categorized'!$A:$A,$A28) -> 6746.19 | K28: =SUMIFS('T12 Categorized'!I:I,'T12 Categorized'!$A:$A,$A28) -> 3228.24 | L28: =SUMIFS('T12 Categorized'!J:J,'T12 Categorized'!$A:$A,$A28) -> 5587.59 | M28: =SUMIFS('T12 Categorized'!K:K,'T12 Categorized'!$A:$A,$A28) -> 17243.43 | N28: =SUMIFS('T12 Categorized'!L:L,'T12 Categorized'!$A:$A,$A28) -> 6906.11 | O28: =SUMIFS('T12 Categorized'!M:M,'T12 Categorized'!$A:$A,$A28) -> 2769.18 | P28: =SUMIFS('T12 Categorized'!N:N,'T12 Categorized'!$A:$A,$A28) -> 1531.22 | Q28: =SUMIFS('T12 Categorized'!O:O,'T12 Categorized'!$A:$A,$A28) -> 31.18
A29: inter/exte | B29: R&M Interior / Exterior | F29: =SUMIFS('T12 Categorized'!D:D,'T12 Categorized'!$A:$A,$A29) -> 3379.41 | G29: =SUMIFS('T12 Categorized'!E:E,'T12 Categorized'!$A:$A,$A29) -> 5455.23 | H29: =SUMIFS('T12 Categorized'!F:F,'T12 Categorized'!$A:$A,$A29) -> 3778.63 | I29: =SUMIFS('T12 Categorized'!G:G,'T12 Categorized'!$A:$A,$A29) -> 9758.59 | J29: =SUMIFS('T12 Categorized'!H:H,'T12 Categorized'!$A:$A,$A29) -> 8594.46 | K29: =SUMIFS('T12 Categorized'!I:I,'T12 Categorized'!$A:$A,$A29) -> 2430.39 | L29: =SUMIFS('T12 Categorized'!J:J,'T12 Categorized'!$A:$A,$A29) -> 5048.7 | M29: =SUMIFS('T12 Categorized'!K:K,'T12 Categorized'!$A:$A,$A29) -> 7339.77 | N29: =SUMIFS('T12 Categorized'!L:L,'T12 Categorized'!$A:$A,$A29) -> 1253.01 | O29: =SUMIFS('T12 Categorized'!M:M,'T12 Categorized'!$A:$A,$A29) -> 2514.4 | P29: =SUMIFS('T12 Categorized'!N:N,'T12 Categorized'!$A:$A,$A29) -> 4046.05 | Q29: =SUMIFS('T12 Categorized'!O:O,'T12 Categorized'!$A:$A,$A29) -> 12926.31
A30: cont | B30: Contract | F30: =SUMIFS('T12 Categorized'!D:D,'T12 Categorized'!$A:$A,$A30) -> 17519.13 | G30: =SUMIFS('T12 Categorized'!E:E,'T12 Categorized'!$A:$A,$A30) -> 9670.21 | H30: =SUMIFS('T12 Categorized'!F:F,'T12 Categorized'!$A:$A,$A30) -> 13327.98 | I30: =SUMIFS('T12 Categorized'!G:G,'T12 Categorized'!$A:$A,$A30) -> 9633.86 | J30: =SUMIFS('T12 Categorized'!H:H,'T12 Categorized'!$A:$A,$A30) -> 8978.45 | K30: =SUMIFS('T12 Categorized'!I:I,'T12 Categorized'!$A:$A,$A30) -> 10643.63 | L30: =SUMIFS('T12 Categorized'!J:J,'T12 Categorized'!$A:$A,$A30) -> 15811.07 | M30: =SUMIFS('T12 Categorized'!K:K,'T12 Categorized'!$A:$A,$A30) -> 6689.05 | N30: =SUMIFS('T12 Categorized'!L:L,'T12 Categorized'!$A:$A,$A30) -> 15053.13 | O30: =SUMIFS('T12 Categorized'!M:M,'T12 Categorized'!$A:$A,$A30) -> 8712.8 | P30: =SUMIFS('T12 Categorized'!N:N,'T12 Categorized'!$A:$A,$A30) -> -320.19 | Q30: =SUMIFS('T12 Categorized'!O:O,'T12 Categorized'!$A:$A,$A30) -> 18318.41
A31: Safe | B31: Life Safety / Elevators | F31: =SUMIFS('T12 Categorized'!D:D,'T12 Categorized'!$A:$A,$A31) -> 0 | G31: =SUMIFS('T12 Categorized'!E:E,'T12 Categorized'!$A:$A,$A31) -> 0 | H31: =SUMIFS('T12 Categorized'!F:F,'T12 Categorized'!$A:$A,$A31) -> 0 | I31: =SUMIFS('T12 Categorized'!G:G,'T12 Categorized'!$A:$A,$A31) -> 0 | J31: =SUMIFS('T12 Categorized'!H:H,'T12 Categorized'!$A:$A,$A31) -> 0 | K31: =SUMIFS('T12 Categorized'!I:I,'T12 Categorized'!$A:$A,$A31) -> 0 | L31: =SUMIFS('T12 Categorized'!J:J,'T12 Categorized'!$A:$A,$A31) -> 0 | M31: =SUMIFS('T12 Categorized'!K:K,'T12 Categorized'!$A:$A,$A31) -> 0 | N31: =SUMIFS('T12 Categorized'!L:L,'T12 Categorized'!$A:$A,$A31) -> 0 | O31: =SUMIFS('T12 Categorized'!M:M,'T12 Categorized'!$A:$A,$A31) -> 0 | P31: =SUMIFS('T12 Categorized'!N:N,'T12 Categorized'!$A:$A,$A31) -> 0 | Q31: =SUMIFS('T12 Categorized'!O:O,'T12 Categorized'!$A:$A,$A31) -> 0
A32: HAF | B32: Homeowners Association Fees | F32: =SUMIFS('T12 Categorized'!D:D,'T12 Categorized'!$A:$A,$A32) -> 0 | G32: =SUMIFS('T12 Categorized'!E:E,'T12 Categorized'!$A:$A,$A32) -> 0 | H32: =SUMIFS('T12 Categorized'!F:F,'T12 Categorized'!$A:$A,$A32) -> 0 | I32: =SUMIFS('T12 Categorized'!G:G,'T12 Categorized'!$A:$A,$A32) -> 0 | J32: =SUMIFS('T12 Categorized'!H:H,'T12 Categorized'!$A:$A,$A32) -> 0 | K32: =SUMIFS('T12 Categorized'!I:I,'T12 Categorized'!$A:$A,$A32) -> 0 | L32: =SUMIFS('T12 Categorized'!J:J,'T12 Categorized'!$A:$A,$A32) -> 0 | M32: =SUMIFS('T12 Categorized'!K:K,'T12 Categorized'!$A:$A,$A32) -> 0 | N32: =SUMIFS('T12 Categorized'!L:L,'T12 Categorized'!$A:$A,$A32) -> 0 | O32: =SUMIFS('T12 Categorized'!M:M,'T12 Categorized'!$A:$A,$A32) -> 0 | P32: =SUMIFS('T12 Categorized'!N:N,'T12 Categorized'!$A:$A,$A32) -> 0 | Q32: =SUMIFS('T12 Categorized'!O:O,'T12 Categorized'!$A:$A,$A32) -> 0
A33: UT | B33: Utilities Trash | F33: =SUMIFS('T12 Categorized'!D:D,'T12 Categorized'!$A:$A,$A33) -> 0 | G33: =SUMIFS('T12 Categorized'!E:E,'T12 Categorized'!$A:$A,$A33) -> 0 | H33: =SUMIFS('T12 Categorized'!F:F,'T12 Categorized'!$A:$A,$A33) -> 0 | I33: =SUMIFS('T12 Categorized'!G:G,'T12 Categorized'!$A:$A,$A33) -> 0 | J33: =SUMIFS('T12 Categorized'!H:H,'T12 Categorized'!$A:$A,$A33) -> 0 | K33: =SUMIFS('T12 Categorized'!I:I,'T12 Categorized'!$A:$A,$A33) -> 0 | L33: =SUMIFS('T12 Categorized'!J:J,'T12 Categorized'!$A:$A,$A33) -> 0 | M33: =SUMIFS('T12 Categorized'!K:K,'T12 Categorized'!$A:$A,$A33) -> 0 | N33: =SUMIFS('T12 Categorized'!L:L,'T12 Categorized'!$A:$A,$A33) -> 0 | O33: =SUMIFS('T12 Categorized'!M:M,'T12 Categorized'!$A:$A,$A33) -> 0 | P33: =SUMIFS('T12 Categorized'!N:N,'T12 Categorized'!$A:$A,$A33) -> 0 | Q33: =SUMIFS('T12 Categorized'!O:O,'T12 Categorized'!$A:$A,$A33) -> 0
A34: UWS | B34: Utilities Water Sewer | F34: =SUMIFS('T12 Categorized'!D:D,'T12 Categorized'!$A:$A,$A34) -> 10217.44 | G34: =SUMIFS('T12 Categorized'!E:E,'T12 Categorized'!$A:$A,$A34) -> 7301.1 | H34: =SUMIFS('T12 Categorized'!F:F,'T12 Categorized'!$A:$A,$A34) -> 12860.31 | I34: =SUMIFS('T12 Categorized'!G:G,'T12 Categorized'!$A:$A,$A34) -> 7486.59 | J34: =SUMIFS('T12 Categorized'!H:H,'T12 Categorized'!$A:$A,$A34) -> 7214.04 | K34: =SUMIFS('T12 Categorized'!I:I,'T12 Categorized'!$A:$A,$A34) -> 8255.49 | L34: =SUMIFS('T12 Categorized'!J:J,'T12 Categorized'!$A:$A,$A34) -> 11805.66 | M34: =SUMIFS('T12 Categorized'!K:K,'T12 Categorized'!$A:$A,$A34) -> 7754.67 | N34: =SUMIFS('T12 Categorized'!L:L,'T12 Categorized'!$A:$A,$A34) -> 6103.57 | O34: =SUMIFS('T12 Categorized'!M:M,'T12 Categorized'!$A:$A,$A34) -> 4639.58 | P34: =SUMIFS('T12 Categorized'!N:N,'T12 Categorized'!$A:$A,$A34) -> 6046.19 | Q34: =SUMIFS('T12 Categorized'!O:O,'T12 Categorized'!$A:$A,$A34) -> 7377.36
... A41: site | B41: R&M Site | F41: =SUMIFS('T12 Categorized'!D:D,'T12 Categorized'!$A:$A,$A41) -> 0 | G41: =SUMIFS('T12 Categorized'!E:E,'T12 Categorized'!$A:$A,$A41) -> 0 | H41: =SUMIFS('T12 Categorized'!F:F,'T12 Categorized'!$A:$A,$A41) -> 0 | I41: =SUMIFS('T12 Categorized'!G:G,'T12 Categorized'!$A:$A,$A41) -> 0 | J41: =SUMIFS('T12 Categorized'!H:H,'T12 Categorized'!$A:$A,$A41) -> 0 | K41: =SUMIFS('T12 Categorized'!I:I,'T12 Categorized'!$A:$A,$A41) -> 0 | L41: =SUMIFS('T12 Categorized'!J:J,'T12 Categorized'!$A:$A,$A41) -> 0 | M41: =SUMIFS('T12 Categorized'!K:K,'T12 Categorized'!$A:$A,$A41) -> 0 | N41: =SUMIFS('T12 Categorized'!L:L,'T12 Categorized'!$A:$A,$A41) -> 0 | O41: =SUMIFS('T12 Categorized'!M:M,'T12 Categorized'!$A:$A,$A41) -> 0 | P41: =SUMIFS('T12 Categorized'!N:N,'T12 Categorized'!$A:$A,$A41) -> 0 | Q41: =SUMIFS('T12 Categorized'!O:O,'T12 Categorized'!$A:$A,$A41) -> 0
B42: Operating Expenses | F42: =SUM(F23:F41) -> 255793.11 | G42: =SUM(G23:G41) -> 230838.97 | H42: =SUM(H23:H41) -> 242080.33 | I42: =SUM(I23:I41) -> 217832.77 | J42: =SUM(J23:J41) -> 211739.01 | K42: =SUM(K23:K41) -> 281110.25 | L42: =SUM(L23:L41) -> 122488.29 | M42: =SUM(M23:M41) -> 224522.55 | ... Q42: =SUM(Q23:Q41) -> 237340.05
B44: Net Operating Income | F44: =F20-F42 -> 235370.5 | G44: =G20-G42 -> 271990.49 | H44: =H20-H42 -> 253855.65 | I44: =I20-I42 -> 281362.63 | J44: =J20-J42 -> 305639.95 | K44: =K20-K42 -> 250086.96 | L44: =L20-L42 -> 404629.42 | M44: =M20-M42 -> 272298.95 | ... Q44: =Q20-Q42 -> 268910.93
B46: Non-Operating Revenue
A47: dispro | B47: Disposition Proceeds | F47: =SUMIFS('T12 Categorized'!D:D,'T12 Categorized'!$A:$A,$A47) -> 0 | G47: =SUMIFS('T12 Categorized'!E:E,'T12 Categorized'!$A:$A,$A47) -> 0 | H47: =SUMIFS('T12 Categorized'!F:F,'T12 Categorized'!$A:$A,$A47) -> 0 | I47: =SUMIFS('T12 Categorized'!G:G,'T12 Categorized'!$A:$A,$A47) -> 0 | J47: =SUMIFS('T12 Categorized'!H:H,'T12 Categorized'!$A:$A,$A47) -> 0 | K47: =SUMIFS('T12 Categorized'!I:I,'T12 Categorized'!$A:$A,$A47) -> 0 | L47: =SUMIFS('T12 Categorized'!J:J,'T12 Categorized'!$A:$A,$A47) -> 0 | M47: =SUMIFS('T12 Categorized'!K:K,'T12 Categorized'!$A:$A,$A47) -> 0 | N47: =SUMIFS('T12 Categorized'!L:L,'T12 Categorized'!$A:$A,$A47) -> 0 | O47: =SUMIFS('T12 Categorized'!M:M,'T12 Categorized'!$A:$A,$A47) -> 0 | P47: =SUMIFS('T12 Categorized'!N:N,'T12 Categorized'!$A:$A,$A47) -> 0 | Q47: =SUMIFS('T12 Categorized'!O:O,'T12 Categorized'!$A:$A,$A47) -> 0
B48: Non-Operating Revenue | F48: =SUM(F47:F47) -> 0 | G48: =SUM(G47:G47) -> 0 | H48: =SUM(H47:H47) -> 0 | I48: =SUM(I47:I47) -> 0 | J48: =SUM(J47:J47) -> 0 | K48: =SUM(K47:K47) -> 0 | L48: =SUM(L47:L47) -> 0 | M48: =SUM(M47:M47) -> 0 | ... Q48: =SUM(Q47:Q47) -> 0
B50: Non-Operating Expenses
...

Sheet Rent Roll (One-Line) 05-23-26
A1: Unit No. | B1: Floor Plan | C1: Net sf | D1: Bed | E1: Bath | F1: Lease Type | G1: Occupancy Status | H1: Market Rent | I1: Contractual Rent | J1: Net Effective Rent | K1: Lease Start Date | L1: Lease Expiration | M1: Move In Date | O1: Scheduled Charges by Code (monthly $)
O2: rent | P2: upco | Q2: garr | R2: trtra | S2: amfee | T2: cpor | U2: petp | V2: petd | W2: mtom | X2: sdep | Y2: stor | Z2: trvtras | AA2: llock | AB2: vtras
A3: 1102 | B3: C1-abi | C3: 1564 | D3: 3 | E3: 2 | F3: Market | G3: Occupied | H3: 2940 | I3: 2940 | J3: 2940 | L3: 46610 | M3: 45087 | O3: 2940 | Q3: 270 | R3: 25 | S3: 10
A4: 1104 | B4: A3-abi | C4: 719 | D4: 1 | E4: 1 | F4: Market | G4: Occupied | H4: 1630 | I4: 1410 | J4: 1410 | L4: 46277 | M4: 45304 | O4: 1410 | R4: 25 | S4: 10 | U4: 25
A5: 1106 | B5: A3-abi | C5: 719 | D5: 1 | E5: 1 | F5: Market | G5: Occupied | H5: 1630 | I5: 1630 | J5: 1630 | L5: 46485 | M5: 45756 | O5: 1630 | R5: 25 | S5: 10
A6: 1108 | B6: B2-abi | C6: 1109 | D6: 2 | E6: 2 | F6: Market | G6: Occupied | H6: 2115 | I6: 2035 | J6: 2035 | L6: 46348 | M6: 45800 | O6: 2035 | Q6: 200 | R6: 25 | S6: 10
A7: 1109 | B7: A4-abi | C7: 736 | D7: 1 | E7: 1 | F7: Market | G7: Occupied | H7: 1725 | I7: 1568 | J7: 1568 | L7: 46373 | M7: 45340 | O7: 1568 | R7: 25 | S7: 10
A8: 1110 | B8: B2-abi | C8: 1109 | D8: 2 | E8: 2 | F8: Market | G8: Vacant | H8: 2115 | I8: 0 | J8: 0
A9: 1112 | B9: C1-abi | C9: 1564 | D9: 3 | E9: 2 | F9: Market | G9: Occupied | H9: 2940 | I9: 2650 | J9: 2650 | L9: 46298 | M9: 45934 | O9: 2650 | R9: 25 | S9: 10
A10: 1113 | B10: A4-abi | C10: 736 | D10: 1 | E10: 1 | F10: Market | G10: Occupied | H10: 1725 | I10: 1568 | J10: 1568 | L10: 46277 | M10: 45304 | O10: 1568 | R10: 25 | S10: 10 | U10: 25
A11: 1114 | B11: A3-abi | C11: 719 | D11: 1 | E11: 1 | F11: Market | G11: Occupied | H11: 1630 | I11: 1492 | J11: 1492 | L11: 46440 | M11: 45283 | O11: 1492 | R11: 25 | S11: 10
A12: 1116 | B12: B2-abi | C12: 1109 | D12: 2 | E12: 2 | F12: Market | G12: Occupied | H12: 2115 | I12: 2125 | J12: 2125 | L12: 46217 | M12: 45061 | O12: 2125 | Q12: 300 | R12: 25 | S12: 10
A13: 1118 | B13: B2-abi | C13: 1109 | D13: 2 | E13: 2 | F13: Market | G13: Occupied | H13: 2115 | I13: 2085 | J13: 2085 | L13: 46346 | M13: 45159 | O13: 2085 | R13: 25 | S13: 10
A14: 1120 | B14: B1-abi | C14: 1082 | D14: 2 | E14: 2 | F14: Market | G14: Occupied | H14: 2165 | I14: 1974 | J14: 1974 | L14: 46518 | M14: 45589 | O14: 1974 | Q14: 520 | R14: 50 | S14: 20 | U14: 50
A15: 1201 | B15: B1-abi | C15: 1082 | D15: 2 | E15: 2 | F15: Market | G15: Occupied | H15: 2260 | I15: 2095 | J15: 2095 | L15: 46598 | M15: 46053 | O15: 2095 | P15: -1047.5 | R15: 25 | S15: 10 | U15: 25
A16: 1202 | B16: C1-abi | C16: 1564 | D16: 3 | E16: 2 | F16: Market | G16: Occupied | H16: 2860 | I16: 2436 | J16: 2436 | L16: 46404 | M16: 45675 | O16: 2436 | Q16: 160 | R16: 25 | S16: 10 | T16: 65
A17: 1203 | B17: A6-abi | C17: 803 | D17: 1 | E17: 1 | F17: Market | G17: Occupied | H17: 1775 | I17: 1775 | J17: 1775 | L17: 46273 | M17: 45909 | O17: 1775 | R17: 25 | S17: 10
A18: 1204 | B18: A3-abi | C18: 719 | D18: 1 | E18: 1 | F18: Market | G18: Vacant | H18: 1550 | I18: 0 | J18: 0
A19: 1205 | B19: A6-abi | C19: 803 | D19: 1 | E19: 1 | F19: Market | G19: Occupied | H19: 1775 | I19: 1775 | J19: 1775 | L19: 46279 | M19: 45915 | O19: 1775 | Q19: 260 | R19: 25 | S19: 10
A20: 1206 | B20: A3-abi | C20: 719 | D20: 1 | E20: 1 | F20: Market | G20: Occupied | H20: 1550 | I20: 1550 | J20: 1550 | L20: 46248 | M20: 46068 | O20: 1550 | R20: 25 | S20: 10
A21: 1207 | B21: B2-abi | C21: 1109 | D21: 2 | E21: 2 | F21: Market | G21: Occupied | H21: 2210 | I21: 2210 | J21: 2210 | L21: 46283 | M21: 45919 | O21: 2210 | Q21: 200 | R21: 25 | S21: 10
A22: 1208 | B22: B2-abi | C22: 1109 | D22: 2 | E22: 2 | F22: Market | G22: Occupied | H22: 2035 | I22: 2035 | J22: 2035 | L22: 46529 | M22: 46165 | O22: 2035 | R22: 25 | S22: 10 | U22: 25
A23: 1209 | B23: A4-abi | C23: 736 | D23: 1 | E23: 1 | F23: Market | G23: Occupied | H23: 1645 | I23: 1521 | J23: 1521 | L23: 46591 | M23: 45589 | O23: 1521 | R23: 25 | S23: 10
A24: 1210 | B24: B2-abi | C24: 1109 | D24: 2 | E24: 2 | F24: Market | G24: Occupied | H24: 2035 | I24: 1907 | J24: 1907 | L24: 46527 | M24: 45689 | O24: 1907 | Q24: 260 | R24: 25 | S24: 10
A25: 1212 | B25: C1-abi | C25: 1564 | D25: 3 | E25: 2 | F25: Market | G25: Occupied | H25: 2860 | I25: 2902 | J25: 2902 | L25: 46203 | M25: 45474 | O25: 2902 | Q25: 260 | R25: 25 | S25: 10
A26: 1213 | B26: A4-abi | C26: 736 | D26: 1 | E26: 1 | F26: Market | G26: Occupied | H26: 1645 | I26: 1645 | J26: 1645 | L26: 46473 | M26: 45744 | O26: 1645 | R26: 25 | S26: 10
A27: 1214 | B27: A3-abi | C27: 719 | D27: 1 | E27: 1 | F27: Market | G27: Occupied | H27: 1550 | I27: 1550 | J27: 1550 | L27: 46340 | M27: 45519 | O27: 1550 | R27: 25 | S27: 10
A28: 1215 | B28: A2-abi | C28: 698 | D28: 1 | E28: 1 | F28: Market | G28: Occupied | H28: 1660 | I28: 1364 | J28: 1364 | L28: 46385 | M28: 46021 | O28: 1364 | R28: 25 | S28: 10
A29: 1216 | B29: B2-abi | C29: 1109 | D29: 2 | E29: 2 | F29: Market | G29: Occupied | H29: 2035 | I29: 2035 | J29: 2035 | L29: 46224 | M29: 45129 | O29: 2035 | R29: 25 | S29: 10 | U29: 25 | Y29: 40
A30: 1217 | B30: A2-abi | C30: 698 | D30: 1 | E30: 1 | F30: Market | G30: Occupied | H30: 1660 | I30: 1395 | J30: 1395 | L30: 46558 | M30: 45709 | O30: 1395 | R30: 25 | S30: 10
A31: 1218 | B31: B2-abi | C31: 1109 | D31: 2 | E31: 2 | F31: Market | G31: Occupied | H31: 2035 | I31: 2035 | J31: 2035 | L31: 46503 | M31: 46080 | O31: 2035 | P31: -1017.5 | R31: 25 | S31: 10
A32: 1219 | B32: A2-abi | C32: 698 | D32: 1 | E32: 1 | F32: Market | G32: Occupied | H32: 1660 | I32: 1660 | J32: 1660 | L32: 46112 | M32: 45901 | O32: 1660 | R32: 25 | S32: 10
A33: 1220 | B33: B1-abi | C33: 1082 | D33: 2 | E33: 2 | F33: Market | G33: Occupied | H33: 2085 | I33: 1915 | J33: 1915 | L33: 46321 | M33: 45835 | O33: 1915 | Q33: 225 | R33: 25 | S33: 10
A34: 1221 | B34: B1-abi | C34: 1082 | D34: 2 | E34: 2 | F34: Market | G34: Occupied | H34: 2260 | I34: 2260 | J34: 2260 | L34: 46504 | M34: 46081 | O34: 2260 | P34: -1130 | Q34: 230 | R34: 25 | S34: 10
A35: 1301 | B35: B1-abi | C35: 1082 | D35: 2 | E35: 2 | F35: Market | G35: Occupied | H35: 2305 | I35: 2314 | J35: 2314 | L35: 46599 | M35: 45061 | O35: 2314 | Q35: 300 | R35: 25 | S35: 10
A36: 1302 | B36: C1-abi | C36: 1564 | D36: 3 | E36: 2 | F36: Market | G36: Vacant | H36: 2905 | I36: 0 | J36: 0
A37: 1303 | B37: A6-abi | C37: 803 | D37: 1 | E37: 1 | F37: Market | G37: Occupied | H37: 1645 | I37: 1645 | J37: 1645 | L37: 46596 | M37: 45594 | O37: 1645 | R37: 25 | S37: 10
A38: 1304 | B38: A3-abi | C38: 719 | D38: 1 | E38: 1 | F38: Market | G38: Occupied | H38: 1595 | I38: 1435 | J38: 1435 | L38: 46210 | M38: 45238 | O38: 1435 | R38: 25 | S38: 10 | T38: 65
A39: 1305 | B39: A6-abi | C39: 803 | D39: 1 | E39: 1 | F39: Market | G39: Occupied | H39: 1820 | I39: 1770 | J39: 1770 | L39: 46300 | M39: 45113 | O39: 1770 | Q39: 200 | R39: 25 | S39: 10
A40: 1306 | B40: A3-abi | C40: 719 | D40: 1 | E40: 1 | F40: Market | G40: Occupied | H40: 1595 | I40: 1397 | J40: 1397 | L40: 46508 | M40: 45779 | O40: 1397 | R40: 25 | S40: 10
...

Sheet Rent Roll (One-Line) 02-26-24
A1: Unit No. | B1: Floor Plan | C1: Net sf | D1: Bed | E1: Bath | F1: Lease Type | G1: Occupancy Status | H1: Market Rent | I1: Contractual Rent | J1: Net Effective Rent | K1: Lease Start Date | L1: Lease Expiration | M1: Move In Date | O1: Scheduled Charges by Code (monthly $)
O2: rent | P2: upco | Q2: garr | R2: vtras | S2: amfee | T2: cpor | U2: petp | V2: empl | W2: edsc | X2: llock | Y2: mtom | Z2: stor
A3: 1102 | B3: C1-abi | C3: 1564 | D3: 3 | E3: 2 | F3: Market | G3: Occupied | H3: 2940 | I3: 2840 | J3: 2840 | L3: 45513 | M3: 45087 | O3: 2840 | Q3: 270 | R3: 25 | S3: 10
A4: 1104 | B4: A3-abi | C4: 719 | D4: 1 | E4: 1 | F4: Market | G4: Occupied | H4: 1630 | I4: 1410 | J4: 1410 | L4: 45728 | M4: 45304 | O4: 1410 | P4: -705 | R4: 25 | S4: 10 | U4: 25
A5: 1106 | B5: A3-abi | C5: 719 | D5: 1 | E5: 1 | F5: Market | G5: Occupied | H5: 1630 | I5: 1450 | J5: 1450 | L5: 45611 | M5: 45185 | O5: 1450 | R5: 25 | S5: 10
A6: 1108 | B6: B2-abi | C6: 1109 | D6: 2 | E6: 2 | F6: Market | G6: Vacant | H6: 2115 | I6: 0 | J6: 0
A7: 1109 | B7: A4-abi | C7: 736 | D7: 1 | E7: 1 | F7: Market | G7: Occupied | H7: 1725 | I7: 1545 | J7: 1545 | L7: 45825 | M7: 45340 | O7: 1545 | R7: 25 | S7: 10
A8: 1110 | B8: B2-abi | C8: 1109 | D8: 2 | E8: 2 | F8: Market | G8: Occupied | H8: 2115 | I8: 2110 | J8: 2110 | L8: 45579 | M8: 45153 | O8: 2110 | R8: 25 | S8: 10
A9: 1112 | B9: C1-abi | C9: 1564 | D9: 3 | E9: 2 | F9: Market | G9: Occupied | H9: 2940 | I9: 2760 | J9: 2760 | L9: 45505 | M9: 45140 | O9: 2760 | R9: 25 | S9: 10 | X9: 29
A10: 1113 | B10: A4-abi | C10: 736 | D10: 1 | E10: 1 | F10: Market | G10: Occupied | H10: 1725 | I10: 1545 | J10: 1545 | L10: 45728 | M10: 45304 | O10: 1545 | P10: -772.5 | R10: 25 | S10: 10 | U10: 25
A11: 1114 | B11: A3-abi | C11: 719 | D11: 1 | E11: 1 | F11: Market | G11: Occupied | H11: 1630 | I11: 1470 | J11: 1470 | L11: 45710 | M11: 45283 | O11: 1470 | P11: -735 | R11: 25 | S11: 10
A12: 1116 | B12: B2-abi | C12: 1109 | D12: 2 | E12: 2 | F12: Market | G12: Occupied | H12: 2115 | I12: 2085 | J12: 2085 | L12: 45487 | M12: 45061 | O12: 2085 | Q12: 300 | R12: 25 | S12: 10
A13: 1118 | B13: B2-abi | C13: 1109 | D13: 2 | E13: 2 | F13: Market | G13: Occupied | H13: 2115 | I13: 2085 | J13: 2085 | L13: 45524 | M13: 45159 | O13: 2085 | R13: 25 | S13: 10
A14: 1120 | B14: B1-abi | C14: 1082 | D14: 2 | E14: 2 | F14: Market | G14: Occupied | H14: 2165 | I14: 2030 | J14: 2030 | L14: 45607 | M14: 45058 | O14: 2030 | Q14: 200 | R14: 25 | S14: 10
A15: 1201 | B15: B1-abi | C15: 1082 | D15: 2 | E15: 2 | F15: Market | G15: Occupied | H15: 2260 | I15: 2260 | J15: 2260 | L15: 45489 | M15: 45094 | O15: 2260 | R15: 25 | S15: 10
A16: 1202 | B16: C1-abi | C16: 1564 | D16: 3 | E16: 2 | F16: Market | G16: Occupied | H16: 2860 | I16: 2860 | J16: 2860 | L16: 45633 | M16: 45177 | O16: 2860 | Q16: 295 | R16: 25 | S16: 10 | U16: 50
A17: 1203 | B17: A6-abi | C17: 803 | D17: 1 | E17: 1 | F17: Market | G17: Occupied | H17: 1775 | I17: 1730 | J17: 1730 | L17: 45505 | M17: 45079 | O17: 1730 | R17: 25 | S17: 10
A18: 1204 | B18: A3-abi | C18: 719 | D18: 1 | E18: 1 | F18: Market | G18: Occupied | H18: 1550 | I18: 1490 | J18: 1490 | L18: 45465 | M18: 45100 | O18: 1490 | R18: 25 | S18: 10
A19: 1205 | B19: A6-abi | C19: 803 | D19: 1 | E19: 1 | F19: Market | G19: Occupied | H19: 1775 | I19: 1750 | J19: 1750 | L19: 45508 | M19: 45082 | O19: 1750 | Q19: 300 | R19: 25 | S19: 10
A20: 1206 | B20: A3-abi | C20: 719 | D20: 1 | E20: 1 | F20: Market | G20: Occupied | H20: 1550 | I20: 1385 | J20: 1385 | L20: 45702 | M20: 45275 | O20: 1385 | P20: -692.5 | R20: 25 | S20: 10
A21: 1207 | B21: B2-abi | C21: 1109 | D21: 2 | E21: 2 | F21: Market | G21: Occupied | H21: 2210 | I21: 2195 | J21: 2195 | L21: 45483 | M21: 45118 | O21: 2195 | R21: 25 | S21: 10 | U21: 25
A22: 1208 | B22: B2-abi | C22: 1109 | D22: 2 | E22: 2 | F22: Market | G22: Occupied | H22: 2035 | I22: 1955 | J22: 1955 | L22: 45610 | M22: 45122 | O22: 1955 | R22: 25 | S22: 10
A23: 1209 | B23: A4-abi | C23: 736 | D23: 1 | E23: 1 | F23: Market | G23: Occupied | H23: 1645 | I23: 1635 | J23: 1635 | L23: 45511 | M23: 45146 | O23: 1635 | Q23: 360 | R23: 25 | S23: 10
A24: 1210 | B24: B2-abi | C24: 1109 | D24: 2 | E24: 2 | F24: Market | G24: Occupied | H24: 2035 | I24: 1990 | J24: 1990 | L24: 45616 | M24: 45128 | O24: 1990 | R24: 25 | S24: 10
A25: 1212 | B25: C1-abi | C25: 1564 | D25: 3 | E25: 2 | F25: Market | G25: Occupied | H25: 2860 | I25: 2860 | J25: 2860 | L25: 45444 | M25: 45079 | O25: 2860 | Q25: 350 | R25: 25 | S25: 10
A26: 1213 | B26: A4-abi | C26: 736 | D26: 1 | E26: 1 | F26: Market | G26: Occupied | H26: 1645 | I26: 1499 | J26: 1499 | L26: 45718 | M26: 45294 | O26: 1499 | P26: -1082 | R26: 25 | S26: 10
A27: 1214 | B27: A3-abi | C27: 719 | D27: 1 | E27: 1 | F27: Market | G27: Occupied | H27: 1550 | I27: 1485 | J27: 1485 | L27: 45512 | M27: 45086 | O27: 1485 | R27: 25 | S27: 10
A28: 1215 | B28: A2-abi | C28: 698 | D28: 1 | E28: 1 | F28: Market | G28: Vacant | H28: 1660 | I28: 0 | J28: 0
A29: 1216 | B29: B2-abi | C29: 1109 | D29: 2 | E29: 2 | F29: Market | G29: Occupied | H29: 2035 | I29: 1980 | J29: 1980 | L29: 45494 | M29: 45129 | O29: 1980 | R29: 25 | S29: 10 | T29: 65
A30: 1217 | B30: A2-abi | C30: 698 | D30: 1 | E30: 1 | F30: Market | G30: Occupied | H30: 1660 | I30: 1480 | J30: 1480 | L30: 45683 | M30: 45257 | O30: 1480 | P30: -740 | R30: 25 | S30: 10
A31: 1218 | B31: B2-abi | C31: 1109 | D31: 2 | E31: 2 | F31: Market | G31: Occupied | H31: 2035 | I31: 2030 | J31: 2030 | L31: 45596 | M31: 45170 | O31: 2030 | R31: 25 | S31: 10 | U31: 25
A32: 1219 | B32: A2-abi | C32: 698 | D32: 1 | E32: 1 | F32: Market | G32: Occupied | H32: 1660 | I32: 1580 | J32: 1580 | L32: 45551 | M32: 45155 | O32: 1580 | R32: 25 | S32: 10
A33: 1220 | B33: B1-abi | C33: 1082 | D33: 2 | E33: 2 | F33: Market | G33: Occupied | H33: 2085 | I33: 2085 | J33: 2085 | L33: 45520 | M33: 45155 | O33: 2085 | R33: 25 | S33: 10
A34: 1221 | B34: B1-abi | C34: 1082 | D34: 2 | E34: 2 | F34: Market | G34: Occupied | H34: 2260 | I34: 1995 | J34: 1995 | L34: 45656 | M34: 45230 | O34: 1995 | R34: 25 | S34: 10
A35: 1301 | B35: B1-abi | C35: 1082 | D35: 2 | E35: 2 | F35: Market | G35: Occupied | H35: 2305 | I35: 2280 | J35: 2280 | L35: 45546 | M35: 45061 | O35: 2280 | Q35: 300 | R35: 25 | S35: 10 | X35: 42
A36: 1302 | B36: C1-abi | C36: 1564 | D36: 3 | E36: 2 | F36: Market | G36: Occupied | H36: 2905 | I36: 2780 | J36: 2780 | L36: 45614 | M36: 45065 | O36: 2780 | Q36: 270 | R36: 25 | S36: 10
A37: 1303 | B37: A6-abi | C37: 803 | D37: 1 | E37: 1 | F37: Market | G37: Occupied | H37: 1645 | I37: 1565 | J37: 1565 | L37: 45528 | M37: 45041 | O37: 1565 | Q37: 250 | R37: 25 | S37: 10
A38: 1304 | B38: A3-abi | C38: 719 | D38: 1 | E38: 1 | F38: Market | G38: Occupied | H38: 1595 | I38: 1435 | J38: 1435 | L38: 45664 | M38: 45238 | O38: 1435 | P38: -717.5 | R38: 25 | S38: 10
A39: 1305 | B39: A6-abi | C39: 803 | D39: 1 | E39: 1 | F39: Market | G39: Occupied | H39: 1820 | I39: 1770 | J39: 1770 | L39: 45540 | M39: 45113 | O39: 1770 | R39: 25 | S39: 10
A40: 1306 | B40: A3-abi | C40: 719 | D40: 1 | E40: 1 | F40: Market | G40: Occupied | H40: 1595 | I40: 1415 | J40: 1415 | L40: 45646 | M40: 45220 | O40: 1415 | R40: 25 | S40: 10 | T40: 65
...

Sheet Lease Trend
A1: Lease Trend & Operating History (monthly)
A2: True market rent from HelloData executed leases (mix-weighted by floor plan) + new-lease signings; loss-to-lease backed into from T12 AGPR; concessions compared T12 vs HelloData. Months flow left-to-right; renewals excluded from market reads.
